Workbook

Sheet PELCA - Legend | License
A1: skip
G10: Version | H10: V1.4.0
F11: https://github.com/merce-fra/PELCA
B12: LEGEND Excel
C14: User-editable values
C16: Must be modified by the user before running the simulation
B18: TEXT | C18: Data ingested by Brightway to calculate the imapcts
B20: GNU LESSER GENERAL PUBLIC LICENSE Version 3, 29 June 2007 Copyright (C) 2007 Free Software Foundation, Inc. <https://fsf.org/> Everyone is permitted to copy and distribute verbatim copies of this license document, but changing it is not allowed. This version of the GNU Lesser General Public License incorporates the terms and conditions of version 3 of the GNU General Public License, supplemented by the additional permissions listed below. 0. Additional Definitions. As used herein, "this License" refers to version 3 of the GNU Lesser General Public License, and the "GNU GPL" refers to version 3 of the GNU General Public License. "The Library" refers to a covered work governed by this License, other than an Application or a Combined Work as defined below. An "Application" is any work that makes use of an interface provided by the Library, but which is not otherwise based on the Library. Defining a subclass of a class defined by the Library is deemed a mode of using an interface provided by the Library. A "Combined Work" is a work produced by combining or linking an Application with the Library. The particular version of the Library with which the Combined Work was made is also called the "Linked Version". The "Minimal Corresponding Source" for a Combined Work means the Corresponding Source for the Combined Work, excluding any source code for portions of the Combined Work that, considered in isolation, are based on the Application, and not on the Linked Version. The "Corresponding Application Code" for a Combined Work means the object code and/or source code for the Application, including any data and utility programs needed for reproducing the Combined Work from the Application, but excluding the System Libraries of the Combined Work. 1. Exception to Section 3 of the GNU GPL. You may convey a covered work under sections 3 and 4 of this License without being bound by section 3 of the GNU GPL. 2. Conveying Modified Versions. If you modify a copy of the Library, and, in your modifications, a facility refers to a function or data to be supplied by an Application that uses the facility (other than as an argument passed when the facility is invoked), then you may convey a copy of the modified version: a) under this License, provided that you make a good faith effort to ensure that, in the event an Application does not supply the function or data, the facility still operates, and performs whatever part of its purpose remains meaningful, or b) under the GNU GPL, with none of the additional permissions of this License applicable to that copy. 3. Object Code Incorporating Material from Library Header Files. The object code form of an Application may incorporate material from a header file that is part of the Library. You may convey such object code under terms of your choice, provided that, if the incorporated material is not limited to numerical parameters, data structure layouts and accessors, or small macros, inline functions and templates (ten or fewer lines in length), you do both of the following: a) Give prominent notice with each copy of the object code that the Library is used in it and that the Library and its use are covered by this License. b) Accompany the object code with a copy of the GNU GPL and this license document. 4. Combined Works. You may convey a Combined Work under terms of your choice that, taken together, effectively do not restrict modification of the portions of the Library contained in the Combined Work and reverse engineering for debugging such modifications, if you also do each of the following: a) Give prominent notice with each copy of the Combined Work that the Library is used in it and that the Library and its use are covered by this License. b) Accompany the Combined Work with a copy of the GNU GPL and this license document. c) For a Combined Work that displays copyright notices during execution, include the copyright notice for the Library among these notices, as well as a reference directing the user to the copies of the GNU GPL and this license document. d) Do one of the following: 0) Convey the Minimal Corresponding Source under the terms of this License, and the Corresponding Application Code in a form suitable for, and under terms that permit, the user to recombine or relink the Application with a modified version of the Linked Version to produce a modified Combined Work, in the manner specified by section 6 of the GNU GPL for conveying Corresponding Source. 1) Use a suitable shared library mechanism for linking with the Library. A suitable mechanism is one that (a) uses at run time a copy of the Library already present on the user's computer system, and (b) will operate properly with a modified version of the Library that is interface-compatible with the Linked Version. e) Provide Installation Information, but only if you would otherwise be required to provide such information under section 6 of the GNU GPL, and only to the extent that such information is necessary to install and execute a modified version of the Combined Work produced by recombining or relinking the Application with a modified version of the Linked Version. (If you use option 4d0, the Installation Information must accompany the Minimal Corresponding Source and Corresponding Application Code. If you use option 4d1, you must provide the Installation Information in the manner specified by section 6 of the GNU GPL for conveying Corresponding Source.) 5. Combined Libraries. You may place library facilities that are a work based on the Library side by side in a single library together with other library facilities that are not Applications and are not covered by this License, and convey such a combined library under terms of your choice, if you do both of the following: a) Accompany the combined library with a copy of the same work based on the Library, uncombined with any other library facilities, conveyed under the terms of this License. b) Give prominent notice with the combined library that part of it is a work based on the Library, and explaining where to find the accompanying uncombined form of the same work. 6. Revised Versions of the GNU Lesser General Public License. The Free Software Foundation may publish revised and/or new versions of the GNU Lesser General Public License from time to time. Such new versions will be similar in spirit to the present version, but may differ in detail to address new problems or concerns. Each version is given a distinguishing version number. If the Library as you received it specifies that a certain numbered version of the GNU Lesser General Public License "or any later version" applies to it, you have the option of following the terms and conditions either of that published version or of any later version published by the Free Software Foundation. If the Library as you received it does not specify a version number of the GNU Lesser General Public License, you may choose any version of the GNU Lesser General Public License ever published by the Free Software Foundation. If the Library as you received it specifies that a proxy can decide whether future versions of the GNU Lesser General Public License shall apply, that proxy's public statement of acceptance of any version is permanent authorization for you to choose that version for the Library.

Sheet Inventory - Manufacturing
A1: Informations | B1: A RU (Reference Unit) can include multiple units. For example: - RU: 4 NP-type capacitors - Unit: 1 NP-type capacitor The exchange flows for each RU are defined based on a single unit. If the RU consists of N units, this is indicated in the 'scaling factor' column of the last row by N. This cell shows that the flows defined for a single unit (in the column 'quantity') represent 1/N of the flows for the total RU. Therefore, the flows for the total RU correspond to N times the flows of a single unit. Example: the RU is a power switch embedding 4 power dice in parallel --> the listed exchanges corresponds to the flows for the manufacturing of 1 power die ; the cell of column D ('scaling factor'), last row indicates 4 ; the cell of column E ('amount'), last row automatically indicates 1/N = 0,25 ; this means that the amounts of all the listed flows will be divided by 0,25 (i.e. multiplied by 4) when computing the manufacturing impacts of this RU.
A2: Database | B2: eFuse_Microchip
A4: Activity | B4: SiC MOSFET Transistor #1
A5: comment | B5: (Unknown)
A6: location | B6: GLO
A7: production amount | B7: =1 -> 1
A8: type | B8: process
A9: unit | B9: unit
A10: Exchanges
A11: name | B11: quantity | C11: unit | D11: scaling factor | E11: amount | F11: database | G11: categories | H11: location | I11: type | J11: Tag
A12: market group for electricity, medium voltage | B12: 2.0468323 | C12: kilowatt hour | D12: 1 | E12: =D12*B12 -> 2.0468323 | F12: ecoinvent 3.9.1_cutoff_ecoSpold02 | G12: (Unknown) | H12: US | I12: technosphere | J12: #4
A13: market for silicon carbide | B13: 0.0041217676 | C13: kilogram | D13: 1 | E13: =D13*B13 -> 0.0041217676 | F13: ecoinvent 3.9.1_cutoff_ecoSpold02 | G13: (Unknown) | H13: GLO | I13: technosphere | J13: #4
A14: market for nitrogen, liquid | B14: 0.011709567 | C14: kilogram | D14: 1 | E14: =D14*B14 -> 0.011709567 | F14: ecoinvent 3.9.1_cutoff_ecoSpold02 | G14: (Unknown) | H14: RER | I14: technosphere | J14: #4
A15: market group for electricity, medium voltage | B15: 0.033489362 | C15: kilowatt hour | D15: 1 | E15: =D15*B15 -> 0.033489362 | F15: ecoinvent 3.9.1_cutoff_ecoSpold02 | G15: (Unknown) | H15: US | I15: technosphere | J15: #4
A16: market for silicon tetrahydride | B16: 4.3402213e-05 | C16: kilogram | D16: 1 | E16: =D16*B16 -> 4.3402213e-05 | F16: ecoinvent 3.9.1_cutoff_ecoSpold02 | G16: (Unknown) | H16: GLO | I16: technosphere | J16: #4
A17: market for propane | B17: 6.0576228e-05 | C17: kilogram | D17: 1 | E17: =D17*B17 -> 6.0576228e-05 | F17: ecoinvent 3.9.1_cutoff_ecoSpold02 | G17: (Unknown) | H17: GLO | I17: technosphere | J17: #4
A18: market for hydrogen, gaseous | B18: 6.0280852e-05 | C18: kilogram | D18: 1 | E18: =D18*B18 -> 6.0280852e-05 | F18: ecoinvent 3.9.1_cutoff_ecoSpold02 | G18: (Unknown) | H18: GLO | I18: technosphere | J18: #4
A19: market for nitrogen, liquid | B19: 0.00083723405 | C19: kilogram | D19: 1 | E19: =D19*B19 -> 0.00083723405 | F19: ecoinvent 3.9.1_cutoff_ecoSpold02 | G19: (Unknown) | H19: RER | I19: technosphere | J19: #4
A20: market group for electricity, medium voltage | B20: 0.0019784485 | C20: kilowatt hour | D20: 1 | E20: =D20*B20 -> 0.0019784485 | F20: ecoinvent 3.9.1_cutoff_ecoSpold02 | G20: (Unknown) | H20: US | I20: technosphere | J20: #4
A21: market for hydrogen fluoride | B21: 0.00041217676 | C21: kilogram | D21: 1 | E21: =D21*B21 -> 0.00041217676 | F21: ecoinvent 3.9.1_cutoff_ecoSpold02 | G21: (Unknown) | H21: RER | I21: technosphere | J21: #4
A22: market for ammonia, anhydrous, liquid | B22: 0.0026002465 | C22: kilogram | D22: 1 | E22: =D22*B22 -> 0.0026002465 | F22: ecoinvent 3.9.1_cutoff_ecoSpold02 | G22: (Unknown) | H22: RER | I22: technosphere | J22: #4
A23: market for hydrogen peroxide, without water, in 50% solution state | B23: 0.0086074284 | C23: kilogram | D23: 1 | E23: =D23*B23 -> 0.0086074284 | F23: ecoinvent 3.9.1_cutoff_ecoSpold02 | G23: (Unknown) | H23: RER | I23: technosphere | J23: #4
... A97: market group for electricity, medium voltage | B97: 0.09757545 | C97: kilowatt hour | D97: 1 | E97: =D97*B97 -> 0.09757545 | F97: ecoinvent 3.9.1_cutoff_ecoSpold02 | G97: (Unknown) | H97: US | I97: technosphere | J97: #4
A98: =B4 -> SiC MOSFET Transistor #1 | B98: 1 | C98: unit | D98: 1 | E98: =B98/D98 -> 1 | F98: =$B$2 -> eFuse_Microchip | G98: (Unknown) | H98: GLO | I98: production | J98: #4
A100: Activity | B100: SiC MOSFET Transistor #2
A101: comment | B101: (Unknown)
A102: location | B102: GLO
A103: production amount | B103: =1 -> 1
A104: type | B104: process
A105: unit | B105: unit
A106: Exchanges
A107: name | B107: quantity | C107: unit | D107: scaling factor | E107: amount | F107: database | G107: categories | H107: location | I107: type | J107: Tag
A108: market group for electricity, medium voltage | B108: 2.0468323 | C108: kilowatt hour | D108: 1 | E108: =D108*B108 -> 2.0468323 | F108: ecoinvent 3.9.1_cutoff_ecoSpold02 | G108: (Unknown) | H108: US | I108: technosphere | J108: #4
A109: market for silicon carbide | B109: 0.0041217676 | C109: kilogram | D109: 1 | E109: =D109*B109 -> 0.0041217676 | F109: ecoinvent 3.9.1_cutoff_ecoSpold02 | G109: (Unknown) | H109: GLO | I109: technosphere | J109: #4
A110: market for nitrogen, liquid | B110: 0.011709567 | C110: kilogram | D110: 1 | E110: =D110*B110 -> 0.011709567 | F110: ecoinvent 3.9.1_cutoff_ecoSpold02 | G110: (Unknown) | H110: RER | I110: technosphere | J110: #4
A111: market group for electricity, medium voltage | B111: 0.033489362 | C111: kilowatt hour | D111: 1 | E111: =D111*B111 -> 0.033489362 | F111: ecoinvent 3.9.1_cutoff_ecoSpold02 | G111: (Unknown) | H111: US | I111: technosphere | J111: #4
A112: market for silicon tetrahydride | B112: 4.3402213e-05 | C112: kilogram | D112: 1 | E112: =D112*B112 -> 4.3402213e-05 | F112: ecoinvent 3.9.1_cutoff_ecoSpold02 | G112: (Unknown) | H112: GLO | I112: technosphere | J112: #4
A113: market for propane | B113: 6.0576228e-05 | C113: kilogram | D113: 1 | E113: =D113*B113 -> 6.0576228e-05 | F113: ecoinvent 3.9.1_cutoff_ecoSpold02 | G113: (Unknown) | H113: GLO | I113: technosphere | J113: #4
A114: market for hydrogen, gaseous | B114: 6.0280852e-05 | C114: kilogram | D114: 1 | E114: =D114*B114 -> 6.0280852e-05 | F114: ecoinvent 3.9.1_cutoff_ecoSpold02 | G114: (Unknown) | H114: GLO | I114: technosphere | J114: #4
A115: market for nitrogen, liquid | B115: 0.00083723405 | C115: kilogram | D115: 1 | E115: =D115*B115 -> 0.00083723405 | F115: ecoinvent 3.9.1_cutoff_ecoSpold02 | G115: (Unknown) | H115: RER | I115: technosphere | J115: #4
...

Sheet Inventory - Use
A1: Activity | B1: Energy - SiC MOSFET Transistor #1
A2: comment | B2: (Unknown)
A3: location | B3: GLO
A4: production amount | B4: =1 -> 1
A5: type | B5: process
A6: unit | B6: unit
A7: Exchanges
A8: name | B8: quantity | C8: unit | D8: scaling factor | E8: amount | F8: database | G8: categories | H8: location | I8: type | J8: Tag
A9: market for electricity, low voltage | B9: 0.002218935 | C9: kilowatt hour | D9: 1 | E9: =D9*B9 -> 0.002218935 | F9: ecoinvent 3.9.1_cutoff_ecoSpold02 | G9: (Unknown) | H9: FR | I9: technosphere | J9: #24
A10: =B1 -> Energy - SiC MOSFET Transistor #1 | B10: 1 | C10: unit | D10: 1 | E10: =B10/D10 -> 1 | F10: ='Inventory - Manufacturing'!B2 -> eFuse_Microchip | G10: (Unknown) | H10: GLO | I10: production
A12: Activity | B12: Energy - SiC MOSFET Transistor #2
A13: comment | B13: (Unknown)
A14: location | B14: GLO
A15: production amount | B15: =1 -> 1
A16: type | B16: process
A17: unit | B17: unit
A18: Exchanges
A19: name | B19: quantity | C19: unit | D19: scaling factor | E19: amount | F19: database | G19: categories | H19: location | I19: type | J19: Tag
A20: market for electricity, low voltage | B20: 0.002218935 | C20: kilowatt hour | D20: 1 | E20: =D20*B20 -> 0.002218935 | F20: ecoinvent 3.9.1_cutoff_ecoSpold02 | G20: (Unknown) | H20: FR | I20: technosphere | J20: #24
A21: =B12 -> Energy - SiC MOSFET Transistor #2 | B21: 1 | C21: unit | D21: 1 | E21: =B21/D21 -> 1 | F21: ='Inventory - Manufacturing'!B2 -> eFuse_Microchip | G21: (Unknown) | H21: GLO | I21: production
A23: Activity | B23: Energy - Current Measurement
A24: comment | B24: (Unknown)
A25: location | B25: GLO
A26: production amount | B26: =1 -> 1
A27: type | B27: process
A28: unit | B28: unit
A29: Exchanges
A30: name | B30: quantity | C30: unit | D30: scaling factor | E30: amount | F30: database | G30: categories | H30: location | I30: type | J30: Tag
A31: market for electricity, low voltage | B31: 0.000707 | C31: kilowatt hour | D31: 1 | E31: =D31*B31 -> 0.000707 | F31: ecoinvent 3.9.1_cutoff_ecoSpold02 | G31: (Unknown) | H31: FR | I31: technosphere | J31: #34
A32: =B23 -> Energy - Current Measurement | B32: 1 | C32: unit | D32: 1 | E32: =B32/D32 -> 1 | F32: ='Inventory - Manufacturing'!B2 -> eFuse_Microchip | G32: (Unknown) | H32: GLO | I32: production
A34: Activity | B34: Energy - Integrated circuits
A35: comment | B35: (Unknown)
A36: location | B36: GLO
A37: production amount | B37: =1 -> 1
A38: type | B38: process
A39: unit | B39: unit
A40: Exchanges
A41: name | B41: quantity | C41: unit | D41: scaling factor | E41: amount | F41: database | G41: categories | H41: location | I41: type | J41: Tag
A42: market for electricity, low voltage | B42: 0.00062 | C42: kilowatt hour | D42: 1 | E42: =D42*B42 -> 0.00062 | F42: ecoinvent 3.9.1_cutoff_ecoSpold02 | G42: (Unknown) | H42: FR | I42: technosphere | J42: #40 #43-#45 #47-#49
A43: =B34 -> Energy - Integrated circuits | B43: 1 | C43: unit | D43: 1 | E43: =B43/D43 -> 1 | F43: ='Inventory - Manufacturing'!B2 -> eFuse_Microchip | G43: (Unknown) | H43: GLO | I43: production

Sheet LCA
A1: skip | C1: Informations
A2: LCA result path | B2: C:\Users\username\filepath | C2: The path where the 'Result PELCA' folder is located (without 'Result PELCA' in the path name). If the folder does not exist, the tool will create a 'Results PELCA' folder and perform the LCA.
A4: Project name (brightway) | B4: inverter_test_02 | C4: The project name provided in Brightway will be built using the Biosphere database (Brightway) and Ecoinvent. For each new project, the databases will need to be reinstalled. The project can then be viewed and utilized with Activity Browser.
A5: Inventory name | B5: ='Inventory - Manufacturing'!B2 -> eFuse_Microchip | C5: The inventory name within the project will also be visible and usable in Activity Browser. The inventory consists of activities listed in the 'Inventory - Manufacturing' and 'Inventory - Use' sheets, with the inventory name specified at the beginning of the 'Inventory - Manufacturing' sheet.
A7: Database ecoinvent | B7: ecoinvent 3.9.1_cutoff_ecoSpold02 | C7: The name of the Ecoinvent database being used. If the database is not yet installed in the Brightway project under the name 'Project name (Brightway)', the tool will install it into the project.
A8: Ecoinvent path | B8: /Users/username/Downloads/ecoinvent 3.9.1_cutoff_ecoSpold02/datasets | C8: The path to the 'datasets' of the database if it needs to be installed.
A10: Type of simulation (Analysis\Monte Carlo) | B10: Analysis | C10: The tool allows for environmental quantification through either a traditional LCA (Analysis) or an uncertainty analysis (Monte Carlo). Selecting 'Monte Carlo' also performs a traditional LCA.
A11: Number of iterations (Monte Carlo) | B11: 10 | C11: The number of iterations for the uncertainty analysis, "Monte Carlo" option.

Sheet LCIA
A1: skip | F1: Informations
A2: Acronym | B2: Method name | C2: Impact category | D2: Specific context | E2: Unit | F2: The methods selected for LCA.
A3: GWP | B3: EF v3.0 no LT | C3: climate change no LT | D3: global warming potential (GWP100) no LT | E3: kg CO2 eq
A4: OD | B4: EF v3.0 no LT | C4: ozone depletion no LT | D4: ozone depletion potential (ODP) no LT | E4: kg CFC-11 eq
A5: HT | B5: EF v3.0 no LT | C5: human toxicity: carcinogenic no LT | D5: comparative toxic unit for human (CTUh) no LT | E5: CTUh
A6: HTNC | B6: EF v3.0 no LT | C6: human toxicity: non-carcinogenic no LT | D6: comparative toxic unit for human (CTUh) no LT | E6: CTUh
A7: PMF | B7: EF v3.0 no LT | C7: particulate matter formation no LT | D7: impact on human health no LT | E7: disease incidence
A8: IR | B8: EF v3.0 no LT | C8: ionising radiation: human health no LT | D8: human exposure efficiency relative to u235 no LT | E8: kBq U-235 eq
A9: POF | B9: EF v3.0 no LT | C9: photochemical oxidant formation: human health no LT | D9: tropospheric ozone concentration increase no LT | E9: kg NMVOC eq
A10: TAP | B10: EF v3.0 no LT | C10: acidification no LT | D10: accumulated exceedance (AE) no LT | E10: mol H+ eq
A11: TE | B11: EF v3.0 no LT | C11: eutrophication: terrestrial no LT | D11: accumulated exceedance (AE) no LT | E11: mol N eq
A12: FE | B12: EF v3.0 no LT | C12: eutrophication: freshwater no LT | D12: fraction of nutrients reaching freshwater end compartment (P) no LT | E12: kg P eq
A13: ME | B13: EF v3.0 no LT | C13: eutrophication: marine no LT | D13: fraction of nutrients reaching marine end compartment (N) no LT | E13: kg N eq
A14: FET | B14: EF v3.0 no LT | C14: ecotoxicity: freshwater no LT | D14: comparative toxic unit for ecosystems (CTUe) no LT | E14: CTUe
... A18: LU | B18: EF v3.0 no LT | C18: land use no LT | D18: soil quality index no LT | E18: Dimensionless

Sheet Cost - Price
A1: skip
A2: Informations | B2: The tool allows models the diagnosis associated with the system, specifically detailing the replacement scenarios when a fault occurs. This includes identifying what components are replaced within the system, To achieve this, this sheet constructs the Replacement Matrix (RM). The numbers in the matrix represent the probability to replace each RU when a specific RU fails, with values ranging from 0 to 1. Row indices represent faults in a specific RU (e.g., Fault RU1), while column indices represent the RUs to be replaced (e.g., RU1). To clarify, consider an example with 2 RUs, resulting in a 2x2 matrix. In this example, if the value in the first row, first column (Fault RU1 ; RU1) is 1, and the value in the first row, second column (Fault RU1 ; RU2) is 0.6, this means that when a fault occurs in RU1, there is 100% probability of replacing RU1 and 60% probabilitu of replacing RU2 according to the diagnosis.
C3: LINK | E3: LINK
C4: 31 | E4: 0.2016
B5: RU raw cost/price (€) | C5: RU assembly cost/price (€) | D5: RU disassembly cost/price (€) | E5: Electricity cost (€/kWh)
A6: SiC MOSFET Transistor #1 | B6: 39.26 | C6: 8.2666667 | D6: 23.25 | E6: =E4 -> 0.2016
A7: SiC MOSFET Transistor #2 | B7: 39.26 | C7: 8.2666667 | D7: 23.25 | E7: =E4 -> 0.2016
A8: Heatsink | B8: 3.16 | C8: 4.1333333 | D8: 11.366667 | E8: 0
A9: Voltage Converter - HV | B9: 1.994 | C9: 27.383333 | D9: 26.866667 | E9: 0
A10: Current Measurement | B10: 2.256 | C10: 48.05 | D10: 47.533333 | E10: =E4 -> 0.2016
A11: Protection Control | B11: 5.512 | C11: 29.966667 | D11: 29.45 | E11: 0
A12: Protection Command | B12: 1.715 | C12: 32.55 | D12: 32.033333 | E12: 0
A13: Voltage Converter - LV | B13: 3.594 | C13: 40.3 | D13: 39.783333 | E13: =E7 -> 0.2016
A14: Transformer - LV-HV Zone | B14: 6.888 | C14: 42.883333 | D14: 42.366667 | E14: 0
A15: Communication - Protocol LIN | B15: 4.992 | C15: 48.05 | D15: 47.533333 | E15: 0
A16: Board | B16: 254.88 | C16: -269.18333 | D16: -265.56667 | E16: 0
A17: Transport | B17: 0 | C17: 0 | D17: 0 | E17: 0
A18: Package | B18: 0 | C18: 0 | D18: 0 | E18: 0
A19: EOL | B19: 0 | C19: 0 | D19: 0 | E19: 0

Sheet Staircase
A1: skip | C1: Informations
A3: Service life (year) | B3: 20 | C3: Duration of use of the staircase curve.
A4: Annual usage time (hours/year) | B4: 5000 | C4: Operating duration in hours per year for the entire system. This information is linked to the 'Inventory - Use' sheet, where each activity represents the energy consumption per hour of the RUs.
A5: Time step (step/year) | B5: 1 | C5: Time step for the staircase curve; for example, a time step of 1 means that the points on the staircase curve are spaced 1 year apart.
A7: Early failure | B7: True | C7: Modeling of failure: choose 'True' if this type of failure is considered, or 'False' if it is not considered.
A8: Random failure | B8: True | C8: Modeling of failure: choose 'True' if this type of failure is considered, or 'False' if it is not considered.
A9: Wearout failure | B9: True | C9: Modeling of failure: choose 'True' if this type of failure is considered, or 'False' if it is not considered.
A11: Preventive Maintenance | B11: True | C11: Modeling of maintenance of RU: choose 'True' if maintenance is considered, or 'False' if it is not considered.
A13: Monte Carlo (number of iteration) | B13: 1000 | C13: Number of iterations for the staircase curve (due to the probabilistic distribution of faults). Note that the staircase curve is calculated deterministically for each iteration, but Monte Carlo iterations allow to determine the distribution of impacts. If you select the number 1, the staircase curve will be presented in a different way.
A15: Plot specific env. impact | B15: 16 | C15: All staircase curves for each impact are displayed on a single plot. However, this number is an option to show the staircase curve for a selected impact on a separate plot. The number corresponds to the impact listed in the 'LCIA' sheet, ranked by the same number.

Sheet Faults & Prev. Maint.
A1: skip
A2: Informations | B2: The tool models the failure of a Replacement Unit (RU) across three life stages: the 'Early' phase (associated with design or manufacturing issues that were not adequately controlled), the 'Random' phase (where failures occur randomly), and the 'Wear-out' phase (resulting from wear and tear). This sheet allows you to specify the parameters necessary to create failure functions (probability distributions) for the RUs. The probability distribution used to model failures is Weibull, characterized by two parameters: β (the shape parameter) and σ (the scale parameter - in years). Failures during the early phase have β < 1, random failures have β = 1, and wear-out failures have β > 1. Maintenance (year) defines the preventive maintenance time for each RU.
B4: Early failure (sigma, year) | C4: Early failure (beta) | D4: Random failure (sigma, year) | E4: Random failure (beta) | F4: Wear-out failure (sigma, year) | G4: Wear-out failure (beta) | H4: Prev. Maintenance (year)
A5: SiC MOSFET Transistor #1 | B5: 3424 | C5: 0.6 | D5: 1141 | E5: 1 | F5: 14 | G5: 7.59 | H5: 13
A6: SiC MOSFET Transistor #2 | B6: 3424 | C6: 0.6 | D6: 1141 | E6: 1 | F6: 14 | G6: 7.59 | H6: 13
A7: Heatsink | B7: 10000 | C7: 0.6 | D7: 10000 | E7: 1 | F7: 10000 | G7: 7.59 | H7: 10000
A8: Voltage Converter - HV | B8: 10000 | C8: 0.6 | D8: 324 | E8: 1.0266 | F8: 10000 | G8: 7.59 | H8: 10000
A9: Current Measurement | B9: 10000 | C9: 0.6 | D9: 324 | E9: 1.0266 | F9: 10000 | G9: 7.59 | H9: 10000
A10: Protection Control | B10: 10000 | C10: 0.6 | D10: 324 | E10: 1.0266 | F10: 10000 | G10: 7.59 | H10: 10000
A11: Protection Command | B11: 10000 | C11: 0.6 | D11: 324 | E11: 1.0266 | F11: 10000 | G11: 7.59 | H11: 10000
A12: Voltage Converter - LV | B12: 10000 | C12: 0.6 | D12: 324 | E12: 1.0266 | F12: 10000 | G12: 7.59 | H12: 10000
A13: Transformer - LV-HV Zone | B13: 10000 | C13: 0.6 | D13: 324 | E13: 1.0266 | F13: 10000 | G13: 7.59 | H13: 10000
A14: Communication - Protocol LIN | B14: 10000 | C14: 0.6 | D14: 324 | E14: 1.0266 | F14: 10000 | G14: 7.59 | H14: 10000
A15: Board | B15: 10000 | C15: 0.6 | D15: 10000 | E15: 1 | F15: 10000 | G15: 7.59 | H15: 10000
A16: Transport | B16: 10000 | C16: 0.6 | D16: 10000 | E16: 1 | F16: 10000 | G16: 8 | H16: 10000
... A18: EOL | B18: 10000 | C18: 0.6 | D18: 10000 | E18: 1 | F18: 10000 | G18: 8 | H18: 10000

Sheet Cur. Maint. (replac. matrix)
A1: skip
A2: Informations | B2: The tool allows models the diagnosis associated with the system, specifically detailing the replacement scenarios when a fault occurs. This includes identifying what components are replaced within the system, To achieve this, this sheet constructs the Replacement Matrix (RM). The numbers in the matrix represent the average proportion of each component replaced when a fault occurs in a specific RU, with values ranging from 0 to 1. Row indices represent faults in a specific RU (e.g., Fault RU1), while column indices represent the RUs to be replaced (e.g., RU1). To clarify, consider an example with 2 RUs, resulting in a 2x2 matrix. In this example, if the value in the first row, first column (Fault RU1 ; RU1) is 1, and the value in the first row, second column (Fault RU1 ; RU2) is 0.6, this means that when a fault occurs in RU1, 100% of RU1 and 60% of RU2 are replaced according to the diagnosis.
B4: SiC MOSFET Transistor #1 | C4: SiC MOSFET Transistor #2 | D4: Voltage Converter - HV | E4: Current Measurement | F4: Protection Control | G4: Protection Command | H4: Voltage Converter – LV | I4: Transformer - LV-HV Zone | J4: Communication - Protocol LIN | K4: Heatsink | L4: Board | M4: Transport | N4: Package | O4: EOL
A5: Fault SiC MOSFET Transistor #1 | B5: 1 | C5: 0.5 | D5: 0 | E5: 0 | F5: 0 | G5: 0 | H5: 0 | I5: 0 | J5: 0 | K5: 0 | L5: 0 | M5: 0 | N5: 0 | O5: 0
A6: Fault SiC MOSFET Transistor #2 | B6: 0.5 | C6: 1 | D6: 0 | E6: 0 | F6: 0 | G6: 0 | H6: 0 | I6: 0 | J6: 0 | K6: 0 | L6: 0 | M6: 0 | N6: 0 | O6: 0
A7: Fault Voltage Converter - HV | B7: 0 | C7: 0 | D7: 1 | E7: 0 | F7: 0 | G7: 0 | H7: 0 | I7: 0 | J7: 0 | K7: 0 | L7: 0 | M7: 0 | N7: 0 | O7: 0
A8: Fault Current Measurement | B8: 0 | C8: 0 | D8: 0 | E8: 1 | F8: 0 | G8: 0 | H8: 0 | I8: 0 | J8: 0 | K8: 0 | L8: 0 | M8: 0 | N8: 0 | O8: 0
A9: Fault Protection Control | B9: 0 | C9: 0 | D9: 0 | E9: 0 | F9: 1 | G9: 0 | H9: 0 | I9: 0 | J9: 0 | K9: 0 | L9: 0 | M9: 0 | N9: 0 | O9: 0
A10: Fault Protection Command | B10: 0 | C10: 0 | D10: 0 | E10: 0 | F10: 0 | G10: 1 | H10: 0 | I10: 0 | J10: 0 | K10: 0 | L10: 0 | M10: 0 | N10: 0 | O10: 0
A11: Fault Voltage Converter – LV | B11: 0 | C11: 0 | D11: 0 | E11: 0 | F11: 0 | G11: 0 | H11: 1 | I11: 0 | J11: 0 | K11: 0 | L11: 0 | M11: 0 | N11: 0 | O11: 0
A12: Fault Transformer - LV-HV Zone | B12: 0 | C12: 0 | D12: 0 | E12: 0 | F12: 0 | G12: 0 | H12: 0 | I12: 1 | J12: 0 | K12: 0 | L12: 0 | M12: 0 | N12: 0 | O12: 0
A13: Fault Communication - Protocol LIN | B13: 0 | C13: 0 | D13: 0 | E13: 0 | F13: 0 | G13: 0 | H13: 0 | I13: 0 | J13: 1 | K13: 0 | L13: 0 | M13: 0 | N13: 0 | O13: 0
A14: Fault Heatsink | B14: 0 | C14: 0 | D14: 0 | E14: 0 | F14: 0 | G14: 0 | H14: 0 | I14: 0 | J14: 0 | K14: 1 | L14: 0 | M14: 0 | N14: 0 | O14: 0
A15: Fault Board | B15: 1 | C15: 1 | D15: 1 | E15: 1 | F15: 1 | G15: 1 | H15: 1 | I15: 1 | J15: 1 | K15: 1 | L15: 1 | M15: 1 | N15: 1 | O15: 1
A16: Fault Transport | B16: 0 | C16: 0 | D16: 0 | E16: 0 | F16: 0 | G16: 0 | H16: 0 | I16: 0 | J16: 0 | K16: 0 | L16: 0 | M16: 0 | N16: 0 | O16: 0
... A18: Fault EOL | B18: 0 | C18: 0 | D18: 0 | E18: 0 | F18: 0 | G18: 0 | H18: 0 | I18: 0 | J18: 0 | K18: 0 | L18: 0 | M18: 0 | N18: 0 | O18: 0

Sheet BOM
B1: Bill of Materials - ACV
C3: Board | D3: MSCDR-EFUSE-006
I4: Mass (g) | J4: {=SUM(B6:B54*I6:I54)*10^-3} -> 101.43414
A5: Tag | B5: Quantité | C5: Designator | D5: PartType | E5: Description | F5: Manufacturer | G5: Manufacturer Part Number | H5: Supplier | I5: Weight Unit (mg) | J5: Total (mg) | K5: Notes | L5: Material Declaration DataSheet | M5: PRIX (Unitaire) | N5: Informations | O5: TOTAL (Prix)
A6: #1 | B6: 12 | C6: C1, C4, C9, C11, C12, C13, C100, C102, C104, C105, C106, C112 | D6: Capacitor NP | E6: CAP CER 100nF 50V 10% X7R SMD 0603 AEC-Q200 | F6: TDK | G6: CGA3E2X7R1H104K080AA | H6: Mousser | I6: 5.12 | J6: =B6*I6 -> 61.44 | L6: https://4donline.ihs.com/images/VipMasterIC/IC/TDKC/TDKC-E-A0011842620/TDKC-E-A0011842517-1.pdf?hkey=6D0214268300F1406B835FE51CB13195 | M6: =0.042 -> 0.042 | N6: x10 | O6: =B6*M6 -> 0.504
A7: #2 | B7: 1 | C7: C2 | D7: Capacitor NP | E7: CAP CER 10000pF 100V 10% X7R SMD 0805 | F7: KEMET | G7: C0805C103K1RACTU | H7: Mousser | I7: 18.97 | J7: =B7*I7 -> 18.97 | L7: https://4donline.ihs.com/images/VipMasterIC/IC/KEME/KEME-E-A0001615328/KEME-E-A0001615328-1.pdf?hkey=6D0214268300F1406B835FE51CB13195 | M7: 0.028 | N7: x10 | O7: =B7*M7 -> 0.028
A8: #3 | B8: 4 | C8: C3, C6, C7, C101 | D8: Capacitor NP | E8: CAP CER 10uF 50V 10% X7R AEC-Q200 SMD 1206 | F8: TDK | G8: CGA5L1X7R1H106K160AC | H8: Mousser | I8: 40.96 | J8: =B8*I8 -> 163.84 | L8: https://4donline.ihs.com/images/VipMasterIC/IC/TDKC/TDKC-E-A0011842620/TDKC-E-A0011842620-1.pdf?hkey=6D0214268300F1406B835FE51CB13195 | M8: 0.627 | N8: x10 | O8: =B8*M8 -> 2.508
A9: #4 | B9: 3 | C9: C5, C103, C107 | D9: Capacitor NP | E9: CAP CER 4.7uF 16V 10% X7R SMD 1206 | F9: KEMET | G9: C1206C475K4RACTU | H9: Mousser | I9: 47.52 | J9: =B9*I9 -> 142.56 | L9: https://4donline.ihs.com/images/VipMasterIC/IC/KEME/KEME-E-A0001615328/KEME-E-A0001615328-1.pdf?hkey=6D0214268300F1406B835FE51CB13195 | M9: 0.21 | N9: x10 | O9: =B9*M9 -> 0.63
A10: #5 | B10: 1 | C10: C8 | D10: Capacitor NP | E10: CAP CER 1uF 25V 10% X7R SMD 0805 | F10: KEMET | G10: C0805C105K3RACTU | H10: Mousser | I10: 18.97 | J10: =B10*I10 -> 18.97 | L10: https://4donline.ihs.com/images/VipMasterIC/IC/KEME/KEME-E-A0001615328/KEME-E-A0001615328-1.pdf?hkey=6D0214268300F1406B835FE51CB13195 | M10: 0.06 | N10: x10 | O10: =B10*M10 -> 0.06
A11: #6 | B11: 3 | C11: C10, C108, C109 | D11: Capacitor NP | E11: CAP CER 4.7uF 2.5kV 10% X7R 1812 AEC-Q200 | F11: Knowles Syfer | G11: 1812YA250472KJTSYX | H11: Kyocera AVX | I11: 6 | J11: =B11*I11 -> 18 | L11: https://www.mouser.fr/ProductDetail/Knowles-Syfer/1812YA250472KSTUYX?qs=Li%252BoUPsLEnsBdpS5E0JL2Q%3D%3D | M11: 2 | N11: x10 | O11: =B11*M11 -> 6
A12: #7 | B12: 1 | C12: C14 | D12: Capacitor NP | E12: CAP CER 220pF 100V 5% C0G SMD 0805 AEC-Q200 | F12: Kyocera AVX | G12: 08051A221J4T2A | H12: Mousser | I12: 12 | J12: =B12*I12 -> 12 | L12: https://4donline.ihs.com/images/VipMasterIC/IC/AVXC/AVXCE00537/AVXCE00537-1.pdf?hkey=6D0214268300F1406B835FE51CB13195 | M12: 0.128 | N12: x10 | O12: =B12*M12 -> 0.128
A13: #8 | B13: 3 | C13: C110, C111, C116 | D13: Capacitor NP | E13: CAP CER 100pF 50V 5% C0G AEC-Q200 SMD 0603 | F13: KEMET | G13: C0603C101J5GACAUTO | H13: Mousser | I13: 4.51 | J13: =B13*I13 -> 13.53 | L13: https://4donline.ihs.com/images/VipMasterIC/IC/KEME/KEME-E-A0001262239/KEME-E-A0001262239-1.pdf?hkey=6D0214268300F1406B835FE51CB13195 | M13: 0.066 | N13: x10 | O13: =B13*M13 -> 0.198
A14: #9 | B14: 4 | C14: C114, C115, C117, C118 | D14: Capacitor NP | E14: CAP CER 10nF 50V 10% X7R SMD 0603 AEC-Q200 | F14: KEMET | G14: C0603C103K5RACAUTO | H14: Mousser | I14: 6.01 | J14: =B14*I14 -> 24.04 | L14: https://4donline.ihs.com/images/VipMasterIC/IC/KEME/KEME-E-A0001615328/KEME-E-A0001615328-1.pdf?hkey=6D0214268300F1406B835FE51CB13195 | M14: 0.05 | N14: x10 | O14: =B14*M14 -> 0.2
A15: #10 | B15: 1 | C15: D1 | D15: Diode Single | E15: DIO RECT S1G 1.1V 1A 400V DO-214AC_SMA | F15: Diodes | G15: S1GB-13-F | H15: Mousser | I15: 64 | J15: =B15*I15 -> 64 | L15: https://4donline.ihs.com/images/VipMasterIC/IC/DIOD/DIODE01223/DIODE01223-1.pdf?hkey=6D0214268300F1406B835FE51CB13195 | M15: 0.119 | N15: x10 | O15: =B15*M15 -> 0.119
A16: #11 | B16: 1 | C16: D2 | D16: Diode TVS Bidirectional | E16: DIODE TVS BI-DIRECTIONAL SM6T39CAHE3_A/I 39V 11.1A DO214AA | F16: Vishay | G16: SM6T39CAHE3_A/I | H16: Mousser | I16: 93 | J16: =B16*I16 -> 93 | L16: https://www.mouser.fr/ProductDetail/Vishay-General-Semiconductor/SM6T39CAHE3_A-I?qs=wnTfsH77Xs4WnCm%252BGW997Q%3D%3D&utm_source=octopart&utm_medium=aggregator&utm_campaign=78-SM6T39CAHE3_A%2FI&utm_content=Vishayabout:blank | M16: 0.543 | N16: x10 | O16: =B16*M16 -> 0.543
A17: #12 | B17: 2 | C17: D3, D102 | D17: LED_green | E17: DIO LED GREEN 2.2V 25mA 15mcd Clear SMD 0603 | F17: Kingbright | G17: APT1608SGC | H17: Mousser | I17: 1.6 | J17: =B17*I17 -> 3.2 | L17: https://4donline.ihs.com/images/VipMasterIC/IC/KBEC/KBEC-E-A0011842624/KBEC-E-A0011842563-1.pdf?hkey=6D0214268300F1406B835FE51CB13195 | M17: 0.14 | N17: x10 | O17: =B17*M17 -> 0.28
A18: #13 | B18: 1 | C18: D4 | D18: Diode Dual AK | E18: DIO SCTKY ARRAY BAS70-04-7-F 1V 15mA SOT-23-3 | F18: Diodes | G18: BAS70-04-7-F | H18: Mousser | I18: 8 | J18: =B18*I18 -> 8 | L18: https://4donline.ihs.com/images/VipMasterIC/IC/DIOD/DIOD-E-A0002837426/DIOD-E-A0002837398-1.pdf?hkey=6D0214268300F1406B835FE51CB13195 | M18: 0.09 | N18: x10 | O18: =B18*M18 -> 0.09
... A23: #18 | B23: 1 | C23: J1 | D23: Header 1x3 | E23: CON TERMINAL 5mm 1x3 Female 12-28AWG 16A TH R/A | F23: On-Shore Technology | G23: OSTVI030152 | H23: Digi-Key | I23: 5.5 | J23: =B23*I23 -> 5.5 | L23: https://www.on-shore.com/wp-content/uploads/OSTVIXX0152-1.pdf | M23: 1.09 | N23: x10 (Digikey) | O23: =B23*M23 -> 1.09
A24: #19 | B24: 2 | C24: J2, J101 | D24: Header 1x6 | E24: CON TAG 6P No-Leg SMD VERT | F24: Microchip | G24: TC2030-MCP-NL | H24: Mousser | I24: 13000 | J24: =B24*I24 -> 26000 | L24: https://www.mouser.fr/ProductDetail/Microchip-Technology/TC2030-MCP-NL?qs=vpV3rcoeaPNaPItFBtR60A%3D%3D&srsltid=AfmBOoroeVT1BBBs631UaUdvalHDSBcG58fy9TAXk0H4vcDK1ADUpEG9 | M24: 0 | O24: =B24*M24 -> 0
A25: #20 | B25: 2 | C25: J100, J102 | D25: Header 1x1 | E25: CON TERMINAL 30A Female 1x1 TH VERT | F25: Keystone Electronics | G25: 8197 | H25: Mousser | I25: 1810 | J25: =B25*I25 -> 3620 | L25: https://www.mouser.fr/ProductDetail/Keystone-Electronics/8197?qs=lQmX4aIt5iCLtZsmTLO7fw%3D%3D&utm_source=octopart&utm_medium=aggregator&utm_campaign=534-8197&utm_content=Keystone%20Electronics | M25: 0 | O25: =B25*M25 -> 0
A26: #21 | B26: 1 | C26: LABEL1 | D26: 08-10015 | E26: LABEL PCBA 18x6mm Datamatrix Assy# / Rev / Serial / Date | F26: ACT Logimark AS | G26: 505462 | H26: ACT Logimark AS | J26: =B26*I26 -> 0 | M26: 0 | O26: =B26*M26 -> 0
A27: #22 | B27: 3 | C27: Q1, Q3, Q102 | D27: 2N7002BK,215_SOT-23-3 | E27: TRANS FET N-CH 2N7002BK,215 60V 350mA 370mW SOT-23-3 | F27: Nexperia | G27: 2N7002BK,215 | H27: Mousser | I27: 7.49697 | J27: =B27*I27 -> 22.49091 | L27: https://4donline.ihs.com/images/VipMasterIC/IC/NEXP/NEXP-E-A0014738174/NEXP-E-A0014737527-1.pdf?hkey=6D0214268300F1406B835FE51CB13195 | M27: 0.149 | N27: x10 | O27: =B27*M27 -> 0.447
A28: #23 | B28: 1 | C28: Q2 | D28: Transistor MOS-P GSD | E28: TRANS FET P-CH Si2333DS -12V -4.1A 750mW SOT-23-3 | F28: Vishay Siliconix | G28: SI2333DS-T1-E3 | H28: Mousser | I28: 11.05 | J28: =B28*I28 -> 11.05 | L28: https://4donline.ihs.com/images/VipMasterIC/IC/VISH/VISH-E-A0001817585/VISH-E-A0001817609-1.pdf?hkey=6D0214268300F1406B835FE51CB13195 | M28: 0.735 | N28: x10 | O28: =B28*M28 -> 0.735
A29: #24 | B29: 2 | C29: Q100, Q101 | D29: Transistor Sic MOS-N DSG | E29: TRANS FET N-CH SiC MSC035SMA070B4 700V 77A 283W TO-247-4 | F29: Microchip | G29: MSC025SMA120B4 | H29: Mousser | I29: 6200 | J29: =B29*I29 -> 12400 | L29: https://www.mouser.fr/datasheet/2/268/MSC035SMA070B_SiC_MOSFET_Datasheet-3444372.pdf | M29: 39.26 | N29: x1 | O29: =B29*M29 -> 78.52
A30: #25 | B30: 1 | C30: R1 | D30: Resistor | E30: RES TKF 4.7R 1% 1/4W SMD 1206 | F30: Panasonic | G30: ERJ-8RQF4R7V | H30: Mousser | I30: 9.86576 | J30: =B30*I30 -> 9.86576 | L30: https://4donline.ihs.com/images/VipMasterIC/IC/PANA/PANAE00764/PANAE00764-1.pdf?hkey=6D0214268300F1406B835FE51CB13195 | M30: 0.099 | N30: x10 | O30: =B30*M30 -> 0.099
A31: #26 | B31: 6 | C31: R2, R7, R10, R18, R19, R117 | D31: Resistor | E31: RES TKF 10k 5% 1/10W SMD 0603 | F31: YAGEO | G31: RC0603JR-0710KL | H31: Mousser | I31: 2.47343 | J31: =B31*I31 -> 14.84058 | L31: https://4donline.ihs.com/images/VipMasterIC/IC/YAGO/YAGO-E-A0011552245/YAGO-E-A0011552245-1.pdf?hkey=6D0214268300F1406B835FE51CB13195 | M31: 0.008 | N31: x10 | O31: =B31*M31 -> 0.048
A32: #27 | B32: 1 | C32: R3 | D32: Resistor | E32: RES TKF 0R 1/10W AEC-Q200 SMD 0603 | F32: Panasonic | G32: ERJ-3GEY0R00V | H32: Mousser | I32: 2.1323 | J32: =B32*I32 -> 2.1323 | L32: https://4donline.ihs.com/images/VipMasterIC/IC/VISH/VISH-E-A0015667156/VISH-E-A0015667087-1.pdf?hkey=6D0214268300F1406B835FE51CB13195 | M32: 0.014 | N32: x10 | O32: =B32*M32 -> 0.014
A33: #28 | B33: 2 | C33: R4, R5 | D33: Resistor | E33: RES TKF 10k 5% 1/8W SMD 0805 | F33: Yageo | G33: RC0805JR-0710KL | H33: Mouser | I33: 4.54 | J33: =B33*I33 -> 9.08 | L33: https://4donline.ihs.com/images/VipMasterIC/IC/KOAS/KOAS-E-A0002571303/KOAS-E-A0002571303-1.pdf?hkey=6D0214268300F1406B835FE51CB13195 | M33: 0.011 | N33: x10 | O33: =B33*M33 -> 0.022
A34: #29 | B34: 7 | C34: R6, R8, R9, R20, R103, R105, R107 | D34: Resistor | E34: RES TKF 100k 5% 1/10W SMD 0603 (Don't Use, Duplicate, Use RSMT0026) | F34: Panasonic | G34: ERJ-3GEYJ104V | H34: Mousser | I34: 2.16112 | J34: =B34*I34 -> 15.12784 | L34: https://4donline.ihs.com/images/VipMasterIC/IC/PANA/PANAE01161/PANAE01161-1.pdf?hkey=6D0214268300F1406B835FE51CB13195 | M34: 0.019 | N34: x10 | O34: =B34*M34 -> 0.133
A35: #30 | B35: 2 | C35: R11, R12 | D35: Resistor | E35: RES TKF 4.7k 5% 1/10W SMD 0603 | F35: Panasonic | G35: ERJ-3GEYJ472V | H35: Mousser | I35: 2.16112 | J35: =B35*I35 -> 4.32224 | L35: https://4donline.ihs.com/images/VipMasterIC/IC/PANA/PANAE01161/PANAE01161-1.pdf?hkey=6D0214268300F1406B835FE51CB13195 | M35: 0.019 | N35: x10 | O35: =B35*M35 -> 0.038
A36: #31 | B36: 7 | C36: R13, R14, R15, R16, R17, R109, R118 | D36: Resistor | E36: RES TKF 100R 5% 1/10W SMD 0603 | F36: Yageo | G36: RC0603JR-07100RL | H36: Mousser | I36: 2.47343 | J36: =B36*I36 -> 17.31401 | L36: https://4donline.ihs.com/images/VipMasterIC/IC/YAGO/YAGO-E-A0011552245/YAGO-E-A0011552245-1.pdf?hkey=6D0214268300F1406B835FE51CB13195 | M36: 0.008 | N36: x10 | O36: =B36*M36 -> 0.056
A37: #32 | B37: 7 | C37: R100, R108, R111, R112, R120, R123, R125 | D37: Resistor | E37: RES TKF 20k 1% 1/10W SMD 0603 | F37: Yageo | G37: RC0603FR-0720KL | H37: Mousser | I37: 2.47343 | J37: =B37*I37 -> 17.31401 | L37: https://4donline.ihs.com/images/VipMasterIC/IC/YAGO/YAGO-E-A0011552245/YAGO-E-A0011552245-1.pdf?hkey=6D0214268300F1406B835FE51CB13195 | M37: 0.01 | N37: x10 | O37: =B37*M37 -> 0.07
A38: #33 | B38: 3 | C38: R101, R102, R104 | D38: Resistor | E38: RES TKF 20R 5% 1/16W SMD 0805 | F38: Panasonic | G38: ERJ-6GEYJ200V | H38: Mousser | I38: 4.81295 | J38: =B38*I38 -> 14.43885 | L38: https://4donline.ihs.com/images/VipMasterIC/IC/PANA/PANAE00775/PANAE00775-1.pdf?hkey=6D0214268300F1406B835FE51CB13195 | M38: 0.024 | N38: x10 | O38: =B38*M38 -> 0.072
A39: #34 | B39: 1 | C39: R106 | D39: Shunt 4 Pin | E39: RES SHUNT MS 0.002R 1% 5W SMD 2726 AEC-Q200 | F39: Vishay Dale | G39: WSLP27262L000FEA | H39: Mousser | I39: 420 | J39: =B39*I39 -> 420 | K39: % par 1000 | L39: https://www.vishay.com/docs/30179/wslp2726.pdf | M39: 1.89 | N39: x10 | O39: =B39*M39 -> 1.89
A40: #35 | B40: 2 | C40: R110, R114 | D40: Resistor | E40: RES TKF 18R 5% 1.5W SMD 2512 | F40: Stackpole Electronics | G40: RPC2512JT18R0 | H40: Mouser | I40: 39.448 | J40: =B40*I40 -> 78.896 | K40: % par 1000 | L40: https://4donline.ihs.com/images/VipMasterIC/IC/SEIE/SEIE-E-A0011298520/SEIE-E-A0011298520-1.pdf?hkey=6D0214268300F1406B835FE51CB13195 | M40: 0.106 | N40: x4000 | O40: =B40*M40 -> 0.212
A41: #36 | B41: 3 | C41: R113, R115, R124 | D41: Resistor | E41: RES TKF 10k 1% 1/10W SMD 0603 AEC-Q200, RES TKF 10k 1% 1/10W AEC-Q200 SMD 0603 | F41: KOA Speer | G41: RK73H1JTTD1002F | H41: Mousser | I41: 2 | J41: =B41*I41 -> 6 | L41: https://www.mouser.fr/ProductDetail/KOA-Speer/RK73H1JTTD1002F?qs=%252BHd4ebZ%252Bq6V15kIYdKv25A%3D%3D&utm_source=octopart&utm_medium=aggregator&utm_campaign=660-RK73H1JTTD1002F&utm_content=KOA%20Speer | M41: 0.023 | N41: x10 | O41: =B41*M41 -> 0.069
A42: #37 | B42: 2 | C42: R116, R119 | D42: Resistor | E42: RES TKF 1k 1% 1/10W SMD 0603 | F42: Stackpole Electronics | G42: RMCF0603FT1K00 | H42: Mousser | I42: 2.47343 | J42: =B42*I42 -> 4.94686 | L42: https://4donline.ihs.com/images/VipMasterIC/IC/YAGO/YAGO-E-A0012006210/YAGO-E-A0012006210-1.pdf?hkey=6D0214268300F1406B835FE51CB13195 | M42: 0.017 | N42: x10 | O42: =B42*M42 -> 0.034
A43: #38 | B43: 2 | C43: R121, R126 | D43: Resistor | E43: RES TKF 4.7K 1% 1/10W SMD 0603 | F43: Panasonic | G43: ERJ-3EKF4701V | H43: Mousser | I43: 2 | J43: =B43*I43 -> 4 | L43: https://www.mouser.fr/ProductDetail/Panasonic/ERJ-3EKF4701V?qs=MVjVSMjNRMouVvwnqrpO2w%3D%3D&utm_source=octopart&utm_medium=aggregator&utm_campaign=667-ERJ-3EKF4701V&utm_content=Panasonic&_gl=1*18jj3c0*_ga*dW5kZWZpbmVk*_ga_15W4STQT4T*dW5kZWZpbmVk*_ga_1KQLCYKRX3*dW5kZWZpbmVk | M43: 0.029 | N43: x10 | O43: =B43*M43 -> 0.058
A44: #39 | B44: 1 | C44: R122 | D44: Resistor | E44: RES TKF 100k 1% 1/10W AEC-Q200 SMD 0603 | F44: KOA Speer | G44: RK73H1JTTD1003F | H44: Mousser | I44: 2.14 | J44: =B44*I44 -> 2.14 | L44: https://4donline.ihs.com/images/VipMasterIC/IC/KOAS/KOASE00031/KOASE00031-1.pdf?hkey=6D0214268300F1406B835FE51CB13195 | M44: 0.017 | N44: x10 | O44: =B44*M44 -> 0.017
A45: #40 | B45: 1 | C45: TH100 | D45: Thermistor NTC | E45: RES THERMISTOR NTC 10K 3380K 1% SMD 0603 | F45: Murata | G45: NCU18XH103F6SRB | H45: Mousser | I45: 4.7 | J45: =B45*I45 -> 4.7 | L45: https://www.mouser.fr/datasheet/2/281/NCU18XH103F6SRB-1108705.pdf | M45: 0.105 | N45: x10 | O45: =B45*M45 -> 0.105
...

Sheet Cost
B1: Bill of Materials - Cost
C3: Board | D3: MSCDR-EFUSE-006 | E3: 365.69
A5: Tag | B5: Quantité | C5: Designator | D5: PartType | E5: PRIX (Unitaire) | F5: Informations | G5: TOTAL (Prix)
A6: #24 | B6: 1 | C6: Q100 | D6: Transistor Sic MOS-N DSG | E6: 39.26 | F6: x1 | G6: =B6*E6 -> 39.26
A7: #24 | B7: 1 | C7: Q101 | D7: Transistor Sic MOS-N DSG | E7: 39.26 | F7: x1 | G7: =B7*E7 -> 39.26
A8: #34 | B8: 1 | C8: R106 | D8: Shunt 4 Pin | E8: 1.89 | F8: x10 | G8: =B8*E8 -> 1.89
A9: #17 | B9: 1 | C9: Heatsink100 | D9: Heatsink_OMNI-UNI-27-50 | E9: 3.16 | F9: x1000 | G9: =B9*E9 -> 3.16 | H9: =SUM(G6:G9) -> 83.57 | I9: Fuse
A10: #1 | B10: 12 | C10: C1, C4, C9, C11, C12, C13, C100, C102, C104, C105, C106, C112 | D10: Capacitor NP | E10: =0.042 -> 0.042 | F10: x10 | G10: =B10*E10 -> 0.504
A11: #2 | B11: 1 | C11: C2 | D11: Capacitor NP | E11: 0.028 | F11: x10 | G11: =B11*E11 -> 0.028
A12: #3 | B12: 4 | C12: C3, C6, C7, C101 | D12: Capacitor NP | E12: 0.627 | F12: x10 | G12: =B12*E12 -> 2.508
A13: #4 | B13: 3 | C13: C5, C103, C107 | D13: Capacitor NP | E13: 0.21 | F13: x10 | G13: =B13*E13 -> 0.63
A14: #5 | B14: 1 | C14: C8 | D14: Capacitor NP | E14: 0.06 | F14: x10 | G14: =B14*E14 -> 0.06
A15: #6 | B15: 3 | C15: C10, C108, C109 | D15: Capacitor NP | E15: 2 | F15: x10 | G15: =B15*E15 -> 6
A16: #7 | B16: 1 | C16: C14 | D16: Capacitor NP | E16: 0.128 | F16: x10 | G16: =B16*E16 -> 0.128
A17: #8 | B17: 3 | C17: C110, C111, C116 | D17: Capacitor NP | E17: 0.066 | F17: x10 | G17: =B17*E17 -> 0.198
A18: #9 | B18: 4 | C18: C114, C115, C117, C118 | D18: Capacitor NP | E18: 0.05 | F18: x10 | G18: =B18*E18 -> 0.2 | H18: =SUM(G10:G18) -> 10.256 | I18: NP Capacitors
A19: #25 | B19: 1 | C19: R1 | D19: Resistor | E19: 0.099 | F19: x10 | G19: 0.099
A20: #26 | B20: 6 | C20: R2, R7, R10, R18, R19, R117 | D20: Resistor | E20: 0.008 | F20: x10 | G20: 0.048
A21: #27 | B21: 1 | C21: R3 | D21: Resistor | E21: 0.014 | F21: x10 | G21: 0.014
A22: #28 | B22: 2 | C22: R4, R5 | D22: Resistor | E22: 0.011 | F22: x10 | G22: 0.022
A23: #29 | B23: 7 | C23: R6, R8, R9, R20, R103, R105, R107 | D23: Resistor | E23: 0.019 | F23: x10 | G23: 0.133
A24: #30 | B24: 2 | C24: R11, R12 | D24: Resistor | E24: 0.019 | F24: x10 | G24: 0.038
A25: #31 | B25: 7 | C25: R13, R14, R15, R16, R17, R109, R118 | D25: Resistor | E25: 0.008 | F25: x10 | G25: 0.056
A26: #32 | B26: 7 | C26: R100, R108, R111, R112, R120, R123, R125 | D26: Resistor | E26: 0.01 | F26: x10 | G26: 0.07
A27: #33 | B27: 3 | C27: R101, R102, R104 | D27: Resistor | E27: 0.024 | F27: x10 | G27: 0.072
A28: #35 | B28: 2 | C28: R110, R114 | D28: Resistor | E28: 0.106 | F28: x4000 | G28: 0.212
A29: #36 | B29: 3 | C29: R113, R115, R124 | D29: Resistor | E29: 0.023 | F29: x10 | G29: 0.069
A30: #37 | B30: 2 | C30: R116, R119 | D30: Resistor | E30: 0.017 | F30: x10 | G30: 0.034
A31: #38 | B31: 2 | C31: R121, R126 | D31: Resistor | E31: 0.029 | F31: x10 | G31: 0.058
A32: #39 | B32: 1 | C32: R122 | D32: Resistor | E32: 0.017 | F32: x10 | G32: 0.017 | H32: =SUM(G19:G32) -> 0.942 | I32: Resistors
A33: #10 | B33: 1 | C33: D1 | D33: Diode Single | E33: 0.119 | F33: x10 | G33: =B33*E33 -> 0.119
A34: #11 | B34: 1 | C34: D2 | D34: Diode TVS Bidirectional | E34: 0.543 | F34: x10 | G34: =B34*E34 -> 0.543
A35: #12 | B35: 2 | C35: D3, D102 | D35: LED_green | E35: 0.14 | F35: x10 | G35: =B35*E35 -> 0.28
A36: #13 | B36: 1 | C36: D4 | D36: Diode Dual AK | E36: 0.09 | F36: x10 | G36: =B36*E36 -> 0.09
A37: #14 | B37: 1 | C37: D5 | D37: PESD1LIN_SOD323 | E37: 0.163 | F37: x10 | G37: =B37*E37 -> 0.163
A38: #15 | B38: 1 | C38: D100 | D38: Diode Zener SOT-23-3 | E38: 0.072 | F38: x10 | G38: =B38*E38 -> 0.072
A39: #16 | B39: 1 | C39: D101 | D39: Diode Zener | E39: 0.126 | F39: x10 | G39: =B39*E39 -> 0.126 | H39: =SUM(G33:G39) -> 1.393 | I39: Diodes
A40: #22 | B40: 3 | C40: Q1, Q3, Q102 | D40: 2N7002BK,215_SOT-23-3 | E40: 0.149 | F40: x10 | G40: =B40*E40 -> 0.447
A41: #41 | B41: 1 | C41: TR1 | D41: Transformer_WE_760390014 | E41: 1.62 | F41: x10 | G41: =B41*E41 -> 1.62
A42: #46 | B42: 1 | C42: U100 | D42: MCP1754S SOT-23A-3 | E42: 0.637 | F42: x10 | G42: =B42*E42 -> 0.637
...

Sheet CAS_Code
A1: CAS - Code
A3: CAS Number | B3: Basic Substance
A4: 60676-86-0 | B4: Silica, vitreous (or fused)
A5: 68475-94-5 | B5: Epoxy Resin
A6: 1# Trade Secret | B6: Phenolic Resin
A7: 1333-86-4 | B7: Carbon Black
A8: 7439-89-6 | B8: Iron | Fe
A9: 7723-14-0 | B9: Phosphorous
A10: 7440-66-6 | B10: Zinc (Metal)
A11: 7440-22-4 | B11: Silver
A12: 1317-38-0 | B12: Copper(II) oxide
A13: 7440-21-3 | B13: Silicon
A14: 7440-50-8 | B14: Copper (Cu)
... A78: 409-21-2 | B78: Silicon Carbide

Sheet Report - BOM
A1: Report - BOM - Efuse
A3: Synthesis | D3: Top 10
A4: Composants | B4: =COUNTA(CAS_Component!B6:B211) -> 49 | D4: Basic Substance | E4: CAS CODE | F4: Total (mg)
A5: Total Composants | B5: =SUM(CAS_EFuse!A6:A126) -> 110 | C5: 1 | D5: =INDEX(CAS_Code!$B$4:$B$334, MATCH(E5,CAS_Code!$A$4:$A$334,0)) -> Aluminum | E5: =INDEX(CAS_EFuse!$E$5:$CH$5,MATCH(LARGE(CAS_EFuse!$E$4:$CH$4,C5), CAS_EFuse!$E$4:$CH$4,0)) -> 7429-90-5 | F5: =LARGE(CAS_EFuse!$E$4:$CH$4, C5) -> 58780.95
A6: Nb Materials Resources | B6: =COUNTA(CAS_Code!A4:A188) -> 75 | C6: 2 | D6: =INDEX(CAS_Code!$B$4:$B$334, MATCH(E6,CAS_Code!$A$4:$A$334,0)) -> Copper (Cu) | E6: =INDEX(CAS_EFuse!$E$5:$CH$5,MATCH(LARGE(CAS_EFuse!$E$4:$CH$4,C6), CAS_EFuse!$E$4:$CH$4,0)) -> 7440-50-8 | F6: =LARGE(CAS_EFuse!$E$4:$CH$4, C6) -> 10755.44
C7: 3 | D7: =INDEX(CAS_Code!$B$4:$B$334, MATCH(E7,CAS_Code!$A$4:$A$334,0)) -> Silica, vitreous (or fused) | E7: =INDEX(CAS_EFuse!$E$5:$CH$5,MATCH(LARGE(CAS_EFuse!$E$4:$CH$4,C7), CAS_EFuse!$E$4:$CH$4,0)) -> 60676-86-0 | F7: =LARGE(CAS_EFuse!$E$4:$CH$4, C7) -> 4239.1727
C8: 4 | D8: =INDEX(CAS_Code!$B$4:$B$334, MATCH(E8,CAS_Code!$A$4:$A$334,0)) -> Nickle (Ni) | E8: =INDEX(CAS_EFuse!$E$5:$CH$5,MATCH(LARGE(CAS_EFuse!$E$4:$CH$4,C8), CAS_EFuse!$E$4:$CH$4,0)) -> 7440-02-0 | F8: =LARGE(CAS_EFuse!$E$4:$CH$4, C8) -> 2341.7059
C9: 5 | D9: =INDEX(CAS_Code!$B$4:$B$334, MATCH(E9,CAS_Code!$A$4:$A$334,0)) -> Zinc (Metal) | E9: =INDEX(CAS_EFuse!$E$5:$CH$5,MATCH(LARGE(CAS_EFuse!$E$4:$CH$4,C9), CAS_EFuse!$E$4:$CH$4,0)) -> 7440-66-6 | F9: =LARGE(CAS_EFuse!$E$4:$CH$4, C9) -> 1986.3735
C10: 6 | D10: =INDEX(CAS_Code!$B$4:$B$334, MATCH(E10,CAS_Code!$A$4:$A$334,0)) -> Sn | Tin | E10: =INDEX(CAS_EFuse!$E$5:$CH$5,MATCH(LARGE(CAS_EFuse!$E$4:$CH$4,C10), CAS_EFuse!$E$4:$CH$4,0)) -> 7440-31-5 | F10: =LARGE(CAS_EFuse!$E$4:$CH$4, C10) -> 1312.3025
C11: 7 | D11: =INDEX(CAS_Code!$B$4:$B$334, MATCH(E11,CAS_Code!$A$4:$A$334,0)) -> Acide polylactique (PLA) | E11: =INDEX(CAS_EFuse!$E$5:$CH$5,MATCH(LARGE(CAS_EFuse!$E$4:$CH$4,C11), CAS_EFuse!$E$4:$CH$4,0)) -> 26100-51-6 | F11: =LARGE(CAS_EFuse!$E$4:$CH$4, C11) -> 1200
C12: 8 | D12: =INDEX(CAS_Code!$B$4:$B$334, MATCH(E12,CAS_Code!$A$4:$A$334,0)) -> Silicon dioxide | E12: =INDEX(CAS_EFuse!$E$5:$CH$5,MATCH(LARGE(CAS_EFuse!$E$4:$CH$4,C12), CAS_EFuse!$E$4:$CH$4,0)) -> 7631-86-9 | F12: =LARGE(CAS_EFuse!$E$4:$CH$4, C12) -> 752.81036
C13: 9 | D13: =INDEX(CAS_Code!$B$4:$B$334, MATCH(E13,CAS_Code!$A$4:$A$334,0)) -> Aluminum oxide : A1203 | E13: =INDEX(CAS_EFuse!$E$5:$CH$5,MATCH(LARGE(CAS_EFuse!$E$4:$CH$4,C13), CAS_EFuse!$E$4:$CH$4,0)) -> 1344-28-1 | F13: =LARGE(CAS_EFuse!$E$4:$CH$4, C13) -> 526.37666
C14: 10 | D14: =INDEX(CAS_Code!$B$4:$B$334, MATCH(E14,CAS_Code!$A$4:$A$334,0)) -> Epoxy Resin | E14: =INDEX(CAS_EFuse!$E$5:$CH$5,MATCH(LARGE(CAS_EFuse!$E$4:$CH$4,C14), CAS_EFuse!$E$4:$CH$4,0)) -> 68475-94-5 | F14: =LARGE(CAS_EFuse!$E$4:$CH$4, C14) -> 209.08512

Sheet Periodic Table VS CAS Code
B2: Mass (mg)
A3: Aluminum | B3: 61125.287
A4: Nickel | B4: 10755.44
A5: Arsenic | B5: 4239.1727
A6: Copper | B6: 2004.6639
A7: Gallium | B7: 1312.3025
A8: Silicon | B8: 1303.3293
A9: Magnesium | B9: 1249.7869
A10: Zinc | B10: 334.8158
A11: Cadmium | B11: 154.267
A12: Chlorine | B12: 151.65
A13: Iron | B13: 45.105513
A14: Lead | B14: 44.809307
... A28: Sulfur | B28: 0.0014709055

Sheet CAS_Component
A1: CAS - Component
A3: Characterization of material resources of the different components
B5: Manufacturer Part Number | C5: Dataseet (mg) | D5: Calculé (mg) | E5: Other | F5: 60676-86-0 | G5: 68475-94-5 | H5: 1# Trade Secret | I5: 1333-86-4 | J5: 7439-89-6 | K5: 7723-14-0 | L5: 7440-66-6 | M5: 7440-22-4 | N5: 1317-38-0 | O5: 7440-21-3 | P5: 7440-50-8 | Q5: 7440-57-5 | R5: 7440-02-0 | S5: 7440-05-3 | T5: 12047-27-7 | U5: 7440-31-5 | V5: 2# Trade Secret | W5: 7787-45-3 | X5: 12048-51-0 | Y5: 1313-97-9 | Z5: 12013-47-7 | AA5: 1317-36-8 | AB5: 7439-92-1 | AC5: 21645-51-2 | AD5: 7631-86-9 | AE5: 7440-55-3 | AF5: 25068-38-6 | AG5: 4# Trade Secret | AH5: 7429-90-5 | AI5: 7439-96-5 | AJ5: 29690-82-2 | AK5: 9003-35-4 | AL5: 7440-36-0 | AM5: 7440-69-9 | AN5: 7440-48-4 | AO5: 14808-60-7 | AP5: 1309-64-4 | AQ5: 68928-70-1 | AR5: 7440-44-0 | AS5: 7440-47-3 | AT5: 7704-34-9 | AU5: 5# Trade Secret | AV5: 603-35-0 | AW5: 129915-35-1 | AX5: 1344-28-1 | AY5: 1305-78-8 | AZ5: 12036-10-1 | BA5: 1303-86-2 | BB5: 1314-13-2 | BC5: 1308-38-9 | BD5: 13463-67-7 | BE5: 12056-51-8 | BF5: 65997-18-4 | BG5: 65997-17-3 | BH5: 10099-76-0 | BI5: 6# Trade Secret | BJ5: 112-34-5 | BK5: 1309-60-0 | BL5: 25035-78-3 | BM5: 1309-37-1 | BN5: 9009-54-5 | BO5: 68952-93-2 | BP5: 28262-63-7 | BQ5: 1633-22-3 | BR5: 7# Trade Secret | BS5: 8# Trade Secret | BT5: 9# Trade Secret | BU5: 10# Trade Secret | BV5: 11# Trade Secret | BW5: 7439-95-4 | BX5: 54208-63-8 | BY5: 827-43-0 | BZ5: 26100-51-6 | CA5: 7440-70-2 | CB5: 409-21-2
B6: CGA3E2X7R1H104K080AA | C6: 5.12 | D6: =SUM(E6:CV6) -> 5.12 | E6: 0.08 | P6: 0.86 | R6: =0.48+0.04 -> 0.52 | T6: 3.59 | U6: 0.07
B7: C0805C103K1RACTU | C7: 18.97 | D7: =SUM(E7:CV7) -> 18.98 | P7: 2.13 | R7: =1.48+0.14 -> 1.62 | T7: 14.44 | U7: 0.43 | V7: =0.14+0.22 -> 0.36
B8: CGA5L1X7R1H106K160AC | C8: 40.96 | D8: =SUM(E8:CV8) -> 40.96 | E8: 0.77 | P8: 3.09 | R8: =14.12+0.15 -> 14.27 | T8: 22.58 | U8: 0.25
B9: C1206C475K4RACTU | C9: 47.52 | D9: =SUM(E9:CV9) -> 47.53 | P9: 1.93 | R9: =4.47+0.2 -> 4.67 | U9: 0.63 | V9: =0.42+0.21 -> 0.63 | W9: 39.67
B10: C0805C105K3RACTU | C10: 18.97 | D10: =SUM(E10:CV10) -> 18.98 | P10: 2.13 | R10: =1.48+0.14 -> 1.62 | U10: 0.43 | V10: =0.14+0.22 -> 0.36 | W10: 14.44
B11: 1812YA250472KJTSYX | C11: 6 | D11: =SUM(E11:CV11) -> 6 | P11: 0.225 | R11: =0.44+0.128 -> 0.568 | T11: 1.29 | U11: 0.192 | X11: 0.58 | Y11: 3.14 | BG11: 0.005
B12: 08051A221J4T2A | C12: 12 | D12: =SUM(E12:CV12) -> 12 | P12: 0.17 | R12: =1.19+0.28 -> 1.47 | T12: 2.557 | U12: 0.42 | X12: 1.148 | Y12: 6.235
B13: C0603C101J5GACAUTO | C13: 4.51 | D13: =SUM(E13:CV13) -> 4.5 | P13: 0.28 | R13: =0.41+0.08 -> 0.49 | U13: 0.12 | V13: 0.55 | Z13: 3.06
B14: C0603C103K5RACAUTO | C14: 6.01 | D14: =SUM(E14:CV14) -> 6 | P14: 0.32 | R14: =0.73+0.08 -> 0.81 | U14: 0.26 | V14: =0.04+0.02 -> 0.06 | W14: 4.55
B15: S1GB-13-F | C15: 64 | D15: =SUM(E15:CV15) -> 64 | F15: =32.3*0.3 -> 9.69 | G15: =32.3*0.06 -> 1.938 | H15: =32.3*0.06 -> 1.938 | I15: =32.3*0.005 -> 0.1615 | J15: =26.6*0.0001 -> 0.00266 | K15: =26.6*0.0003 -> 0.00798 | L15: =26.6*0.0001 -> 0.00266 | M15: =2.56*0.025 -> 0.064 | O15: =1.9*0.95 -> 1.805 | P15: =26.6*0.9995 -> 26.5867 | R15: =1.9*0.01 -> 0.019 | U15: =2.56*0.05+0.64 -> 0.768 | AA15: =1.9*0.04 -> 0.076 | AB15: =2.56*0.925 -> 2.368 | AC15: =32.3*0.05 -> 1.615 | AD15: =32.3*0.525 -> 16.9575
A16: INTERPOLATION | B16: SM6T39CAHE3_A/I | C16: 93 | D16: =SUM(E16:CV16) -> 93 | F16: =$C$16*F15/$C$15 -> 14.080781 | G16: =$C$16*G15/$C$15 -> 2.8161562 | H16: =$C$16*H15/$C$15 -> 2.8161562 | I16: =$C$16*I15/$C$15 -> 0.23467969 | J16: =$C$16*J15/$C$15 -> 0.0038653125 | K16: =$C$16*K15/$C$15 -> 0.011595937 | L16: =$C$16*L15/$C$15 -> 0.0038653125 | M16: =$C$16*M15/$C$15 -> 0.093 | ... CA16: =$C$16*CA15/$C$15 -> 0
B17: APT1608SGC | C17: 1.6 | D17: =SUM(E17:CV17) -> 1.6 | K17: 0.025 | M17: 0.0225 | P17: 0.04355592 | Q17: =0.012+0.00068592 -> 0.01268592 | R17: 0.03489618 | AE17: 0.025 | AF17: =0.0075+0.6506 -> 0.6581 | AG17: 0.77826198
B18: BAS70-04-7-F | C18: 8 | D18: =SUM(E18:CV18) -> 8 | I18: =8*0.6763*0.005 -> 0.027052 | J18: =8*0.3086*0.5053 -> 1.2474846 | M18: =8*0.3086*0.0962 -> 0.23749856 | O18: =8*0.006*0.967033 -> 0.046417584 | Q18: =8*0.006*0.010989+8*0.002 -> 0.016527472 | R18: =8*0.3086*0.361 -> 0.8912368 | U18: =8*0.0071 -> 0.0568 | V18: =8*0.6763*0.1275 -> 0.689826 | AD18: =8*0.6763*0.69 -> 3.733176 | AH18: =8*0.006*0.021978 -> 0.001054944 | AI18: =8*0.3086*0.0375 -> 0.09258 | AJ18: =8*0.6763*0.1225 -> 0.662774 | AK18: =8*0.6763*0.055 -> 0.297572
B19: PESD1LIN,115 | C19: 4.19845 | D19: =SUM(E19:CV19) -> 4.1984479 | F19: =4.19845*0.4768903 -> 2.0022001 | H19: =4.19845*0.0604509 -> 0.25380008 | I19: =4.19845*0.002015 -> 0.0084598767 | J19: =4.19845*0.0066494+4.19845*0.0000031 -> 0.027930189 | K19: =4.19845*0.0003927 -> 0.0016487313 | L19: =4.19845*0.0005236 -> 0.0021983084 | M19: =4.19845*0.0058902 -> 0.02472971 | O19: =4.19845*0.0166728+4.19845*0.0166728 -> 0.13999983 | P19: =4.19845*0.2482522 -> 1.0422744 | Q19: =4.19845*0.002227 -> 0.0093499482 | U19: =4.19845*0.0309483 -> 0.12993489 | AB19: =4.19845*0.0000785+4.19845*0.0000031 -> 0.00034259352 | AJ19: =4.19845*0.1323203 -> 0.55554016 | AL19: =4.19845*0.0000031 -> 1.3015195e-05 | AM19: =4.19845*0.0000062 -> 2.603039e-05
B20: BZX84C4V3 | C20: 8.93 | D20: =SUM(E20:CV20) -> 8.9364 | J20: 1.899 | M20: 0.0648 | O20: 0.0424 | P20: 0.0024 | Q20: 0.04 | R20: 0.7929 | U20: 0.03 | AN20: 0.0049 | AO20: 5.89 | AP20: 0.05 | AQ20: 0.12
B21: BZX84J-B22.115 | C21: 3.78328 | D21: =SUM(E21:CV21) -> 3.783277 | F21: =3.78328*0.4248007 -> 1.60714 | I21: =3.78328*0.0016969 -> 0.0064198478 | J21: =3.78328*0.0101777+3.78328*0.0000021 -> 0.038513034 | K21: =3.78328*0.0005987 -> 0.0022650497 | L21: =3.78328*0.0007982 -> 0.0030198141 | M21: =3.78328*0.0083417 -> 0.031558987 | O21: =3.78328*0.013216 -> 0.049999828 | P21: =3.78328*0.3790885+3.78328*0.0008664 -> 1.4374758 | U21: =3.78328*0.0211351 -> 0.079960001 | AB21: =3.78328*0.0001197+3.78328*0.0000021 -> 0.0004608035 | AJ21: =3.78328*0.0989882 -> 0.37450008 | AK21: =3.78328*0.0401609 -> 0.15193993 | AL21: =3.78328*0.0000021 -> 7.944888e-06 | AM21: =3.78328*0.0000042 -> 1.5889776e-05
B22: OMNI-UNI-27-50 | C22: 56699 | D22: =SUM(E22:CV22) -> 58760 | AH22: 58760
B23: OSTVI030152 | C23: 5500 | D23: =SUM(E23:CV23) -> 5500 | L23: 900 | R23: 2200 | U23: 1200 | BZ23: 1200
B24: TC2030-MCP-NL | C24: 0 | D24: =SUM(E24:CV24) -> 0
B25: 8197 | C25: 1810 | D25: =SUM(E25:CV25) -> 1810 | L25: =C25*0.3 -> 543 | P25: =C25*0.7 -> 1267
B26: 505462 | D26: =SUM(E26:CV26) -> 0
