Workbook

Sheet 0. CONTENTS
A1: skip
A2: #VALUE! | B2: PELCA IGBT Designer - Open-source manufacturing Life Cycle Inventory (LCI) model for Si IGBT power semiconductor
B5: Guillemet, T.; Pichon, P.-Y.; Degrenne, N. An Open-Source Life Cycle Inventory (LCI) Model to Assess the Environmental Impacts of IGBT Power Semiconductor Manufacturing. Sustainability 2026, 18, 2663. https://doi.org/10.3390/su18052663
B6: Version: V1.0.0
B7: Authors: T. Guillemet, P.Y. Pichon, N. Degrenne
B8: Contact: pelca@fr.merce.mee.com
A9: Sheet # | B9: Content
A10: 0 | B10: Contents
A11: 1 | B11: User inputs
A12: 2 | B12: Process recap
A13: 3 | B13: Summary LCI
A14: 4 | B14: Inputs list
A15: 5 | B15: Impact categories
A16: 6 | B16: Pedigree matrix
A17: 7 | B17: Bill of Materials (BoM)
A18: 8 | B18: Bill of Energy (BoE)
A19: 9 | B19: Reference device
A20: 10 | B20: IGBT process flow
A21: 11 | B21: Raw wafer production
... A40: 30 | B40: References

Sheet 1. USER INPUTS
A1: skip
A2: #VALUE! | B2: PELCA IGBT Designer - Open-source manufacturing Life Cycle Inventory (LCI) model for Si IGBT power semiconductor - V1.0.0 | D2: Unit | E2: Value | F2: I/O type
A3: Wafer and die metrics | B3: Die size | C3: X (after dicing) | D3: mm | E3: 10 | F3: User input
C4: Y (after dicing) | D4: mm | E4: 10 | F4: User input
C5: Z (after thinning) | D5: mm | E5: =0.07 -> 0.07 | F5: User input
B6: Sawing street width | C6: X | D6: mm | E6: 0.12 | F6: User input
C7: Y | D7: mm | E7: 0.12 | F7: User input
B8: Die area | C8: Adie (before dicing) | D8: mm² | E8: =($E$3+($E$6/2))*($E$4+($E$7/2)) -> 101.2036 | F8: Model output
C9: Adie (after dicing) | D9: mm² | E9: =$E$3*$E$4 -> 100 | F9: Model output
B10: Die voltage rating | D10: V | E10: 750 | F10: Fixed
B11: Die current rating | D11: A | E11: =$E$9*2.7 -> 270 | F11: Model output
B12: Wafer diameter (Dwf) | D12: mm | E12: 200 | F12: User input
B13: Edge exclusion width | D13: mm | E13: =IF($E$12=100, '4. INPUTS LIST'!#REF!, IF('1. USER INPUTS'!$E$12=150, '4. INPUTS LIST'!$B$15, IF('1. USER INPUTS'!$E$12=200, '4. INPUTS LIST'!$B$16, IF('1. USER INPUTS'!$E$12=300, '4. INPUTS LIST'!$B$17, IF('1. USER INPUTS'!$E$12=450, '4. INPUTS LIST'!#REF!))))) -> 6 | F13: Model output
B14: Usable wafer area (Awf) | D14: cm² | E14: =PI()*((($E$12*0.1)-(2*$E$13*0.1))/2)^2 -> 277.59113 | F14: Model output
B15: Gross die (die count per wafer) | D15: [.] | E15: =INT(((PI()*(($E$12/2)-$E$13)^2)/$E$8)-((0.51*2*PI()*(($E$3+$E$6+$E$4+$E$7)/2))/$E$8)) -> 273 | F15: Model output
B16: Front-end (FE) yield model | D16: [.] | E16: Murphy, triangular | F16: User input
B17: Wafer killer defect density (D0) | D17: cm-2 | E17: 0.1 | F17: User input
B18: Front-end (FE) yield (η1) | D18: % | E18: =IF($E$16="Murphy, triangular", '4. INPUTS LIST'!$D$20, IF('1. USER INPUTS'!$E$16="Murphy, rectangular", '4. INPUTS LIST'!$D$21, IF('1. USER INPUTS'!$E$16="Seed", '4. INPUTS LIST'!$D$22, IF('1. USER INPUTS'!$E$16="Poisson", '4. INPUTS LIST'!$D$23)))) -> 0.9055917 | F18: Model output
B19: Probing yield (η2) | D19: % | E19: 0.94 | F19: User input
B20: Dicing yield (η3) | D20: % | E20: 0.985 | F20: User input
B21: Manufacturing yield η (η1 x η2 x η3) | D21: % | E21: =$E$18*$E$19*$E$20 -> 0.83848736 | F21: Model output
B22: Good die count per wafer | D22: [.] | E22: =INT($E$15*$E$21) -> 228 | F22: Model output
B23: Scaling factor (µ) | D23: cm-2 | E23: =(1/$E$21)/($E$14) -> 0.0042963327 | F23: Model output
A24: Wafer fab metrics | B24: Fab location and associated electricity mix | D24: [.] | E24: JP | F24: User input
D25: [.] | E25: =IF($E$24="GLO", '4. INPUTS LIST'!$A$3, IF('1. USER INPUTS'!$E$24="RER", '4. INPUTS LIST'!$A$4, IF('1. USER INPUTS'!$E$24="US", '4. INPUTS LIST'!$A$5, IF('1. USER INPUTS'!$E$24="CN", '4. INPUTS LIST'!$A$6, IF('1. USER INPUTS'!$E$24="AT", '4. INPUTS LIST'!$A$7, IF('1. USER INPUTS'!$E$24="JP", '4. INPUTS LIST'!$A$8, IF('1. USER INPUTS'!$E$24="FR", '4. INPUTS LIST'!$A$9, IF('1. USER INPUTS'!$E$24="DE", '4. INPUTS LIST'!$A$10, IF('1. USER INPUTS'!$E$24="SG", '4. INPUTS LIST'!$A$11, IF('1. USER INPUTS'!$E$24="CH", '4. INPUTS LIST'!$A$12)))))))))) -> Japan | F25: Model output
B26: Fab ISO class | D26: [.] | E26: 4 | F26: User input
B27: Cleanroom air change rate | D27: h-1 | E27: =IF($E$26=1,'4. INPUTS LIST'!$C$26,IF('1. USER INPUTS'!$E$26=2,'4. INPUTS LIST'!$C$27,IF('1. USER INPUTS'!$E$26=3,'4. INPUTS LIST'!$C$28,IF('1. USER INPUTS'!$E$26=4,'4. INPUTS LIST'!$C$29,IF('1. USER INPUTS'!$E$26=5,'4. INPUTS LIST'!$C$30,IF('1. USER INPUTS'!$E$26=6,'4. INPUTS LIST'!$C$31,IF('1. USER INPUTS'!$E$26=7,'4. INPUTS LIST'!$C$32,IF('1. USER INPUTS'!$E$26=8,'4. INPUTS LIST'!$C$33)))))))) -> 400 | F27: Model output
B28: Fab throughput | D28: wfs/month | E28: 100000 | F28: User input
B29: Fab area | D29: m² | E29: ='29. FAB SIZE MODEL'!$L$4 -> 36520 | F29: Model output
B30: Abatement efficiency | D30: % | E30: 0.95 | F30: User input
B31: Wastewater recycling yield | D31: % | E31: 0.5 | F31: User input

Sheet 2. PROCESS RECAP 
A1: skip
A2: Process category | B2: Included sub-process steps | C2: Equipment nominal electrical power (kW) | D2: Power Correction Factor (PCF) | E2: Equipment electrical power (kW) | F2: Batch size (nb of wafer per iteration) | G2: Processing time per batch and per iterations (s) | H2: Nb of iterations | I2: Total processing time (s) | J2: Total nb of process steps
A4: PHOTOLITHOGAPHY | B4: Spin-coating | C4: 12 | D4: 2 | E4: =C4/D4 -> 6 | F4: 1 | G4: ='14. PHOTOLITHO.'!$D$44 -> 120 | H4: 11 | I4: =$G$4*$H$4 -> 1320 | J4: =SUM($H$4:$H$6) -> 33
B5: UV-exposure | C5: 45 | D5: 2 | E5: =C5/D5 -> 22.5 | F5: 1 | G5: ='14. PHOTOLITHO.'!$D$66 -> 300 | H5: 11 | I5: =$G$5*$H$5 -> 3300
B6: Development | C6: 12 | D6: 2 | E6: =C6/D6 -> 6 | F6: 1 | G6: ='14. PHOTOLITHO.'!$D$93 -> 360 | H6: 11 | I6: =$G$6*$H$6 -> 3960
A8: WET CLEAN | B8: RCA clean | C8: 13.8 | D8: 2 | E8: =C8/D8 -> 6.9 | F8: =IF('1. USER INPUTS'!$E$12=150,50,IF('1. USER INPUTS'!$E$12=200,50,IF('1. USER INPUTS'!$E$12=300,25))) -> 50 | G8: ='13. WET CLEAN'!$D$51 -> 2460 | H8: 2 | I8: =$G$8*$H$8 -> 4920 | J8: =SUM($H$8:$H$11) -> 10
B9: Piranha clean | C9: 13.8 | D9: 2 | E9: =C9/D9 -> 6.9 | F9: =IF('1. USER INPUTS'!$E$12=150,50,IF('1. USER INPUTS'!$E$12=200,50,IF('1. USER INPUTS'!$E$12=300,25))) -> 50 | G9: ='13. WET CLEAN'!$D$142 -> 1500 | H9: 1 | I9: =$G$9*$H$9 -> 1500
B10: HF clean | C10: 13.8 | D10: 2 | E10: =C10/D10 -> 6.9 | F10: =IF('1. USER INPUTS'!$E$12=150,50,IF('1. USER INPUTS'!$E$12=200,50,IF('1. USER INPUTS'!$E$12=300,25))) -> 50 | G10: ='13. WET CLEAN'!$D$112 -> 1500 | H10: 2 | I10: =$G$10*$H$10 -> 3000
B11: Spin-rinse drying | C11: 2.5 | D11: 2 | E11: 2.5 | F11: =IF('1. USER INPUTS'!$E$12=150,50,IF('1. USER INPUTS'!$E$12=200,50,IF('1. USER INPUTS'!$E$12=300,25))) -> 50 | G11: ='13. WET CLEAN'!$D$84 -> 450 | H11: 5 | I11: =$G$11*$H$11 -> 2250
A13: WET ETCH | B13: Photoresist (PR) wet stripping | C13: 12.8 | D13: 2 | E13: =C13/D13 -> 6.4 | F13: 50 | G13: ='12. WET ETCH'!$D$155 -> 360 | H13: 7 | I13: =$G$13*$H$13 -> 2520 | J13: =SUM($H$13:$H$17) -> 11
B14: Wet lift-off - PR, metals | C14: 12.8 | D14: 2 | E14: =C14/D14 -> 6.4 | F14: 1 | G14: ='12. WET ETCH'!$D$185 -> 1800 | H14: 1 | I14: =$G$14*$H$14 -> 1800
B15: Spin-etching - Si | C15: 3.3 | D15: 2 | E15: =C15/D15 -> 1.65 | F15: 1 | G15: ='12. WET ETCH'!$D$58 -> 186 | H15: 1 | I15: =$G$15*$H$15 -> 186
B16: Dip etching - SiO2 | C16: 12.8 | D16: 2 | E16: =C16/D16 -> 6.4 | F16: 50 | G16: ='12. WET ETCH'!$D$94 -> 120 | H16: 1 | I16: =$G$16*$H$16 -> 120
B17: Dip etching - SiN | C17: 12.8 | D17: 2 | E17: =C17/D17 -> 6.4 | F17: 50 | G17: ='12. WET ETCH'!$D$126 -> 1260 | H17: 1 | I17: =$G$17*$H$17 -> 1260
A19: DRY ETCH | B19: Photoresist (PR) dry stripping | C19: 12.8 | D19: 2 | E19: =C19/D19 -> 6.4 | F19: 25 | G19: ='15. DRY ETCH'!$D$146 -> 180 | H19: 9 | I19: =$G$19*$H$19 -> 1620 | J19: =SUM($H$19:$H$23) -> 16
B20: Dry etching - Si | C20: 43.6 | D20: 2 | E20: =C20/D20 -> 21.8 | F20: 1 | G20: ='15. DRY ETCH'!$D$52 -> 159 | H20: 2 | I20: =$G$20*$H$20 -> 318
B21: Dry etching - Si (trenches) | C21: 43.6 | D21: 2 | E21: =C21/D21 -> 21.8 | F21: 1 | G21: ='15. DRY ETCH'!$D$107 -> 240 | H21: 1 | I21: =$G$21*$H$21 -> 240
B22: Dry etching - SiN | C22: 43.6 | D22: 2 | E22: =C22/D22 -> 21.8 | F22: 1 | G22: ='15. DRY ETCH'!$D$50 -> 180 | H22: 1 | I22: =$G$22*$H$22 -> 180
B23: Dry etching - SiO2 | C23: 43.6 | D23: 2 | E23: =C23/D23 -> 21.8 | F23: 1 | G23: ='15. DRY ETCH'!$D$54 -> 212.4 | H23: 3 | I23: =$G$23*$H$23 -> 637.2
A25: ION IMPLANT | B25: P implantation | C25: 25 | D25: 2 | E25: =C25/D25 -> 12.5 | F25: 1 | G25: ='17. IMPLANT'!$D$70 -> 360 | H25: 3 | I25: =$G$25*$H$25 -> 1080 | J25: =SUM($H$25:$H$27) -> 7
B26: P+ implantation | C26: 25 | D26: 2 | E26: =C26/D26 -> 12.5 | F26: 1 | G26: ='17. IMPLANT'!$D$105 -> 540 | H26: 2 | I26: =$G$26*$H$26 -> 1080
B27: N+ implantation | C27: 25 | D27: 2 | E27: =C27/D27 -> 12.5 | F27: 1 | G27: ='17. IMPLANT'!$D$35 -> 540 | H27: 2 | I27: =$G$27*$H$27 -> 1080
A29: THERMAL PROCESSES | B29: Dry thermal oxidation - Scattering oxide | C29: 15 | D29: 2 | E29: =C29/D29 -> 7.5 | F29: 100 | G29: ='16. THERMAL PROC.'!$D$30 -> 4920 | H29: 1 | I29: =$G$29*$H$29 -> 4920 | J29: =SUM($H$29:$H$36) -> 11
B30: Dry thermal oxidation - Gate oxide | C30: 15 | D30: 2 | E30: =C30/D30 -> 7.5 | F30: 100 | G30: ='16. THERMAL PROC.'!$D$57 -> 9960 | H30: 1 | I30: =$G$30*$H$30 -> 9960
B31: Wet thermal oxidation - LOCOS (field oxide) | C31: 15 | D31: 2 | E31: =C31/D31 -> 7.5 | F31: 100 | G31: ='16. THERMAL PROC.'!$D$93 -> 8520 | H31: 1 | I31: =$G$31*$H$31 -> 8520
B32: Rapid thermal annealing - Post-implant activation (PIA) | C32: 15 | D32: 2 | E32: =C32/D32 -> 7.5 | F32: 1 | G32: ='16. THERMAL PROC.'!$D$122 -> 982 | H32: 3 | I32: =$G$32*$H$32 -> 2946
B33: Rapid thermal annealing - Salicide process | C33: 15 | D33: 2 | E33: =C33/D33 -> 7.5 | F33: 1 | G33: ='16. THERMAL PROC.'!$D$123 -> 2062 | H33: 1 | I33: =$G$33*$H$33 -> 2062
B34: Furnace annealing | C34: 15 | D34: 2 | E34: =C34/D34 -> 7.5 | F34: 100 | G34: ='16. THERMAL PROC.'!$D$148 -> 4860 | H34: 1 | I34: =$G$34*$H$34 -> 4860
B35: Laser annealing | C35: 34 | D35: 2 | E35: =C35/D35 -> 17 | F35: 1 | G35: ='16. THERMAL PROC.'!$D$171 -> 1308.9969 | H35: 2 | I35: =$G$35*$H$35 -> 2617.9939
B36: Hard baking (polyimide) | C36: 3 | D36: 2 | E36: =C36/D36 -> 1.5 | F36: 100 | G36: ='16. THERMAL PROC.'!$D$189 -> 7620 | H36: 1 | I36: =$G$36*$H$36 -> 7620
A38: PVD | B38: PVD - Ti | C38: 34 | D38: 2 | E38: =C38/D38 -> 17 | F38: 1 | G38: ='19. PVD'!$D$70 -> 240 | H38: 2 | I38: =$G$38 -> 240 | J38: =SUM($H$38:$H$41) -> 6
B39: PVD - Al | C39: 34 | D39: 2 | E39: =C39/D39 -> 17 | F39: 1 | G39: ='19. PVD'!$D$36 -> 405.06329 | H39: 2 | I39: =G39 -> 405.06329
B40: PVD - Ni | C40: 34 | D40: 2 | E40: =C40/D40 -> 17 | F40: 1 | G40: ='19. PVD'!$D$102 -> 180 | H40: 1 | I40: =G40*H40 -> 180
B41: PVD - Ag | C41: 34 | D41: 2 | E41: =C41/D41 -> 17 | F41: 1 | G41: ='19. PVD'!$D$134 -> 117.64706 | H41: 1 | I41: =G41*H41 -> 117.64706
A43: CVD | B43: LP-CVD - SiN | C43: 14.6 | D43: 2 | E43: =C43/D43 -> 7.3 | F43: 100 | G43: ='18. CVD'!$D$64 -> 1500 | H43: 1 | I43: =$G$43*$H$43 -> 1500 | J43: =SUM($H$43:$H$47) -> 7
B44: LP-CVD - Doped PolySi | C44: 14.6 | D44: 2 | E44: =C44/D44 -> 7.3 | F44: 100 | G44: ='18. CVD'!$D$115 -> 2580 | H44: 1 | I44: =$G$44*$H$44 -> 2580
B45: LP-CVD - SiO2 | C45: 14.6 | D45: 2 | E45: =C45/D45 -> 7.3 | F45: 100 | G45: ='18. CVD'!$D$163 -> 1680 | H45: 1 | I45: =$G$45*$H$45 -> 1680
B46: PE-CVD - SiO2 | C46: 15 | D46: 2 | E46: =C46/D46 -> 7.5 | F46: 1 | G46: ='18. CVD'!$D$218 -> 1680 | H46: 3 | I46: =$G$46 -> 1680
B47: LP-CVD - W | C47: 14.6 | D47: 2 | E47: =C47/D47 -> 7.3 | F47: 100 | G47: ='18. CVD'!$D$275 -> 765 | H47: 1 | I47: =$G$47*$H$47 -> 765
A49: CMP | B49: Dielectric CMP - PolySi / Si / SiO2 | C49: 9 | D49: 2 | E49: =C49/D49 -> 4.5 | F49: 1 | G49: ='20. CMP'!$D$39 -> 300 | H49: 2 | I49: =$G$49*$H$49 -> 600 | J49: =SUM($H$49:$H$51) -> 6
...

Sheet 3. SUMMARY LCI
A1: Database | B1: IGBT LCI dtb
A2: cutoff | B2: 12
A3: Activity | B3: RAW WAFER PRODUCTION
A4: comment | B4: (Unknown)
A5: location | B5: RER
A6: production amount | B6: 1
A7: reference product | B7: Processed cm² of Si IGBT good die
A8: type | B8: process
A9: unit | B9: unit
A10: Exchanges
A11: name | B11: amount | C11: unit | D11: database | E11: reference product | F11: categories | G11: location | H11: type | I11: uncertainty type | J11: loc | K11: scale | L11: GSD | M11: R | N11: C | O11: T | P11: G | Q11: F | R11: SDGi1 | S11: SDGi2 | T11: SDGi3 | U11: SDGi4 | V11: SDGi5 | W11: Ufb | X11: SDGb
A12: =IF($G$12='4. INPUTS LIST'!$B$3,'4. INPUTS LIST'!$C$3, IF($G$12='4. INPUTS LIST'!$B$4,'4. INPUTS LIST'!$C$4, IF($G$12='4. INPUTS LIST'!$B$5,'4. INPUTS LIST'!$C$5, IF($G$12='4. INPUTS LIST'!$B$6,'4. INPUTS LIST'!$C$6, IF($G$12='4. INPUTS LIST'!$B$7,'4. INPUTS LIST'!$C$7, IF($G$12='4. INPUTS LIST'!$B$8,'4. INPUTS LIST'!$C$8, IF($G$12='4. INPUTS LIST'!$B$9,'4. INPUTS LIST'!$C$9, IF($G$12='4. INPUTS LIST'!$B$10,'4. INPUTS LIST'!$C$10, IF($G$12='4. INPUTS LIST'!$B$11,'4. INPUTS LIST'!$C$11, IF($G$12='4. INPUTS LIST'!$B$12,'4. INPUTS LIST'!$C$12)))))))))) -> market for electricity, medium voltage | B12: ='11. RAW WF PROD.'!$D$32 -> 0.48496366 | C12: kilowatt hour | D12: ecoinvent_3.9.1_cutoff | E12: =IF($A$12='4. INPUTS LIST'!$C$3,'4. INPUTS LIST'!$D$3, IF($A$12='4. INPUTS LIST'!$C$7, '4. INPUTS LIST'!$D$7, IF($A$12='4. INPUTS LIST'!$C$12,'4. INPUTS LIST'!$D$12))) -> electricity, medium voltage | F12: (Unknown) | G12: ='1. USER INPUTS'!$E$24 -> JP | H12: technosphere | I12: 2 | J12: =IF(B12=0,"(Unknown)",LN((ABS(B12)))) -> -0.72368133 | K12: =IF(B12>0,SQRT(LN(L12)),"(Unknown)") -> 0.47591494 | L12: =IF(B12>0,(EXP(SQRT((LN(X12))^2+(LN(R12))^2+(LN(S12))^2+(LN(T12))^2+(LN(U12))^2+(LN(V12))^2))),"(Unknown)") -> 1.2541964 | M12: 4 | N12: 4 | O12: 5 | P12: 3 | Q12: 2 | R12: =IF(M12=1, '6. PEDIGREE MATRIX'!$B$4, IF(M12=2, '6. PEDIGREE MATRIX'!$C$4, IF(M12=3, '6. PEDIGREE MATRIX'!$D$4, IF(M12=4, '6. PEDIGREE MATRIX'!$E$4, IF(M12=5, '6. PEDIGREE MATRIX'!$F$4))))) -> 1.0935647 | S12: =IF(N12=1, '6. PEDIGREE MATRIX'!$B$6, IF(N12=2, '6. PEDIGREE MATRIX'!$C$6, IF(N12=3, '6. PEDIGREE MATRIX'!$D$6, IF(N12=4, '6. PEDIGREE MATRIX'!$E$6, IF(N12=5, '6. PEDIGREE MATRIX'!$F$6))))) -> 1.0457364 | T12: =IF(O12=1, '6. PEDIGREE MATRIX'!$B$8, IF(O12=2, '6. PEDIGREE MATRIX'!$C$8, IF(O12=3, '6. PEDIGREE MATRIX'!$D$8, IF(O12=4, '6. PEDIGREE MATRIX'!$E$8, IF(O12=5, '6. PEDIGREE MATRIX'!$F$8))))) -> 1.2214028 | U12: =IF(P12=1, '6. PEDIGREE MATRIX'!$B$10, IF(P12=2, '6. PEDIGREE MATRIX'!$C$10, IF(P12=3, '6. PEDIGREE MATRIX'!$D$10, IF(P12=4, '6. PEDIGREE MATRIX'!$E$10, IF(P12=5, '6. PEDIGREE MATRIX'!$F$10))))) -> 1.0100502 | V12: =IF(Q12=1, '6. PEDIGREE MATRIX'!$B$12, IF(Q12=2, '6. PEDIGREE MATRIX'!$C$12, IF(Q12=3, '6. PEDIGREE MATRIX'!$D$12, IF(Q12=4, '6. PEDIGREE MATRIX'!$E$12, IF(Q12=5, '6. PEDIGREE MATRIX'!$F$12))))) -> 1.0247974 | W12: 0.0006 | X12: =EXP(SQRT(W12)) -> 1.0247974
A13: market for silica sand | B13: ='11. RAW WF PROD.'!$D$34 -> 0.0061332968 | C13: kilogram | D13: ecoinvent_3.9.1_cutoff | E13: silica sand | F13: (Unknown) | G13: GLO | H13: technosphere | I13: 2 | J13: =IF(B13=0,"(Unknown)",LN((ABS(B13)))) -> -5.0940229 | K13: =IF(B13>0,SQRT(LN(L13)),"(Unknown)") -> 0.47591494 | L13: =IF(B13>0,(EXP(SQRT((LN(X13))^2+(LN(R13))^2+(LN(S13))^2+(LN(T13))^2+(LN(U13))^2+(LN(V13))^2))),"(Unknown)") -> 1.2541964 | M13: 4 | N13: 4 | O13: 5 | P13: 3 | Q13: 2 | R13: =IF(M13=1, '6. PEDIGREE MATRIX'!$B$4, IF(M13=2, '6. PEDIGREE MATRIX'!$C$4, IF(M13=3, '6. PEDIGREE MATRIX'!$D$4, IF(M13=4, '6. PEDIGREE MATRIX'!$E$4, IF(M13=5, '6. PEDIGREE MATRIX'!$F$4))))) -> 1.0935647 | S13: =IF(N13=1, '6. PEDIGREE MATRIX'!$B$6, IF(N13=2, '6. PEDIGREE MATRIX'!$C$6, IF(N13=3, '6. PEDIGREE MATRIX'!$D$6, IF(N13=4, '6. PEDIGREE MATRIX'!$E$6, IF(N13=5, '6. PEDIGREE MATRIX'!$F$6))))) -> 1.0457364 | T13: =IF(O13=1, '6. PEDIGREE MATRIX'!$B$8, IF(O13=2, '6. PEDIGREE MATRIX'!$C$8, IF(O13=3, '6. PEDIGREE MATRIX'!$D$8, IF(O13=4, '6. PEDIGREE MATRIX'!$E$8, IF(O13=5, '6. PEDIGREE MATRIX'!$F$8))))) -> 1.2214028 | U13: =IF(P13=1, '6. PEDIGREE MATRIX'!$B$10, IF(P13=2, '6. PEDIGREE MATRIX'!$C$10, IF(P13=3, '6. PEDIGREE MATRIX'!$D$10, IF(P13=4, '6. PEDIGREE MATRIX'!$E$10, IF(P13=5, '6. PEDIGREE MATRIX'!$F$10))))) -> 1.0100502 | V13: =IF(Q13=1, '6. PEDIGREE MATRIX'!$B$12, IF(Q13=2, '6. PEDIGREE MATRIX'!$C$12, IF(Q13=3, '6. PEDIGREE MATRIX'!$D$12, IF(Q13=4, '6. PEDIGREE MATRIX'!$E$12, IF(Q13=5, '6. PEDIGREE MATRIX'!$F$12))))) -> 1.0247974 | W13: 0.0006 | X13: 1.0247974
A14: market for wood chips, dry, measured as dry mass | B14: ='11. RAW WF PROD.'!$D$35 -> 0.0023028364 | C14: kilogram | D14: ecoinvent_3.9.1_cutoff | E14: wood chips, dry, measured as dry mass | F14: (Unknown) | G14: RoW | H14: technosphere | I14: 2 | J14: =IF(B14=0,"(Unknown)",LN((ABS(B14)))) -> -6.0736137 | K14: =IF(B14>0,SQRT(LN(L14)),"(Unknown)") -> 0.47591494 | L14: =IF(B14>0,(EXP(SQRT((LN(X14))^2+(LN(R14))^2+(LN(S14))^2+(LN(T14))^2+(LN(U14))^2+(LN(V14))^2))),"(Unknown)") -> 1.2541964 | M14: 4 | N14: 4 | O14: 5 | P14: 3 | Q14: 2 | R14: =IF(M14=1, '6. PEDIGREE MATRIX'!$B$4, IF(M14=2, '6. PEDIGREE MATRIX'!$C$4, IF(M14=3, '6. PEDIGREE MATRIX'!$D$4, IF(M14=4, '6. PEDIGREE MATRIX'!$E$4, IF(M14=5, '6. PEDIGREE MATRIX'!$F$4))))) -> 1.0935647 | S14: =IF(N14=1, '6. PEDIGREE MATRIX'!$B$6, IF(N14=2, '6. PEDIGREE MATRIX'!$C$6, IF(N14=3, '6. PEDIGREE MATRIX'!$D$6, IF(N14=4, '6. PEDIGREE MATRIX'!$E$6, IF(N14=5, '6. PEDIGREE MATRIX'!$F$6))))) -> 1.0457364 | T14: =IF(O14=1, '6. PEDIGREE MATRIX'!$B$8, IF(O14=2, '6. PEDIGREE MATRIX'!$C$8, IF(O14=3, '6. PEDIGREE MATRIX'!$D$8, IF(O14=4, '6. PEDIGREE MATRIX'!$E$8, IF(O14=5, '6. PEDIGREE MATRIX'!$F$8))))) -> 1.2214028 | U14: =IF(P14=1, '6. PEDIGREE MATRIX'!$B$10, IF(P14=2, '6. PEDIGREE MATRIX'!$C$10, IF(P14=3, '6. PEDIGREE MATRIX'!$D$10, IF(P14=4, '6. PEDIGREE MATRIX'!$E$10, IF(P14=5, '6. PEDIGREE MATRIX'!$F$10))))) -> 1.0100502 | V14: =IF(Q14=1, '6. PEDIGREE MATRIX'!$B$12, IF(Q14=2, '6. PEDIGREE MATRIX'!$C$12, IF(Q14=3, '6. PEDIGREE MATRIX'!$D$12, IF(Q14=4, '6. PEDIGREE MATRIX'!$E$12, IF(Q14=5, '6. PEDIGREE MATRIX'!$F$12))))) -> 1.0247974 | W14: 0.0006 | X14: 1.0247974
A15: market for petroleum coke | B15: ='11. RAW WF PROD.'!$D$36 -> 0.00075241188 | C15: kilogram | D15: ecoinvent_3.9.1_cutoff | E15: petroleum coke | F15: (Unknown) | G15: GLO | H15: technosphere | I15: 2 | J15: =IF(B15=0,"(Unknown)",LN((ABS(B15)))) -> -7.1922267 | K15: =IF(B15>0,SQRT(LN(L15)),"(Unknown)") -> 0.47591494 | L15: =IF(B15>0,(EXP(SQRT((LN(X15))^2+(LN(R15))^2+(LN(S15))^2+(LN(T15))^2+(LN(U15))^2+(LN(V15))^2))),"(Unknown)") -> 1.2541964 | M15: 4 | N15: 4 | O15: 5 | P15: 3 | Q15: 2 | R15: =IF(M15=1, '6. PEDIGREE MATRIX'!$B$4, IF(M15=2, '6. PEDIGREE MATRIX'!$C$4, IF(M15=3, '6. PEDIGREE MATRIX'!$D$4, IF(M15=4, '6. PEDIGREE MATRIX'!$E$4, IF(M15=5, '6. PEDIGREE MATRIX'!$F$4))))) -> 1.0935647 | S15: =IF(N15=1, '6. PEDIGREE MATRIX'!$B$6, IF(N15=2, '6. PEDIGREE MATRIX'!$C$6, IF(N15=3, '6. PEDIGREE MATRIX'!$D$6, IF(N15=4, '6. PEDIGREE MATRIX'!$E$6, IF(N15=5, '6. PEDIGREE MATRIX'!$F$6))))) -> 1.0457364 | T15: =IF(O15=1, '6. PEDIGREE MATRIX'!$B$8, IF(O15=2, '6. PEDIGREE MATRIX'!$C$8, IF(O15=3, '6. PEDIGREE MATRIX'!$D$8, IF(O15=4, '6. PEDIGREE MATRIX'!$E$8, IF(O15=5, '6. PEDIGREE MATRIX'!$F$8))))) -> 1.2214028 | U15: =IF(P15=1, '6. PEDIGREE MATRIX'!$B$10, IF(P15=2, '6. PEDIGREE MATRIX'!$C$10, IF(P15=3, '6. PEDIGREE MATRIX'!$D$10, IF(P15=4, '6. PEDIGREE MATRIX'!$E$10, IF(P15=5, '6. PEDIGREE MATRIX'!$F$10))))) -> 1.0100502 | V15: =IF(Q15=1, '6. PEDIGREE MATRIX'!$B$12, IF(Q15=2, '6. PEDIGREE MATRIX'!$C$12, IF(Q15=3, '6. PEDIGREE MATRIX'!$D$12, IF(Q15=4, '6. PEDIGREE MATRIX'!$E$12, IF(Q15=5, '6. PEDIGREE MATRIX'!$F$12))))) -> 1.0247974 | W15: 0.0006 | X15: 1.0247974
A16: market for graphite | B16: ='11. RAW WF PROD.'!$D$37 -> 0.00020520324 | C16: kilogram | D16: ecoinvent_3.9.1_cutoff | E16: graphite | F16: (Unknown) | G16: GLO | H16: technosphere | I16: 2 | J16: =IF(B16=0,"(Unknown)",LN((ABS(B16)))) -> -8.4915097 | K16: =IF(B16>0,SQRT(LN(L16)),"(Unknown)") -> 0.47591494 | L16: =IF(B16>0,(EXP(SQRT((LN(X16))^2+(LN(R16))^2+(LN(S16))^2+(LN(T16))^2+(LN(U16))^2+(LN(V16))^2))),"(Unknown)") -> 1.2541964 | M16: 4 | N16: 4 | O16: 5 | P16: 3 | Q16: 2 | R16: =IF(M16=1, '6. PEDIGREE MATRIX'!$B$4, IF(M16=2, '6. PEDIGREE MATRIX'!$C$4, IF(M16=3, '6. PEDIGREE MATRIX'!$D$4, IF(M16=4, '6. PEDIGREE MATRIX'!$E$4, IF(M16=5, '6. PEDIGREE MATRIX'!$F$4))))) -> 1.0935647 | S16: =IF(N16=1, '6. PEDIGREE MATRIX'!$B$6, IF(N16=2, '6. PEDIGREE MATRIX'!$C$6, IF(N16=3, '6. PEDIGREE MATRIX'!$D$6, IF(N16=4, '6. PEDIGREE MATRIX'!$E$6, IF(N16=5, '6. PEDIGREE MATRIX'!$F$6))))) -> 1.0457364 | T16: =IF(O16=1, '6. PEDIGREE MATRIX'!$B$8, IF(O16=2, '6. PEDIGREE MATRIX'!$C$8, IF(O16=3, '6. PEDIGREE MATRIX'!$D$8, IF(O16=4, '6. PEDIGREE MATRIX'!$E$8, IF(O16=5, '6. PEDIGREE MATRIX'!$F$8))))) -> 1.2214028 | U16: =IF(P16=1, '6. PEDIGREE MATRIX'!$B$10, IF(P16=2, '6. PEDIGREE MATRIX'!$C$10, IF(P16=3, '6. PEDIGREE MATRIX'!$D$10, IF(P16=4, '6. PEDIGREE MATRIX'!$E$10, IF(P16=5, '6. PEDIGREE MATRIX'!$F$10))))) -> 1.0100502 | V16: =IF(Q16=1, '6. PEDIGREE MATRIX'!$B$12, IF(Q16=2, '6. PEDIGREE MATRIX'!$C$12, IF(Q16=3, '6. PEDIGREE MATRIX'!$D$12, IF(Q16=4, '6. PEDIGREE MATRIX'!$E$12, IF(Q16=5, '6. PEDIGREE MATRIX'!$F$12))))) -> 1.0247974 | W16: 0.0006 | X16: 1.0247974
A17: market for hydrochloric acid, without water, in 30% solution state | B17: ='11. RAW WF PROD.'!$D$38 -> 0.0085045342 | C17: kilogram | D17: ecoinvent_3.9.1_cutoff | E17: hydrochloric acid, without water, in 30% solution state | F17: (Unknown) | G17: RoW | H17: technosphere | I17: 2 | J17: =IF(B17=0,"(Unknown)",LN((ABS(B17)))) -> -4.7671558 | K17: =IF(B17>0,SQRT(LN(L17)),"(Unknown)") -> 0.47591494 | L17: =IF(B17>0,(EXP(SQRT((LN(X17))^2+(LN(R17))^2+(LN(S17))^2+(LN(T17))^2+(LN(U17))^2+(LN(V17))^2))),"(Unknown)") -> 1.2541964 | M17: 4 | N17: 4 | O17: 5 | P17: 3 | Q17: 2 | R17: =IF(M17=1, '6. PEDIGREE MATRIX'!$B$4, IF(M17=2, '6. PEDIGREE MATRIX'!$C$4, IF(M17=3, '6. PEDIGREE MATRIX'!$D$4, IF(M17=4, '6. PEDIGREE MATRIX'!$E$4, IF(M17=5, '6. PEDIGREE MATRIX'!$F$4))))) -> 1.0935647 | S17: =IF(N17=1, '6. PEDIGREE MATRIX'!$B$6, IF(N17=2, '6. PEDIGREE MATRIX'!$C$6, IF(N17=3, '6. PEDIGREE MATRIX'!$D$6, IF(N17=4, '6. PEDIGREE MATRIX'!$E$6, IF(N17=5, '6. PEDIGREE MATRIX'!$F$6))))) -> 1.0457364 | T17: =IF(O17=1, '6. PEDIGREE MATRIX'!$B$8, IF(O17=2, '6. PEDIGREE MATRIX'!$C$8, IF(O17=3, '6. PEDIGREE MATRIX'!$D$8, IF(O17=4, '6. PEDIGREE MATRIX'!$E$8, IF(O17=5, '6. PEDIGREE MATRIX'!$F$8))))) -> 1.2214028 | U17: =IF(P17=1, '6. PEDIGREE MATRIX'!$B$10, IF(P17=2, '6. PEDIGREE MATRIX'!$C$10, IF(P17=3, '6. PEDIGREE MATRIX'!$D$10, IF(P17=4, '6. PEDIGREE MATRIX'!$E$10, IF(P17=5, '6. PEDIGREE MATRIX'!$F$10))))) -> 1.0100502 | V17: =IF(Q17=1, '6. PEDIGREE MATRIX'!$B$12, IF(Q17=2, '6. PEDIGREE MATRIX'!$C$12, IF(Q17=3, '6. PEDIGREE MATRIX'!$D$12, IF(Q17=4, '6. PEDIGREE MATRIX'!$E$12, IF(Q17=5, '6. PEDIGREE MATRIX'!$F$12))))) -> 1.0247974 | W17: 0.0006 | X17: 1.0247974
A18: Carbon dioxide, non-fossil | B18: ='11. RAW WF PROD.'!$D$58 -> 0.010488166 | C18: kilogram | D18: biosphere3 | E18: (Unknown) | F18: ('air') | G18: (Unknown) | H18: biosphere | I18: 2 | J18: =IF(B18=0,"(Unknown)",LN((ABS(B18)))) -> -4.5575077 | K18: =IF(B18>0,SQRT(LN(L18)),"(Unknown)") -> 0.47591494 | L18: =IF(B18>0,(EXP(SQRT((LN(X18))^2+(LN(R18))^2+(LN(S18))^2+(LN(T18))^2+(LN(U18))^2+(LN(V18))^2))),"(Unknown)") -> 1.2541964 | M18: 4 | N18: 4 | O18: 5 | P18: 3 | Q18: 2 | R18: =IF(M18=1, '6. PEDIGREE MATRIX'!$B$4, IF(M18=2, '6. PEDIGREE MATRIX'!$C$4, IF(M18=3, '6. PEDIGREE MATRIX'!$D$4, IF(M18=4, '6. PEDIGREE MATRIX'!$E$4, IF(M18=5, '6. PEDIGREE MATRIX'!$F$4))))) -> 1.0935647 | S18: =IF(N18=1, '6. PEDIGREE MATRIX'!$B$6, IF(N18=2, '6. PEDIGREE MATRIX'!$C$6, IF(N18=3, '6. PEDIGREE MATRIX'!$D$6, IF(N18=4, '6. PEDIGREE MATRIX'!$E$6, IF(N18=5, '6. PEDIGREE MATRIX'!$F$6))))) -> 1.0457364 | T18: =IF(O18=1, '6. PEDIGREE MATRIX'!$B$8, IF(O18=2, '6. PEDIGREE MATRIX'!$C$8, IF(O18=3, '6. PEDIGREE MATRIX'!$D$8, IF(O18=4, '6. PEDIGREE MATRIX'!$E$8, IF(O18=5, '6. PEDIGREE MATRIX'!$F$8))))) -> 1.2214028 | U18: =IF(P18=1, '6. PEDIGREE MATRIX'!$B$10, IF(P18=2, '6. PEDIGREE MATRIX'!$C$10, IF(P18=3, '6. PEDIGREE MATRIX'!$D$10, IF(P18=4, '6. PEDIGREE MATRIX'!$E$10, IF(P18=5, '6. PEDIGREE MATRIX'!$F$10))))) -> 1.0100502 | V18: =IF(Q18=1, '6. PEDIGREE MATRIX'!$B$12, IF(Q18=2, '6. PEDIGREE MATRIX'!$C$12, IF(Q18=3, '6. PEDIGREE MATRIX'!$D$12, IF(Q18=4, '6. PEDIGREE MATRIX'!$E$12, IF(Q18=5, '6. PEDIGREE MATRIX'!$F$12))))) -> 1.0247974 | W18: 0.0006 | X18: 1.0247974
A19: Carbon monoxide, non-fossil | B19: ='11. RAW WF PROD.'!$D$59 -> 0.00020976331 | C19: kilogram | D19: biosphere3 | E19: (Unknown) | F19: ('air') | G19: (Unknown) | H19: biosphere | I19: 2 | J19: =IF(B19=0,"(Unknown)",LN((ABS(B19)))) -> -8.4695308 | K19: =IF(B19>0,SQRT(LN(L19)),"(Unknown)") -> 0.47591494 | L19: =IF(B19>0,(EXP(SQRT((LN(X19))^2+(LN(R19))^2+(LN(S19))^2+(LN(T19))^2+(LN(U19))^2+(LN(V19))^2))),"(Unknown)") -> 1.2541964 | M19: 4 | N19: 4 | O19: 5 | P19: 3 | Q19: 2 | R19: =IF(M19=1, '6. PEDIGREE MATRIX'!$B$4, IF(M19=2, '6. PEDIGREE MATRIX'!$C$4, IF(M19=3, '6. PEDIGREE MATRIX'!$D$4, IF(M19=4, '6. PEDIGREE MATRIX'!$E$4, IF(M19=5, '6. PEDIGREE MATRIX'!$F$4))))) -> 1.0935647 | S19: =IF(N19=1, '6. PEDIGREE MATRIX'!$B$6, IF(N19=2, '6. PEDIGREE MATRIX'!$C$6, IF(N19=3, '6. PEDIGREE MATRIX'!$D$6, IF(N19=4, '6. PEDIGREE MATRIX'!$E$6, IF(N19=5, '6. PEDIGREE MATRIX'!$F$6))))) -> 1.0457364 | T19: =IF(O19=1, '6. PEDIGREE MATRIX'!$B$8, IF(O19=2, '6. PEDIGREE MATRIX'!$C$8, IF(O19=3, '6. PEDIGREE MATRIX'!$D$8, IF(O19=4, '6. PEDIGREE MATRIX'!$E$8, IF(O19=5, '6. PEDIGREE MATRIX'!$F$8))))) -> 1.2214028 | U19: =IF(P19=1, '6. PEDIGREE MATRIX'!$B$10, IF(P19=2, '6. PEDIGREE MATRIX'!$C$10, IF(P19=3, '6. PEDIGREE MATRIX'!$D$10, IF(P19=4, '6. PEDIGREE MATRIX'!$E$10, IF(P19=5, '6. PEDIGREE MATRIX'!$F$10))))) -> 1.0100502 | V19: =IF(Q19=1, '6. PEDIGREE MATRIX'!$B$12, IF(Q19=2, '6. PEDIGREE MATRIX'!$C$12, IF(Q19=3, '6. PEDIGREE MATRIX'!$D$12, IF(Q19=4, '6. PEDIGREE MATRIX'!$E$12, IF(Q19=5, '6. PEDIGREE MATRIX'!$F$12))))) -> 1.0247974 | W19: 0.0006 | X19: 1.0247974
A20: Nitrogen oxides | B20: ='11. RAW WF PROD.'!$D$60 -> 1.7328274e-05 | C20: kilogram | D20: biosphere3 | E20: (Unknown) | F20: ('air') | G20: (Unknown) | H20: biosphere | I20: 2 | J20: =IF(B20=0,"(Unknown)",LN((ABS(B20)))) -> -10.963171 | K20: =IF(B20>0,SQRT(LN(L20)),"(Unknown)") -> 0.47591494 | L20: =IF(B20>0,(EXP(SQRT((LN(X20))^2+(LN(R20))^2+(LN(S20))^2+(LN(T20))^2+(LN(U20))^2+(LN(V20))^2))),"(Unknown)") -> 1.2541964 | M20: 4 | N20: 4 | O20: 5 | P20: 3 | Q20: 2 | R20: =IF(M20=1, '6. PEDIGREE MATRIX'!$B$4, IF(M20=2, '6. PEDIGREE MATRIX'!$C$4, IF(M20=3, '6. PEDIGREE MATRIX'!$D$4, IF(M20=4, '6. PEDIGREE MATRIX'!$E$4, IF(M20=5, '6. PEDIGREE MATRIX'!$F$4))))) -> 1.0935647 | S20: =IF(N20=1, '6. PEDIGREE MATRIX'!$B$6, IF(N20=2, '6. PEDIGREE MATRIX'!$C$6, IF(N20=3, '6. PEDIGREE MATRIX'!$D$6, IF(N20=4, '6. PEDIGREE MATRIX'!$E$6, IF(N20=5, '6. PEDIGREE MATRIX'!$F$6))))) -> 1.0457364 | T20: =IF(O20=1, '6. PEDIGREE MATRIX'!$B$8, IF(O20=2, '6. PEDIGREE MATRIX'!$C$8, IF(O20=3, '6. PEDIGREE MATRIX'!$D$8, IF(O20=4, '6. PEDIGREE MATRIX'!$E$8, IF(O20=5, '6. PEDIGREE MATRIX'!$F$8))))) -> 1.2214028 | U20: =IF(P20=1, '6. PEDIGREE MATRIX'!$B$10, IF(P20=2, '6. PEDIGREE MATRIX'!$C$10, IF(P20=3, '6. PEDIGREE MATRIX'!$D$10, IF(P20=4, '6. PEDIGREE MATRIX'!$E$10, IF(P20=5, '6. PEDIGREE MATRIX'!$F$10))))) -> 1.0100502 | V20: =IF(Q20=1, '6. PEDIGREE MATRIX'!$B$12, IF(Q20=2, '6. PEDIGREE MATRIX'!$C$12, IF(Q20=3, '6. PEDIGREE MATRIX'!$D$12, IF(Q20=4, '6. PEDIGREE MATRIX'!$E$12, IF(Q20=5, '6. PEDIGREE MATRIX'!$F$12))))) -> 1.0247974 | W20: 0.0006 | X20: 1.0247974
A21: Methanol | B21: ='11. RAW WF PROD.'!$D$61 -> 0.00010716169 | C21: kilogram | D21: biosphere3 | E21: (Unknown) | F21: ('air') | G21: (Unknown) | H21: biosphere | I21: 2 | J21: =IF(B21=0,"(Unknown)",LN((ABS(B21)))) -> -9.1411717 | K21: =IF(B21>0,SQRT(LN(L21)),"(Unknown)") -> 0.47591494 | L21: =IF(B21>0,(EXP(SQRT((LN(X21))^2+(LN(R21))^2+(LN(S21))^2+(LN(T21))^2+(LN(U21))^2+(LN(V21))^2))),"(Unknown)") -> 1.2541964 | M21: 4 | N21: 4 | O21: 5 | P21: 3 | Q21: 2 | R21: =IF(M21=1, '6. PEDIGREE MATRIX'!$B$4, IF(M21=2, '6. PEDIGREE MATRIX'!$C$4, IF(M21=3, '6. PEDIGREE MATRIX'!$D$4, IF(M21=4, '6. PEDIGREE MATRIX'!$E$4, IF(M21=5, '6. PEDIGREE MATRIX'!$F$4))))) -> 1.0935647 | S21: =IF(N21=1, '6. PEDIGREE MATRIX'!$B$6, IF(N21=2, '6. PEDIGREE MATRIX'!$C$6, IF(N21=3, '6. PEDIGREE MATRIX'!$D$6, IF(N21=4, '6. PEDIGREE MATRIX'!$E$6, IF(N21=5, '6. PEDIGREE MATRIX'!$F$6))))) -> 1.0457364 | T21: =IF(O21=1, '6. PEDIGREE MATRIX'!$B$8, IF(O21=2, '6. PEDIGREE MATRIX'!$C$8, IF(O21=3, '6. PEDIGREE MATRIX'!$D$8, IF(O21=4, '6. PEDIGREE MATRIX'!$E$8, IF(O21=5, '6. PEDIGREE MATRIX'!$F$8))))) -> 1.2214028 | U21: =IF(P21=1, '6. PEDIGREE MATRIX'!$B$10, IF(P21=2, '6. PEDIGREE MATRIX'!$C$10, IF(P21=3, '6. PEDIGREE MATRIX'!$D$10, IF(P21=4, '6. PEDIGREE MATRIX'!$E$10, IF(P21=5, '6. PEDIGREE MATRIX'!$F$10))))) -> 1.0100502 | V21: =IF(Q21=1, '6. PEDIGREE MATRIX'!$B$12, IF(Q21=2, '6. PEDIGREE MATRIX'!$C$12, IF(Q21=3, '6. PEDIGREE MATRIX'!$D$12, IF(Q21=4, '6. PEDIGREE MATRIX'!$E$12, IF(Q21=5, '6. PEDIGREE MATRIX'!$F$12))))) -> 1.0247974 | W21: 0.0006 | X21: 1.0247974
A22: Methane, non-fossil | B22: ='11. RAW WF PROD.'!$D$62 -> 8.6641368e-05 | C22: kilogram | D22: biosphere3 | E22: (Unknown) | F22: ('air') | G22: (Unknown) | H22: biosphere | I22: 2 | J22: =IF(B22=0,"(Unknown)",LN((ABS(B22)))) -> -9.3537332 | K22: =IF(B22>0,SQRT(LN(L22)),"(Unknown)") -> 0.47591494 | L22: =IF(B22>0,(EXP(SQRT((LN(X22))^2+(LN(R22))^2+(LN(S22))^2+(LN(T22))^2+(LN(U22))^2+(LN(V22))^2))),"(Unknown)") -> 1.2541964 | M22: 4 | N22: 4 | O22: 5 | P22: 3 | Q22: 2 | R22: =IF(M22=1, '6. PEDIGREE MATRIX'!$B$4, IF(M22=2, '6. PEDIGREE MATRIX'!$C$4, IF(M22=3, '6. PEDIGREE MATRIX'!$D$4, IF(M22=4, '6. PEDIGREE MATRIX'!$E$4, IF(M22=5, '6. PEDIGREE MATRIX'!$F$4))))) -> 1.0935647 | S22: =IF(N22=1, '6. PEDIGREE MATRIX'!$B$6, IF(N22=2, '6. PEDIGREE MATRIX'!$C$6, IF(N22=3, '6. PEDIGREE MATRIX'!$D$6, IF(N22=4, '6. PEDIGREE MATRIX'!$E$6, IF(N22=5, '6. PEDIGREE MATRIX'!$F$6))))) -> 1.0457364 | T22: =IF(O22=1, '6. PEDIGREE MATRIX'!$B$8, IF(O22=2, '6. PEDIGREE MATRIX'!$C$8, IF(O22=3, '6. PEDIGREE MATRIX'!$D$8, IF(O22=4, '6. PEDIGREE MATRIX'!$E$8, IF(O22=5, '6. PEDIGREE MATRIX'!$F$8))))) -> 1.2214028 | U22: =IF(P22=1, '6. PEDIGREE MATRIX'!$B$10, IF(P22=2, '6. PEDIGREE MATRIX'!$C$10, IF(P22=3, '6. PEDIGREE MATRIX'!$D$10, IF(P22=4, '6. PEDIGREE MATRIX'!$E$10, IF(P22=5, '6. PEDIGREE MATRIX'!$F$10))))) -> 1.0100502 | V22: =IF(Q22=1, '6. PEDIGREE MATRIX'!$B$12, IF(Q22=2, '6. PEDIGREE MATRIX'!$C$12, IF(Q22=3, '6. PEDIGREE MATRIX'!$D$12, IF(Q22=4, '6. PEDIGREE MATRIX'!$E$12, IF(Q22=5, '6. PEDIGREE MATRIX'!$F$12))))) -> 1.0247974 | W22: 0.0006 | X22: 1.0247974
A23: Ethane | B23: ='11. RAW WF PROD.'!$D$63 -> 3.6480576e-05 | C23: kilogram | D23: biosphere3 | E23: (Unknown) | F23: ('air') | G23: (Unknown) | H23: biosphere | I23: 2 | J23: =IF(B23=0,"(Unknown)",LN((ABS(B23)))) -> -10.218731 | K23: =IF(B23>0,SQRT(LN(L23)),"(Unknown)") -> 0.47591494 | L23: =IF(B23>0,(EXP(SQRT((LN(X23))^2+(LN(R23))^2+(LN(S23))^2+(LN(T23))^2+(LN(U23))^2+(LN(V23))^2))),"(Unknown)") -> 1.2541964 | M23: 4 | N23: 4 | O23: 5 | P23: 3 | Q23: 2 | R23: =IF(M23=1, '6. PEDIGREE MATRIX'!$B$4, IF(M23=2, '6. PEDIGREE MATRIX'!$C$4, IF(M23=3, '6. PEDIGREE MATRIX'!$D$4, IF(M23=4, '6. PEDIGREE MATRIX'!$E$4, IF(M23=5, '6. PEDIGREE MATRIX'!$F$4))))) -> 1.0935647 | S23: =IF(N23=1, '6. PEDIGREE MATRIX'!$B$6, IF(N23=2, '6. PEDIGREE MATRIX'!$C$6, IF(N23=3, '6. PEDIGREE MATRIX'!$D$6, IF(N23=4, '6. PEDIGREE MATRIX'!$E$6, IF(N23=5, '6. PEDIGREE MATRIX'!$F$6))))) -> 1.0457364 | T23: =IF(O23=1, '6. PEDIGREE MATRIX'!$B$8, IF(O23=2, '6. PEDIGREE MATRIX'!$C$8, IF(O23=3, '6. PEDIGREE MATRIX'!$D$8, IF(O23=4, '6. PEDIGREE MATRIX'!$E$8, IF(O23=5, '6. PEDIGREE MATRIX'!$F$8))))) -> 1.2214028 | U23: =IF(P23=1, '6. PEDIGREE MATRIX'!$B$10, IF(P23=2, '6. PEDIGREE MATRIX'!$C$10, IF(P23=3, '6. PEDIGREE MATRIX'!$D$10, IF(P23=4, '6. PEDIGREE MATRIX'!$E$10, IF(P23=5, '6. PEDIGREE MATRIX'!$F$10))))) -> 1.0100502 | V23: =IF(Q23=1, '6. PEDIGREE MATRIX'!$B$12, IF(Q23=2, '6. PEDIGREE MATRIX'!$C$12, IF(Q23=3, '6. PEDIGREE MATRIX'!$D$12, IF(Q23=4, '6. PEDIGREE MATRIX'!$E$12, IF(Q23=5, '6. PEDIGREE MATRIX'!$F$12))))) -> 1.0247974 | W23: 0.0006 | X23: 1.0247974
A24: Water | B24: ='11. RAW WF PROD.'!$D$65 -> 2.3712374e-06 | C24: cubic meter | D24: biosphere3 | E24: (Unknown) | F24: ('air') | G24: (Unknown) | H24: biosphere | I24: 2 | J24: =IF(B24=0,"(Unknown)",LN((ABS(B24)))) -> -12.952099 | K24: =IF(B24>0,SQRT(LN(L24)),"(Unknown)") -> 0.47591494 | L24: =IF(B24>0,(EXP(SQRT((LN(X24))^2+(LN(R24))^2+(LN(S24))^2+(LN(T24))^2+(LN(U24))^2+(LN(V24))^2))),"(Unknown)") -> 1.2541964 | M24: 4 | N24: 4 | O24: 5 | P24: 3 | Q24: 2 | R24: =IF(M24=1, '6. PEDIGREE MATRIX'!$B$4, IF(M24=2, '6. PEDIGREE MATRIX'!$C$4, IF(M24=3, '6. PEDIGREE MATRIX'!$D$4, IF(M24=4, '6. PEDIGREE MATRIX'!$E$4, IF(M24=5, '6. PEDIGREE MATRIX'!$F$4))))) -> 1.0935647 | S24: =IF(N24=1, '6. PEDIGREE MATRIX'!$B$6, IF(N24=2, '6. PEDIGREE MATRIX'!$C$6, IF(N24=3, '6. PEDIGREE MATRIX'!$D$6, IF(N24=4, '6. PEDIGREE MATRIX'!$E$6, IF(N24=5, '6. PEDIGREE MATRIX'!$F$6))))) -> 1.0457364 | T24: =IF(O24=1, '6. PEDIGREE MATRIX'!$B$8, IF(O24=2, '6. PEDIGREE MATRIX'!$C$8, IF(O24=3, '6. PEDIGREE MATRIX'!$D$8, IF(O24=4, '6. PEDIGREE MATRIX'!$E$8, IF(O24=5, '6. PEDIGREE MATRIX'!$F$8))))) -> 1.2214028 | U24: =IF(P24=1, '6. PEDIGREE MATRIX'!$B$10, IF(P24=2, '6. PEDIGREE MATRIX'!$C$10, IF(P24=3, '6. PEDIGREE MATRIX'!$D$10, IF(P24=4, '6. PEDIGREE MATRIX'!$E$10, IF(P24=5, '6. PEDIGREE MATRIX'!$F$10))))) -> 1.0100502 | V24: =IF(Q24=1, '6. PEDIGREE MATRIX'!$B$12, IF(Q24=2, '6. PEDIGREE MATRIX'!$C$12, IF(Q24=3, '6. PEDIGREE MATRIX'!$D$12, IF(Q24=4, '6. PEDIGREE MATRIX'!$E$12, IF(Q24=5, '6. PEDIGREE MATRIX'!$F$12))))) -> 1.0247974 | W24: 0.0006 | X24: 1.0247974
A25: Sulfur dioxide | B25: ='11. RAW WF PROD.'!$D$66 -> 4.3320684e-05 | C25: kilogram | D25: biosphere3 | E25: (Unknown) | F25: ('air') | G25: (Unknown) | H25: biosphere | I25: 2 | J25: =IF(B25=0,"(Unknown)",LN((ABS(B25)))) -> -10.04688 | K25: =IF(B25>0,SQRT(LN(L25)),"(Unknown)") -> 0.47591494 | L25: =IF(B25>0,(EXP(SQRT((LN(X25))^2+(LN(R25))^2+(LN(S25))^2+(LN(T25))^2+(LN(U25))^2+(LN(V25))^2))),"(Unknown)") -> 1.2541964 | M25: 4 | N25: 4 | O25: 5 | P25: 3 | Q25: 2 | R25: =IF(M25=1, '6. PEDIGREE MATRIX'!$B$4, IF(M25=2, '6. PEDIGREE MATRIX'!$C$4, IF(M25=3, '6. PEDIGREE MATRIX'!$D$4, IF(M25=4, '6. PEDIGREE MATRIX'!$E$4, IF(M25=5, '6. PEDIGREE MATRIX'!$F$4))))) -> 1.0935647 | S25: =IF(N25=1, '6. PEDIGREE MATRIX'!$B$6, IF(N25=2, '6. PEDIGREE MATRIX'!$C$6, IF(N25=3, '6. PEDIGREE MATRIX'!$D$6, IF(N25=4, '6. PEDIGREE MATRIX'!$E$6, IF(N25=5, '6. PEDIGREE MATRIX'!$F$6))))) -> 1.0457364 | T25: =IF(O25=1, '6. PEDIGREE MATRIX'!$B$8, IF(O25=2, '6. PEDIGREE MATRIX'!$C$8, IF(O25=3, '6. PEDIGREE MATRIX'!$D$8, IF(O25=4, '6. PEDIGREE MATRIX'!$E$8, IF(O25=5, '6. PEDIGREE MATRIX'!$F$8))))) -> 1.2214028 | U25: =IF(P25=1, '6. PEDIGREE MATRIX'!$B$10, IF(P25=2, '6. PEDIGREE MATRIX'!$C$10, IF(P25=3, '6. PEDIGREE MATRIX'!$D$10, IF(P25=4, '6. PEDIGREE MATRIX'!$E$10, IF(P25=5, '6. PEDIGREE MATRIX'!$F$10))))) -> 1.0100502 | V25: =IF(Q25=1, '6. PEDIGREE MATRIX'!$B$12, IF(Q25=2, '6. PEDIGREE MATRIX'!$C$12, IF(Q25=3, '6. PEDIGREE MATRIX'!$D$12, IF(Q25=4, '6. PEDIGREE MATRIX'!$E$12, IF(Q25=5, '6. PEDIGREE MATRIX'!$F$12))))) -> 1.0247974 | W25: 0.0006 | X25: 1.0247974
A26: Hydrogen | B26: ='11. RAW WF PROD.'!$D$67 -> 0.00015732248 | C26: kilogram | D26: biosphere3 | E26: (Unknown) | F26: ('air') | G26: (Unknown) | H26: biosphere | I26: 2 | J26: =IF(B26=0,"(Unknown)",LN((ABS(B26)))) -> -8.7572128 | K26: =IF(B26>0,SQRT(LN(L26)),"(Unknown)") -> 0.47591494 | L26: =IF(B26>0,(EXP(SQRT((LN(X26))^2+(LN(R26))^2+(LN(S26))^2+(LN(T26))^2+(LN(U26))^2+(LN(V26))^2))),"(Unknown)") -> 1.2541964 | M26: 4 | N26: 4 | O26: 5 | P26: 3 | Q26: 2 | R26: =IF(M26=1, '6. PEDIGREE MATRIX'!$B$4, IF(M26=2, '6. PEDIGREE MATRIX'!$C$4, IF(M26=3, '6. PEDIGREE MATRIX'!$D$4, IF(M26=4, '6. PEDIGREE MATRIX'!$E$4, IF(M26=5, '6. PEDIGREE MATRIX'!$F$4))))) -> 1.0935647 | S26: =IF(N26=1, '6. PEDIGREE MATRIX'!$B$6, IF(N26=2, '6. PEDIGREE MATRIX'!$C$6, IF(N26=3, '6. PEDIGREE MATRIX'!$D$6, IF(N26=4, '6. PEDIGREE MATRIX'!$E$6, IF(N26=5, '6. PEDIGREE MATRIX'!$F$6))))) -> 1.0457364 | T26: =IF(O26=1, '6. PEDIGREE MATRIX'!$B$8, IF(O26=2, '6. PEDIGREE MATRIX'!$C$8, IF(O26=3, '6. PEDIGREE MATRIX'!$D$8, IF(O26=4, '6. PEDIGREE MATRIX'!$E$8, IF(O26=5, '6. PEDIGREE MATRIX'!$F$8))))) -> 1.2214028 | U26: =IF(P26=1, '6. PEDIGREE MATRIX'!$B$10, IF(P26=2, '6. PEDIGREE MATRIX'!$C$10, IF(P26=3, '6. PEDIGREE MATRIX'!$D$10, IF(P26=4, '6. PEDIGREE MATRIX'!$E$10, IF(P26=5, '6. PEDIGREE MATRIX'!$F$10))))) -> 1.0100502 | V26: =IF(Q26=1, '6. PEDIGREE MATRIX'!$B$12, IF(Q26=2, '6. PEDIGREE MATRIX'!$C$12, IF(Q26=3, '6. PEDIGREE MATRIX'!$D$12, IF(Q26=4, '6. PEDIGREE MATRIX'!$E$12, IF(Q26=5, '6. PEDIGREE MATRIX'!$F$12))))) -> 1.0247974 | W26: 0.0006 | X26: 1.0247974
A27: Silicon dioxide | B27: ='11. RAW WF PROD.'!$D$68 -> 2.0520324e-05 | C27: kilogram | D27: biosphere3 | E27: (Unknown) | F27: ('water', 'surface water') | G27: (Unknown) | H27: biosphere | I27: 2 | J27: =IF(B27=0,"(Unknown)",LN((ABS(B27)))) -> -10.794095 | K27: =IF(B27>0,SQRT(LN(L27)),"(Unknown)") -> 0.47591494 | L27: =IF(B27>0,(EXP(SQRT((LN(X27))^2+(LN(R27))^2+(LN(S27))^2+(LN(T27))^2+(LN(U27))^2+(LN(V27))^2))),"(Unknown)") -> 1.2541964 | M27: 4 | N27: 4 | O27: 5 | P27: 3 | Q27: 2 | R27: =IF(M27=1, '6. PEDIGREE MATRIX'!$B$4, IF(M27=2, '6. PEDIGREE MATRIX'!$C$4, IF(M27=3, '6. PEDIGREE MATRIX'!$D$4, IF(M27=4, '6. PEDIGREE MATRIX'!$E$4, IF(M27=5, '6. PEDIGREE MATRIX'!$F$4))))) -> 1.0935647 | S27: =IF(N27=1, '6. PEDIGREE MATRIX'!$B$6, IF(N27=2, '6. PEDIGREE MATRIX'!$C$6, IF(N27=3, '6. PEDIGREE MATRIX'!$D$6, IF(N27=4, '6. PEDIGREE MATRIX'!$E$6, IF(N27=5, '6. PEDIGREE MATRIX'!$F$6))))) -> 1.0457364 | T27: =IF(O27=1, '6. PEDIGREE MATRIX'!$B$8, IF(O27=2, '6. PEDIGREE MATRIX'!$C$8, IF(O27=3, '6. PEDIGREE MATRIX'!$D$8, IF(O27=4, '6. PEDIGREE MATRIX'!$E$8, IF(O27=5, '6. PEDIGREE MATRIX'!$F$8))))) -> 1.2214028 | U27: =IF(P27=1, '6. PEDIGREE MATRIX'!$B$10, IF(P27=2, '6. PEDIGREE MATRIX'!$C$10, IF(P27=3, '6. PEDIGREE MATRIX'!$D$10, IF(P27=4, '6. PEDIGREE MATRIX'!$E$10, IF(P27=5, '6. PEDIGREE MATRIX'!$F$10))))) -> 1.0100502 | V27: =IF(Q27=1, '6. PEDIGREE MATRIX'!$B$12, IF(Q27=2, '6. PEDIGREE MATRIX'!$C$12, IF(Q27=3, '6. PEDIGREE MATRIX'!$D$12, IF(Q27=4, '6. PEDIGREE MATRIX'!$E$12, IF(Q27=5, '6. PEDIGREE MATRIX'!$F$12))))) -> 1.0247974 | W27: 0.0006 | X27: 1.0247974
A28: =B3 -> RAW WAFER PRODUCTION | B28: 1 | C28: unit | D28: =$B$1 -> IGBT LCI dtb | E28: =B7 -> Processed cm² of Si IGBT good die | F28: (Unknown) | G28: RER | H28: production | I28: 0 | J28: (Unknown) | K28: (Unknown) | L28: (Unknown) | M28: 0 | N28: 0 | O28: 0 | P28: 0 | Q28: 0 | R28: 0 | S28: 0 | T28: 0 | U28: 0 | V28: 0 | W28: 0 | X28: 0
A31: Activity | B31: WET CLEAN
A32: comment | B32: (Unknown)
A33: location | B33: RER
A34: production amount | B34: 1
A35: reference product | B35: Processed cm² of Si IGBT good die
A36: type | B36: process
A37: unit | B37: unit
A38: Exchanges
A39: name | B39: amount | C39: unit | D39: database | E39: reference product | F39: categories | G39: location | H39: type | I39: uncertainty type | J39: loc | K39: scale | L39: GSD | M39: R | N39: C | O39: T | P39: G | Q39: F | R39: SDGi1 | S39: SDGi2 | T39: SDGi3 | U39: SDGi4 | V39: SDGi5 | W39: Ufb | X39: SDGb
A40: =IF($G$40='4. INPUTS LIST'!$B$3,'4. INPUTS LIST'!$C$3, IF($G$40='4. INPUTS LIST'!$B$4,'4. INPUTS LIST'!$C$4, IF($G$40='4. INPUTS LIST'!$B$5,'4. INPUTS LIST'!$C$5, IF($G$40='4. INPUTS LIST'!$B$6,'4. INPUTS LIST'!$C$6, IF($G$40='4. INPUTS LIST'!$B$7,'4. INPUTS LIST'!$C$7, IF($G$40='4. INPUTS LIST'!$B$8,'4. INPUTS LIST'!$C$8, IF($G$40='4. INPUTS LIST'!$B$9,'4. INPUTS LIST'!$C$9, IF($G$40='4. INPUTS LIST'!$B$10,'4. INPUTS LIST'!$C$10, IF($G$40='4. INPUTS LIST'!$B$11,'4. INPUTS LIST'!$C$11, IF($G$40='4. INPUTS LIST'!$B$12,'4. INPUTS LIST'!$C$12)))))))))) -> market for electricity, medium voltage | B40: ='13. WET CLEAN'!$D$6 -> 0.0022475548 | C40: kilowatt hour | D40: ecoinvent_3.9.1_cutoff | E40: =IF($A$40='4. INPUTS LIST'!$C$3,'4. INPUTS LIST'!$D$3, IF($A$40='4. INPUTS LIST'!$C$7, '4. INPUTS LIST'!$D$7, IF($A$40='4. INPUTS LIST'!$C$12,'4. INPUTS LIST'!$D$12))) -> electricity, medium voltage | F40: (Unknown) | G40: ='1. USER INPUTS'!$E$24 -> JP | H40: technosphere | I40: 2 | J40: =IF(B40=0,"(Unknown)",LN((ABS(B40)))) -> -6.0979124 | K40: =IF(B40>0,SQRT(LN(L40)),"(Unknown)") -> 0.32603904 | L40: =IF(B40>0,(EXP(SQRT((LN(X40))^2+(LN(R40))^2+(LN(S40))^2+(LN(T40))^2+(LN(U40))^2+(LN(V40))^2))),"(Unknown)") -> 1.1121571 | M40: 4 | N40: 4 | O40: 1 | P40: 3 | Q40: 2 | R40: =IF(M40=1, '6. PEDIGREE MATRIX'!$B$4, IF(M40=2, '6. PEDIGREE MATRIX'!$C$4, IF(M40=3, '6. PEDIGREE MATRIX'!$D$4, IF(M40=4, '6. PEDIGREE MATRIX'!$E$4, IF(M40=5, '6. PEDIGREE MATRIX'!$F$4))))) -> 1.0935647 | S40: =IF(N40=1, '6. PEDIGREE MATRIX'!$B$6, IF(N40=2, '6. PEDIGREE MATRIX'!$C$6, IF(N40=3, '6. PEDIGREE MATRIX'!$D$6, IF(N40=4, '6. PEDIGREE MATRIX'!$E$6, IF(N40=5, '6. PEDIGREE MATRIX'!$F$6))))) -> 1.0457364 | T40: =IF(O40=1, '6. PEDIGREE MATRIX'!$B$8, IF(O40=2, '6. PEDIGREE MATRIX'!$C$8, IF(O40=3, '6. PEDIGREE MATRIX'!$D$8, IF(O40=4, '6. PEDIGREE MATRIX'!$E$8, IF(O40=5, '6. PEDIGREE MATRIX'!$F$8))))) -> 1 | U40: =IF(P40=1, '6. PEDIGREE MATRIX'!$B$10, IF(P40=2, '6. PEDIGREE MATRIX'!$C$10, IF(P40=3, '6. PEDIGREE MATRIX'!$D$10, IF(P40=4, '6. PEDIGREE MATRIX'!$E$10, IF(P40=5, '6. PEDIGREE MATRIX'!$F$10))))) -> 1.0100502 | V40: =IF(Q40=1, '6. PEDIGREE MATRIX'!$B$12, IF(Q40=2, '6. PEDIGREE MATRIX'!$C$12, IF(Q40=3, '6. PEDIGREE MATRIX'!$D$12, IF(Q40=4, '6. PEDIGREE MATRIX'!$E$12, IF(Q40=5, '6. PEDIGREE MATRIX'!$F$12))))) -> 1.0247974 | W40: 0.0006 | X40: =EXP(SQRT(W40)) -> 1.0247974
A41: market for hydrogen fluoride | B41: ='13. WET CLEAN'!$D$7 -> 0.0003293855 | C41: kilogram | D41: ecoinvent_3.9.1_cutoff | E41: hydrogen fluoride | F41: (Unknown) | G41: RoW | H41: technosphere | I41: 2 | J41: =IF(B41=0,"(Unknown)",LN((ABS(B41)))) -> -8.0182817 | K41: =IF(B41>0,SQRT(LN(L41)),"(Unknown)") -> 0.32603904 | L41: =IF(B41>0,(EXP(SQRT((LN(X41))^2+(LN(R41))^2+(LN(S41))^2+(LN(T41))^2+(LN(U41))^2+(LN(V41))^2))),"(Unknown)") -> 1.1121571 | M41: 4 | N41: 4 | O41: 1 | P41: 3 | Q41: 2 | R41: =IF(M41=1, '6. PEDIGREE MATRIX'!$B$4, IF(M41=2, '6. PEDIGREE MATRIX'!$C$4, IF(M41=3, '6. PEDIGREE MATRIX'!$D$4, IF(M41=4, '6. PEDIGREE MATRIX'!$E$4, IF(M41=5, '6. PEDIGREE MATRIX'!$F$4))))) -> 1.0935647 | S41: =IF(N41=1, '6. PEDIGREE MATRIX'!$B$6, IF(N41=2, '6. PEDIGREE MATRIX'!$C$6, IF(N41=3, '6. PEDIGREE MATRIX'!$D$6, IF(N41=4, '6. PEDIGREE MATRIX'!$E$6, IF(N41=5, '6. PEDIGREE MATRIX'!$F$6))))) -> 1.0457364 | T41: =IF(O41=1, '6. PEDIGREE MATRIX'!$B$8, IF(O41=2, '6. PEDIGREE MATRIX'!$C$8, IF(O41=3, '6. PEDIGREE MATRIX'!$D$8, IF(O41=4, '6. PEDIGREE MATRIX'!$E$8, IF(O41=5, '6. PEDIGREE MATRIX'!$F$8))))) -> 1 | U41: =IF(P41=1, '6. PEDIGREE MATRIX'!$B$10, IF(P41=2, '6. PEDIGREE MATRIX'!$C$10, IF(P41=3, '6. PEDIGREE MATRIX'!$D$10, IF(P41=4, '6. PEDIGREE MATRIX'!$E$10, IF(P41=5, '6. PEDIGREE MATRIX'!$F$10))))) -> 1.0100502 | V41: =IF(Q41=1, '6. PEDIGREE MATRIX'!$B$12, IF(Q41=2, '6. PEDIGREE MATRIX'!$C$12, IF(Q41=3, '6. PEDIGREE MATRIX'!$D$12, IF(Q41=4, '6. PEDIGREE MATRIX'!$E$12, IF(Q41=5, '6. PEDIGREE MATRIX'!$F$12))))) -> 1.0247974 | W41: 0.0006 | X41: =EXP(SQRT(W41)) -> 1.0247974
A42: market for ammonia, anhydrous, liquid | B42: ='13. WET CLEAN'!$D$8 -> 0.00037234883 | C42: kilogram | D42: ecoinvent_3.9.1_cutoff | E42: ammonia, anhydrous, liquid | F42: (Unknown) | G42: RoW | H42: technosphere | I42: 2 | J42: =IF(B42=0,"(Unknown)",LN((ABS(B42)))) -> -7.8956794 | K42: =IF(B42>0,SQRT(LN(L42)),"(Unknown)") -> 0.32603904 | L42: =IF(B42>0,(EXP(SQRT((LN(X42))^2+(LN(R42))^2+(LN(S42))^2+(LN(T42))^2+(LN(U42))^2+(LN(V42))^2))),"(Unknown)") -> 1.1121571 | M42: 4 | N42: 4 | O42: 1 | P42: 3 | Q42: 2 | R42: =IF(M42=1, '6. PEDIGREE MATRIX'!$B$4, IF(M42=2, '6. PEDIGREE MATRIX'!$C$4, IF(M42=3, '6. PEDIGREE MATRIX'!$D$4, IF(M42=4, '6. PEDIGREE MATRIX'!$E$4, IF(M42=5, '6. PEDIGREE MATRIX'!$F$4))))) -> 1.0935647 | S42: =IF(N42=1, '6. PEDIGREE MATRIX'!$B$6, IF(N42=2, '6. PEDIGREE MATRIX'!$C$6, IF(N42=3, '6. PEDIGREE MATRIX'!$D$6, IF(N42=4, '6. PEDIGREE MATRIX'!$E$6, IF(N42=5, '6. PEDIGREE MATRIX'!$F$6))))) -> 1.0457364 | T42: =IF(O42=1, '6. PEDIGREE MATRIX'!$B$8, IF(O42=2, '6. PEDIGREE MATRIX'!$C$8, IF(O42=3, '6. PEDIGREE MATRIX'!$D$8, IF(O42=4, '6. PEDIGREE MATRIX'!$E$8, IF(O42=5, '6. PEDIGREE MATRIX'!$F$8))))) -> 1 | U42: =IF(P42=1, '6. PEDIGREE MATRIX'!$B$10, IF(P42=2, '6. PEDIGREE MATRIX'!$C$10, IF(P42=3, '6. PEDIGREE MATRIX'!$D$10, IF(P42=4, '6. PEDIGREE MATRIX'!$E$10, IF(P42=5, '6. PEDIGREE MATRIX'!$F$10))))) -> 1.0100502 | V42: =IF(Q42=1, '6. PEDIGREE MATRIX'!$B$12, IF(Q42=2, '6. PEDIGREE MATRIX'!$C$12, IF(Q42=3, '6. PEDIGREE MATRIX'!$D$12, IF(Q42=4, '6. PEDIGREE MATRIX'!$E$12, IF(Q42=5, '6. PEDIGREE MATRIX'!$F$12))))) -> 1.0247974 | W42: 0.0006 | X42: =EXP(SQRT(W42)) -> 1.0247974
...

Sheet 4. INPUTS LIST
A1: skip
A2: Fab location | B2: Location acronym | C2: Activity - Electricity mix | D2: Reference product | E2: Description
A3: Global | B3: GLO | C3: market group for electricity, medium voltage | D3: electricity, medium voltage | E3: Global electricity mix, worldwide
A4: Europe | B4: RER | C4: market group for electricity, medium voltage | D4: electricity, medium voltage | E4: European electricity mix
A5: US | B5: US | C5: market group for electricity, medium voltage | D5: electricity, medium voltage | E5: US electricity mix
A6: China | B6: CN | C6: market group for electricity, medium voltage | D6: electricity, medium voltage | E6: China electricity mix of different provinces
A7: Austria | B7: AT | C7: market for electricity, medium voltage | D7: electricity, medium voltage | E7: Austrian electricity mix
A8: Japan | B8: JP | C8: market for electricity, medium voltage | D8: electricity, medium voltage | E8: Japan electricity mix
A9: France | B9: FR | C9: market for electricity, medium voltage | D9: electricity, medium voltage | E9: French electricity mix
A10: Germany | B10: DE | C10: market for electricity, medium voltage | D10: electricity, medium voltage | E10: German electricity mix
A11: Singapore | B11: SG | C11: market for electricity, medium voltage | D11: electricity, medium voltage | E11: Singapore electricity mix
A12: Switzerland | B12: CH | C12: market for electricity, medium voltage, renewable energy products | D12: electricity, medium voltage, renewable energy products | E12: Swiss renewable electricity mix
A14: Wafer diameter (Dwf, mm) | B14: Edge exclusion width (mm)
A15: 150 | B15: 6
A16: 200 | B16: 6
A17: 300 | B17: 3
A19: Yield model | B19: Die area (cm²) | C19: Defect density (cm-2) | D19: Front-end manufacturing yield (YFE, %)
A20: Murphy, triangular | B20: ='1. USER INPUTS'!$E$9*0.01 -> 1 | C20: ='1. USER INPUTS'!$E$17 -> 0.1 | D20: =((1-EXP(-$B$20*$C$20))/($B$20*$C$20))^2 -> 0.9055917
A21: Murphy, rectangular | D21: =(1-EXP(-2*$B$20*$C$20))/(2*$B$20*$C$20) -> 0.90634623
A22: Seed | D22: =(1/(1+($B$20*$C$20))) -> 0.90909091
A23: Poisson | D23: =EXP(-$B$20*$C$20) -> 0.90483742
A25: Wafer fab ISO class (ISO 14644-1) | B25: Cleanroom Class | C25: Air change rate (h-1)
A26: 1 | B26: - | C26: 700
A27: 2 | B27: - | C27: 600
A28: 3 | B28: 1 | C28: 500
A29: 4 | B29: 10 | C29: 400
A30: 5 | B30: 100 | C30: 240
A31: 6 | B31: 1000 | C31: 150
A32: 7 | B32: 10 000 | C32: 30
A33: 8 | B33: 100 000 | C33: 5

Sheet 5. IMPACTS CATEGORIES
A1: skip | F1: Informations
A2: Acronym | B2: Method name | C2: Impact category | D2: Specific context | E2: Unit | F2: The methods selected for LCA.
A3: GWP | B3: EF v3.1 no LT | C3: climate change no LT | D3: global warming potential (GWP100) no LT | E3: kg CO2 eq
A4: OD | B4: EF v3.1 no LT | C4: ozone depletion no LT | D4: ozone depletion potential (ODP) no LT | E4: kg CFC-11 eq
A5: HT | B5: EF v3.1 no LT | C5: human toxicity: carcinogenic no LT | D5: comparative toxic unit for human (CTUh) no LT | E5: CTUh
A6: HTNC | B6: EF v3.1 no LT | C6: human toxicity: non-carcinogenic no LT | D6: comparative toxic unit for human (CTUh) no LT | E6: CTUh
A7: PMF | B7: EF v3.1 no LT | C7: particulate matter formation no LT | D7: impact on human health no LT | E7: disease incidence
A8: IR | B8: EF v3.1 no LT | C8: ionising radiation: human health no LT | D8: human exposure efficiency relative to u235 no LT | E8: kBq U-235 eq
A9: POF | B9: EF v3.1 no LT | C9: photochemical ozone formation: human health no LT | D9: tropospheric ozone concentration increase no LT | E9: kg NMVOC eq
A10: TAP | B10: EF v3.1 no LT | C10: acidification no LT | D10: accumulated exceedance (AE) no LT | E10: mol H+ eq
A11: TE | B11: EF v3.1 no LT | C11: eutrophication: terrestrial no LT | D11: accumulated exceedance (AE) no LT | E11: mol N eq
A12: FE | B12: EF v3.1 no LT | C12: eutrophication: freshwater no LT | D12: fraction of nutrients reaching freshwater end compartment (P) no LT | E12: kg P eq
A13: ME | B13: EF v3.1 no LT | C13: eutrophication: marine no LT | D13: fraction of nutrients reaching marine end compartment (N) no LT | E13: kg N eq
A14: FET | B14: EF v3.1 no LT | C14: ecotoxicity: freshwater no LT | D14: comparative toxic unit for ecosystems (CTUe) no LT | E14: CTUe
... A18: LU | B18: EF v3.1 no LT | C18: land use no LT | D18: soil quality index no LT | E18: Dimensionless
A20: Direction | B20: Dispatching / receiving system | C20: Flow description
A21: Inflow | B21: Technosphere | C21: Energy input
A22: Inflow | B22: Technosphere | C22: Product material input
A23: Inflow | B23: Technosphere | C23: Process input
A24: Outflow | B24: Technosphere | C24: Waste (solid, liquid, gaseous)
A25: Outflow | B25: Biosphere | C25: Emission to air, soil, water
A26: Outflow | B26: Within system boundary | C26: Internal flow

Sheet 6. PEDIGREE MATRIX
A1: skip
A2: Rating | B2: 1 | C2: 2 | D2: 3 | E2: 4 | F2: 5
A3: Reliability (R) | B3: Verified data based on measurements | C3: Verified data partly based on assumptions | D3: Non-verified data partly based on qualified measurements | E3: Qualified estimate | F3: Non-qualified estimate
A4: Indiv. Standard deviation factor (SDGi) | B4: 1 | C4: 1.0247974 | D4: 1.0457364 | E4: 1.0935647 | F4: 1.2214028
A5: Completeness (C) | B5: Representative relevant data from all sites, over an adequate period | C5: Representative relevant data from >50% sites, over an adequate period | D5: Representative relevant data from <50% sites, OR >50%, but over shorter period | E5: Representative relevant data from 1 sites, OR some sites, but over shorter period | F5: Representativeness unknown
A6: Indiv. Standard deviation factor (SDGi) | B6: 1 | C6: 1.0100502 | D6: 1.0247974 | E6: 1.0457364 | F6: 1.0935647
A7: Temporal correlation (T) | B7: Data < 3 years old | C7: Data < 6 years old | D7: Data < 10 years old | E7: Data < 15 years old | F7: Data > 15 years old
A8: Indiv. Standard deviation factor (SDGi) | B8: 1 | C8: 1.0142426 | D8: 1.0457364 | E8: 1.0935647 | F8: 1.2214028
A9: Geographical correlation (G) | B9: Data from area under study | C9: Average data from larger area in which area under study is included | D9: Data from area with similar production conditions | E9: Data from area with slightly similar production conditions | F9: Data from unknown OR distinctly different area
A10: Indiv. Standard deviation factor (SDGi) | B10: 1 | C10: 1.0050125 | D10: 1.0100502 | E10: 1.0247974 | F10: 1.0457364
A11: Further technological correlation (F) | B11: Data from enterprises, processes and materials under study | C11: Data from processes and materials under study, different enterprise | D11: Data from processes and materials under study, from different technology | E11: Data on related processes and materials | F11: Data on related processes on lab scale OR from different technology
A12: Indiv. Standard deviation factor (SDGi) | B12: 1 | C12: 1.0247974 | D12: 1.0935647 | E12: 1.2214028 | F12: 1.4139825
B14: Reliability (R) | C14: Completeness (C) | D14: Temporal correlation (T) | E14: Geographical correlation (G) | F14: Further tech. Correlation (F)
A15: Matrix pedigree | B15: 4 | C15: 4 | D15: 1 | E15: 3 | F15: 2
A16: Indiv. std deviation factors (SDGi) | B16: =IF(B15=1, $B$4, IF(B15=2, $C$4, IF(B15=3, $D$4, IF(B15=4, $E$4, IF(B15=5, $F$4))))) -> 1.0935647 | C16: =IF(C15=1, $B$6, IF(C15=2, $C$6, IF(C15=3, $D$6, IF(C15=4, $E$6, IF(C15=5, $F$6))))) -> 1.0457364 | D16: =IF(D15=1, $B$8, IF(D15=2, $C$8, IF(D15=3, $D$8, IF(D15=4, $E$8, IF(D15=5, $F$8))))) -> 1 | E16: =IF(E15=1, $B$10, IF(E15=2, $C$10, IF(E15=3, $D$10, IF(E15=4, $E$10, IF(E15=5, $F$10))))) -> 1.0100502 | F16: =IF(F15=1, $B$12, IF(F15=2, $C$12, IF(F15=3, $D$12, IF(F15=4, $E$12, IF(F15=5, $F$12))))) -> 1.0247974
A17: Ufb | B17: 0.0006
A18: Basic error / uncertainty factors (SDGb) | B18: =EXP(SQRT(B17)) -> 1.0247974
A19: Geometric standard deviation (SDGtot / GSD) | B19: =EXP(SQRT((LN(B16))^2+(LN(C16))^2+(LN(D16))^2+(LN(E16))^2+(LN(F16))^2+(LN(B18))^2)) -> 1.1121571
A20: Scale | B20: =SQRT(LN(B19)) -> 0.32603904

Sheet 7. BoM
A1: skip
A2: WAFER PROCESS STEPS - BILL OF MATERIALS (BoM)
A4: TOTAL BoM - WAFER PROCESS STEPS
A5: UPW input | B5: kg/cm² - Per cm² of good die | C5: water production, ultrapure | D5: =SUM('3. SUMMARY LCI'!$B$46,'3. SUMMARY LCI'!$B$70,'3. SUMMARY LCI'!$B$91,'3. SUMMARY LCI'!$B$243,'3. SUMMARY LCI'!$B$267,'3. SUMMARY LCI'!$B$286) -> 5.8296893
B6: kg - Per wafer | C6: water production, ultrapure | D6: =$D$5/'1. USER INPUTS'!$E$23 -> 1356.899
A7: Other chemical / material input | B7: kg/cm² - Per cm² of good die | C7: - | D7: =SUM('3. SUMMARY LCI'!$B$41:$B$45,'3. SUMMARY LCI'!$B$47,'3. SUMMARY LCI'!$B$66:$B$69,'3. SUMMARY LCI'!$B$71,'3. SUMMARY LCI'!$B$92:$B$99,'3. SUMMARY LCI'!$B$118:$B$122,'3. SUMMARY LCI'!$B$143:$B$145,'3. SUMMARY LCI'!$B$163:$B$165,'3. SUMMARY LCI'!$B$185:$B$192,'3. SUMMARY LCI'!$B$219:$B$223,'3. SUMMARY LCI'!$B$241:$B$242,'3. SUMMARY LCI'!$B$244:$B$245,'3. SUMMARY LCI'!$B$268:$B$269,'3. SUMMARY LCI'!$B$287) -> 0.1850812
B8: kg - Per wafer | C8: - | D8: =$D$7/'1. USER INPUTS'!$E$23 -> 43.078881
A9: Total chemical / material input | B9: kg/cm² - Per cm² of good die | C9: - | D9: =SUM(D5,D7) -> 6.0147705
B10: kg - Per wafer | C10: - | D10: =SUM(D6,D8) -> 1399.9778
A12: DETAILED BoM - WAFER PROCESS STEPS - PER CM² OF GOOD DIE
A13: NH3 | B13: kg/cm² - Per cm² of good die | C13: market for ammonia, anhydrous, liquid | D13: =SUM('3. SUMMARY LCI'!$B$42,'3. SUMMARY LCI'!$B$92,'3. SUMMARY LCI'!$B$186,'3. SUMMARY LCI'!$B$244) -> 0.0021434508
A14: H2O2 | B14: kg/cm² - Per cm² of good die | C14: market for hydrogen peroxide, without water, in 50% solution state | D14: =SUM('3. SUMMARY LCI'!$B$43,'3. SUMMARY LCI'!$B$97,'3. SUMMARY LCI'!$B$242) -> 0.0081173513
A15: HCl | B15: kg/cm² - Per cm² of good die | C15: market for hydrochloric acid, without water, in 30% solution state | D15: =SUM('3. SUMMARY LCI'!$B$44) -> 0.0004869177
A16: N2 | B16: kg/cm² - Per cm² of good die | C16: air separation, cryogenic | D16: =SUM('3. SUMMARY LCI'!$B$45,'3. SUMMARY LCI'!$B$71,'3. SUMMARY LCI'!$B$99,'3. SUMMARY LCI'!$B$121,'3. SUMMARY LCI'!$B$144,'3. SUMMARY LCI'!$B$165,'3. SUMMARY LCI'!$B$189,'3. SUMMARY LCI'!$B$245) -> 0.075060671
A17: C3H8O | B17: kg/cm² - Per cm² of good die | C17: market for isopropanol | D17: ='3. SUMMARY LCI'!B47 -> 0.0044971146
A18: HMDS | B18: kg/cm² - Per cm² of good die | C18: market for hexamethyldisilazane | D18: =SUM('3. SUMMARY LCI'!$B$66) -> 2.4863696e-05
A19: PGMEA | B19: kg/cm² - Per cm² of good die | C19: market for dipropylene glycol monomethyl ether | D19: =SUM('3. SUMMARY LCI'!$B$67) -> 0.0019305862
A20: PHENOLIC RESIN | B20: kg/cm² - Per cm² of good die | C20: market for phenolic resin | D20: =SUM('3. SUMMARY LCI'!$B$68) -> 5.2234656e-05
A21: C3H9N | B21: kg/cm² - Per cm² of good die | C21: market for trimethylamine | D21: =SUM('3. SUMMARY LCI'!$B$69) -> 0.00011412442
A22: O2 | B22: kg/cm² - Per cm² of good die | C22: market for oxygen, liquid | D22: =SUM('3. SUMMARY LCI'!$B$120,'3. SUMMARY LCI'!$B$143,'3. SUMMARY LCI'!$B$188) -> 0.035158214
A23: HF | B23: kg/cm² - Per cm² of good die | C23: market for hydrogen fluoride | D23: =SUM('3. SUMMARY LCI'!$B$41,'3. SUMMARY LCI'!$B$93) -> 0.001847716
A24: HNO3 | B24: kg/cm² - Per cm² of good die | C24: market for nitric acid, without water, in 50% solution state | D24: ='3. SUMMARY LCI'!$B$94 -> 0.010248967
A25: DMSO | B25: kg/cm² - Per cm² of good die | C25: market for dimethyl sulfoxide | D25: ='3. SUMMARY LCI'!$B$98 -> 0.0031792862
A26: CH3COOH | B26: kg/cm² - Per cm² of good die | C26: market for acetic acid, without water, in 98% solution state | D26: ='3. SUMMARY LCI'!$B$95 -> 0.0030429753
A27: H2SO4 | B27: kg/cm² - Per cm² of good die | C27: market for sulfuric acid | D27: ='3. SUMMARY LCI'!$B$96 -> 0.013759005
A28: CHF3 | B28: kg/cm² - Per cm² of good die | C28: market for trifluoromethane | D28: =SUM('3. SUMMARY LCI'!B118,'3. SUMMARY LCI'!B191) -> 0.0041896205
A29: SF6 | B29: kg/cm² - Per cm² of good die | C29: market for sulfur hexafluoride, liquid | D29: =SUM('3. SUMMARY LCI'!$B$119) -> 0.004837778
A30: H2 | B30: kg/cm² - Per cm² of good die | C30: market for hydrogen, gaseous | D30: =SUM('3. SUMMARY LCI'!$B$145) -> 0.013576611
A31: Ar | B31: kg/cm² - Per cm² of good die | C31: market for argon, liquid | D31: =SUM('3. SUMMARY LCI'!B190,'3. SUMMARY LCI'!B223) -> 6.5091148e-05
A32: PH3 | B32: kg/cm² - Per cm² of good die | C32: market for phosphane | D32: =SUM('3. SUMMARY LCI'!$B$187,'3. SUMMARY LCI'!$B$163) -> 0.00036166528
A33: BF3 | B33: kg/cm² - Per cm² of good die | C33: market for boron trifluoride | D33: =SUM('3. SUMMARY LCI'!$B$164) -> 0.0012450772
A34: SiH4 | B34: kg/cm² - Per cm² of good die | C34: market for silicon tetrahydride | D34: =SUM('3. SUMMARY LCI'!$B$185) -> 8.0217113e-06
A35: Al | B35: kg/cm² - Per cm² of good die | C35: market for aluminium, primary, ingot | D35: =SUM('3. SUMMARY LCI'!$B$219) -> 2.5509948e-05
A36: W | B36: kg/cm² - Per cm² of good die | C36: market for tungsten concentrate | D36: ='3. SUMMARY LCI'!$B$192 -> 3.0148201e-08
A37: Ti | B37: kg/cm² - Per cm² of good die | C37: market for titanium | D37: ='3. SUMMARY LCI'!$B$220 -> 3.6442783e-06
A38: Ni | B38: kg/cm² - Per cm² of good die | C38: market for nickel, class 1 | D38: ='3. SUMMARY LCI'!$B$221 -> 1.2012621e-05
A39: Ag | B39: kg/cm² - Per cm² of good die | C39: market for silver | D39: ='3. SUMMARY LCI'!B222 -> 5.6704971e-06
A40: SiO2 | B40: kg/cm² - Per cm² of good die | C40: market for activated silica | D40: ='3. SUMMARY LCI'!$B$241 -> 0.00043129165
A41: POLYESTER FILM | B41: kg/cm² - Per cm² of good die | C41: market for polyester resin, unsaturated | D41: ='3. SUMMARY LCI'!$B$268 -> 3.752257e-05
A42: BS GLASS | B42: kg/cm² - Per cm² of good die | C42: market for glass tube, borosilicate | D42: ='3. SUMMARY LCI'!$B$269 -> 0.00029964066
...

Sheet 8. BoE
A1: skip
A2: IGBT WAFER & DIE - BILL OF ENERGY (BoE)
A4: ELECTRICITY CONSUMPTION BREAKDOWN - RAW WAFER PRODUCTION / WAFER PROCESS STEPS / CLEANROOM
