Workbook

Sheet comment
B1: Excel sheet for the inverter stage reliability assessment (IGBT power modules)
B3: Short summary of sheets in this document:
B4: page parameters: | C4: value of most parameters used in the calculation tool (for calculation of losses, etc)
B5: page options: | C5: to enable/disable some graphs for instance
B6: page mission_profile: | C6: description of mission profile(s)
B7: page results: | C7: result of processing (parameters for PELCA: reliability + replacement cost)
B8: page thermal_data: | C8: for debug / result of thermal simulations (thermal cycles, avg temperatures)
D9: Tj_D | F9: diode avg junction temperature | J9: calculated using IEC formula
C10: (for lifetime calculation only) | D10: Tj_Q | F10: IGBT avg junction temperature
D11: deltaT_D | F11: thermal cycle of diode at output frequency
D12: deltaT_Q | F12: thermal cycle of IGBT at output frequency
D13: Tj_D_pwm | F13: avg igbt junction temperature for that temperature cycle | J13: calculated using "pwm" simulation
D14: Tj_Q_pwm | F14: diode avg junction temperature
D15: deltaT_D_pwm | F15: diode temperature cycle at output frequency
D16: deltaT_Q_pwm | F16: igbt temperature cycle at output frequency
D17: N_fout_cy | F17: number of output cycles (at fout frequency)
D18: Tc | F18: avg case temperature
C19: (for lifetime calculation | D19: delta_Tc_cycling | F19: thermal cycle of case temperature
C20: + FIDES formulas) | D20: delta_Tj_D_cycling | F20: thermal cycle of diode junction temp due to MP cycling
D21: delta_Tj_Q_cycling | F21: thermal cycle of IGBT junction temp due to MP cycling
D22: Tc_max_cycling | F22: max temperature of case reached during cycling
D23: deltaTj_D_phase | F23: diode junction temperature cycle during one cycle of MP
D24: Tj_D_phase | F24: avg diode junction temperature for that temperature cycle
D25: deltaTj_Q_phase | F25: IGBT junction temperature cycle during one cycle of MP
D26: Tj_Q_phase | F26: avg igbt junction temperature for that temperature cycle
C27: calculated power losses | D27: PL_on_T_HB | F27: On-losses IGBT
D28: PL_on_D_HB | F28: On-losses diode
D29: PL_sw_T_HB | F29: switching losses IGBT
D30: PL_sw_D_HB | F30: recovery losses diode
D31: total_loss | F31: total inverter losses
D32: deltaTx_heatsink | F32: estimated increase of air flow temperature through heatsink
C33: Operating point | D33: active_Pout | F33: active power generated
D34: Iout | F34: output phase current (RMS)
D35: PF | F35: power factor
D36: Vout_rms | F36: output voltage
D37: life_ratio | F37: number of hour per year / 8760h
B40: Important note: only use numbers in cells…. Or save with ctrl+alt F9 before each execution of tool!

Sheet parameters
B2: General parameters
B3: S_rated | C3: 250000 | D3: Rated apparent power
B4: PN | C4: 200000 | D4: Nominal active power
B5: Vin | C5: 230
B6: Vout_rms | C6: 170 | D6: # for Mi ~ 0.7
B7: PF | C7: 0.87 | D7: # phy=30°
B8: Ir_out | C8: 363 | D8: rated CDM output current, RMS value (normal duty)
B9: Udc | C9: 540 | D9: CDM DC link voltage
B10: fsw | C10: 2000 | D10: power > 90kW
B11: Imotor_cable | C11: 10 | D11: Motor cable current, relevant for increased switching losses
B12: fout_nom | C12: 50 | D12: electric motor frequency (at m=1; control V/F = cste)
B14: Topology
B15: nb_parallel_sw | C15: 2
B17: IGBT parameters | D17: Device (losses) parameters: diodes+IGBTs of CM600
B18: T_k11 | C18: 4.8388402e-05 | D18: IGBT Ic-Vcesat datasheet fitting parameter | F18: IGBT (Transistor) conduction "power" model | K18: adapted from page Use_loss_FR-A840_inve_standrds of Usage_model(004)
B19: T_k12 | C19: 0.016748504 | D19: IGBT datasheet fitting parameter
B20: T_k21 | C20: 0.00016755466 | D20: IGBT datasheet fitting parameter
B21: T_k22 | C21: 0.608755 | D21: IGBT datasheet fitting parameter
B22: T_k31 | C22: -0.0016458066 | D22: IGBT datasheet fitting parameter
B23: T_k32 | C23: 0.64851244 | D23: IGBT datasheet fitting parameter
B24: D_k11 | C24: 4.8104e-05 | D24: Diode Ie-Vec datasheet fitting parameter | F24: Diode conduction "power" model
B25: D_k12 | C25: 0.01601896 | D25: Diode Ie-Vec datasheet fitting parameter
B26: D_k21 | C26: -0.00013203253 | D26: Diode Ie-Vec datasheet fitting parameter
B27: D_k22 | C27: 0.62561455 | D27: Diode Ie-Vec datasheet fitting parameter
B28: D_k31 | C28: -0.0015902334 | D28: Diode Ie-Vec datasheet fitting parameter
B29: D_k32 | C29: 0.72175553 | D29: Diode Ie-Vec datasheet fitting parameter
B30: EON_0 | C30: 7.7435813 | D30: EON switching energy parameter | E30: in mJ | F30: IGBT
B31: ICON_1 | C31: 0.037237605 | D31: EON switching energy parameter
B32: ICON_2 | C32: 6.6070111e-05 | D32: EON switching energy parameter
B33: TCON | C33: 0.00060045681 | D33: EON switching energy parameter
B34: VCON | C34: 1.3 | D34: EON switching energy parameter
B35: RgCON | C35: 0.55287278 | D35: EON switching energy parameter
B36: EOFF_0 | C36: 10.516277 | D36: EOFF switching energy parameter | E36: in mJ
B37: ICOFF_1 | C37: 0.075427972 | D37: EOFF switching energy parameter
B38: ICOFF_2 | C38: 2.1046999e-05 | D38: EOFF switching energy parameter
B39: TCOFF | C39: 0.0072458208 | D39: EOFF switching energy parameter
B40: VCOFF | C40: 1.3 | D40: EOFF switching energy parameter
B41: RgOFF | C41: 0.035670497 | D41: EOFF switching energy parameter
B42: ERR_0 | C42: 19.034646 | D42: ERR switching energy parameter | F42: Diode
B43: ICRR_1 | C43: 0.071199622 | D43: ERR switching energy parameter
...

Sheet options
A2: Options
A4: optional plots enable/disable (0 / 1)
A5: plot_CDF_en | B5: 1
A6: plot_bathtub_en | B6: 0
A7: plot_lifetime_mission_profile_en | B7: 0
A8: plot_mission_profile_en | B8: 0
A9: plot_cond_currents_en | B9: 0 | C9: (debug only - for "PWM" method to determine losses)
A10: display_sim_IEC | B10: 0 | C10: (debug only - result of electro-thermal simulation to determine thermal cycles - losses calculated using "IEC" method)
A11: display_sim_pwm | B11: 0 | C11: (debug only - result of electro-thermal simulation to determine thermal cycles - losses calculated using "PWM" method)

Sheet mission_profile
A1: mission profile | B1: Operating_Phase | C1: Rel_speed | D1: Rel_torque | E1: Tx | F1: delta_T_cycling | G1: T_max_cycling | H1: Operating_Hours_per_Year | I1: N_cy | J1: theta_cy | K1: RH_ambient | L1: G_RMS | M1: Pi_application | N1: Pi_type | O1: phase_nb | P1: phases
A2: 1 | B2: true | C2: 0.9 | D2: 1 | E2: 31 | F2: 5 | G2: 31 | H2: 1000 | I2: 1460 | J2: 0.68493151 | K2: 30 | L2: 0.3 | M2: 1 | N2: 0.92 | O2: 0 | P2: 0#1
B3: true | C3: 0.9 | D3: 0.5 | E3: 26 | F3: 5 | G3: 26 | H3: 3500 | I3: 1460 | J3: 2.3972603 | K3: 30 | L3: 0.3 | M3: 1 | N3: 0.92 | O3: 1 | P3: 1#2
B4: true | C4: 0.5 | D4: 0.25 | E4: 21 | F4: 6 | G4: 21 | H4: 500 | I4: 365 | J4: 1.369863 | K4: 30 | L4: 0.3 | M4: 1 | N4: 0.92 | O4: 2 | P4: 2#3
B5: false | C5: 0 | D5: 0 | E5: 15 | F5: 10 | G5: 20 | H5: 3760 | I5: 365 | J5: 10.30137 | K5: 30 | L5: 0.3 | M5: 1 | N5: 0.92 | O5: 3 | P5: 3#3
A7: 2 | B7: true | C7: 1 | D7: 1 | E7: 36 | F7: 10 | G7: 36 | H7: 1000 | I7: 730 | J7: 1.369863 | K7: 30 | L7: 0.3 | M7: 1 | N7: 0.92 | O7: 0 | P7: 0#1
B8: true | C8: 0.5 | D8: 0.25 | E8: 26 | F8: 11 | G8: 26 | H8: 3500 | I8: 730 | J8: 4.7945205 | K8: 30 | L8: 0.3 | M8: 1 | N8: 0.92 | O8: 1 | P8: 1#2
B9: false | C9: 0 | D9: 0 | E9: 15 | F9: 10 | G9: 20 | H9: 4260 | I9: 365 | J9: 11.671233 | K9: 30 | L9: 0.3 | M9: 1 | N9: 0.92 | O9: 2 | P9: 2#2

Sheet Replacement
A8: total mounting time | B8: =parameters!C79 -> 65 | C8: min
A9: total dismounting time | B9: =parameters!C80 -> 52 | C9: min
A10: total time | B10: =B9+B8 -> 117 | C10: min
A12: pwer module price | B12: =parameters!C81 -> 311.461
A13: number of modules | B13: =parameters!C15*3 -> 6
A14: total price of modules | B14: =B12*B13 -> 1868.766
A16: Hourly cost | B16: =parameters!C78 -> 100
A17: assembly cost | B17: =(B8/60)*$B$16 -> 108.33333
A18: disassembly cost | B18: =(B9/60)*$B$16 -> 86.666667
A20: Replacement cost of inverter | B20: =B14+B17+B18 -> 2063.766 | D20: (labor + modules)
A21: (complete RU)
A23: to paste into PELCA 'Cost - Price' sheet:
B24: RU raw cost/price (€) | C24: RU assembly cost/price (€) | D24: RU disassembly cost/price (€) | E24: Electricity cost (€/kWh)
A25: Inverter | B25: =B14 -> 1868.766 | C25: =B17 -> 108.33333 | D25: =B18 -> 86.666667 | E25: 0

Sheet thermal_data
A1: mission_id | B1: mission profile | C1: Operating_Phase | D1: Rel_speed | E1: Rel_torque | F1: Tx | G1: delta_T_cycling | H1: T_max_cycling | I1: Operating_Hours_per_Year | J1: N_cy | K1: theta_cy | L1: RH_ambient | M1: G_RMS | N1: Pi_application | O1: Pi_type | P1: phase_nb | Q1: phases | R1: Tj_D_iec | S1: Tj_Q_iec | T1: deltaT_D_iec | U1: deltaT_Q_iec | V1: Tj_D_pwm | W1: Tj_Q_pwm | X1: deltaT_D_pwm | Y1: deltaT_Q_pwm | Z1: N_fout_cy | AA1: Tc | AB1: delta_Tc_cycling | AC1: delta_Tj_D_cycling | AD1: delta_Tj_Q_cycling | AE1: Tc_max_cycling | AF1: deltaTj_D_phase | AG1: Tj_D_phase | AH1: deltaTj_Q_phase | AI1: Tj_Q_phase | AJ1: PL_on_T_HB | AK1: PL_on_D_HB | AL1: PL_sw_T_HB | AM1: PL_sw_D_HB | AN1: total_loss | AO1: deltaTx_heatsink | AP1: active_Pout | AQ1: Iout | AR1: PF | AS1: Vout_rms | AT1: life_ratio
A2: 0 | B2: 1 | C2: TRUE | D2: 0.9 | E2: 1 | F2: 31 | G2: 5 | H2: 31 | I2: 1000 | J2: 1460 | K2: 0.68493151 | L2: 30 | M2: 0.3 | N2: 1 | O2: 0.92 | P2: 0 | Q2: 0#1 | R2: 92.187508 | S2: 95.383535 | T2: 1.0195621 | U2: 2.5009207 | V2: 103.6942 | W2: 106.5515 | X2: 1.4606833 | Y2: 2.785042 | Z2: 162000000 | AA2: 89.987807 | AB2: 29.136699 | AC2: 29.482545 | AD2: 31.69457 | AE2: 89.987807 | AF2: 29.482545 | AG2: 77.446236 | AH2: 31.69457 | AI2: 79.536249 | AJ2: 59.795138 | AK2: 8.3747534 | AL2: 52.697873 | AM2: 20.589806 | AN2: 1697.4908 | AO2: 8.2522647 | AP2: 196118.01 | AQ2: 363 | AR2: 0.87 | AS2: 207 | AT2: 0.11415525
A3: 0 | C3: TRUE | D3: 0.9 | E3: 0.5 | F3: 26 | G3: 5 | H3: 26 | I3: 3500 | J3: 1460 | K3: 2.3972603 | L3: 30 | M3: 0.3 | N3: 1 | O3: 0.92 | P3: 1 | Q3: 1#2 | R3: 62.704964 | S3: 63.688964 | T3: 0.85926273 | U3: 1.3153471 | V3: 69.058511 | W3: 69.895139 | X3: 1.0923083 | Y3: 1.4800853 | Z3: 567000000 | AA3: 60.851107 | AB3: 11.948952 | AC3: 11.766708 | AD3: 12.861435 | AE3: 60.851107 | AF3: 11.766708 | AG3: 56.82161 | AH3: 12.861435 | AI3: 57.258247 | AJ3: 26.187375 | AK3: 5.5283396 | AL3: 32.977778 | AM3: 18.882304 | AN3: 1002.9096 | AO3: 4.8755934 | AP3: 98464.766 | AQ3: 203.28 | AR3: 0.78 | AS3: 207 | AT3: 0.39954338
A4: 0 | C4: TRUE | D4: 0.5 | E4: 0.25 | F4: 21 | G4: 6 | H4: 21 | I4: 500 | J4: 365 | K4: 1.369863 | L4: 30 | M4: 0.3 | N4: 1 | O4: 0.92 | P4: 2 | Q4: 2#3 | R4: 50.938256 | S4: 50.827529 | T4: 1.3963817 | U4: 1.3204437 | V4: 54.911047 | W4: 55.003333 | X4: 1.4962007 | Y4: 1.5594915 | Z4: 45000000 | AA4: 48.902156 | AB4: 33.902156 | AC4: 35.938256 | AD4: 35.827529 | AE4: 48.902156 | AF4: 35.938256 | AG4: 32.969128 | AH4: 35.827529 | AI4: 32.913764 | AJ4: 13.173837 | AK4: 8.3408377 | AL4: 26.943445 | AM4: 18.453524 | AN4: 802.93973 | AO4: 3.9034503 | AP4: 27839.74 | AQ4: 141.57 | AR4: 0.57 | AS4: 115 | AT4: 0.057077626
A5: 0 | C5: FALSE | D5: 0 | E5: 0 | F5: 15 | G5: 10 | H5: 20 | I5: 3760 | J5: 365 | K5: 10.30137 | L5: 30 | M5: 0.3 | N5: 1 | O5: 0.92 | P5: 3 | Q5: 3#3 | R5: 15 | S5: 15 | T5: 10 | U5: 10 | V5: 15 | W5: 15 | X5: 10 | Y5: 10 | Z5: 0 | AA5: 15 | AB5: 10 | AC5: 10 | AD5: 10 | AE5: 20 | AF5: 10 | AG5: 15 | AH5: 10 | AI5: 15 | AJ5: 0 | AK5: 0 | AL5: 0 | AM5: 0 | AN5: 0 | AO5: 0 | AP5: 0 | AQ5: 0 | AR5: 1 | AS5: 0 | AT5: 0.42922374
A6: 1 | B6: 2 | C6: TRUE | D6: 1 | E6: 1 | F6: 36 | G6: 10 | H6: 36 | I6: 1000 | J6: 730 | K6: 1.369863 | L6: 30 | M6: 0.3 | N6: 1 | O6: 0.92 | P6: 0 | Q6: 0#1 | R6: 97.116509 | S6: 100.69407 | T6: 0.8517278 | U6: 2.3908381 | V6: 109.05522 | W6: 111.94041 | X6: 1.3607659 | Y6: 2.6020106 | Z6: 180000000 | AA6: 95.136725 | AB6: 41.2054 | AC6: 41.149435 | AD6: 44.833787 | AE6: 95.136725 | AF6: 41.149435 | AG6: 76.541791 | AH6: 44.833787 | AI6: 78.277173 | AJ6: 62.45499 | AK6: 5.2729502 | AL6: 53.31231 | AM6: 20.774439 | AN6: 1701.7763 | AO6: 8.2730981 | AP6: 217908.9 | AQ6: 363 | AR6: 0.87 | AS6: 230 | AT6: 0.11415525
A7: 1 | C7: TRUE | D7: 0.5 | E7: 0.25 | F7: 26 | G7: 11 | H7: 26 | I7: 3500 | J7: 730 | K7: 4.7945205 | L7: 30 | M7: 0.3 | N7: 1 | O7: 0.92 | P7: 1 | Q7: 1#2 | R7: 55.967073 | S7: 55.860279 | T7: 1.3961399 | U7: 1.3228989 | V7: 59.981185 | W7: 60.078502 | X7: 1.4973948 | Y7: 1.564136 | Z7: 3.15e+08 | AA7: 53.931326 | AB7: 38.931326 | AC7: 40.967073 | AD7: 40.860279 | AE7: 53.931326 | AF7: 40.967073 | AG7: 35.483537 | AH7: 40.860279 | AI7: 35.430139 | AJ7: 13.031901 | AK7: 8.258494 | AL7: 27.159974 | AM7: 18.531227 | AN7: 803.77916 | AO7: 3.9075312 | AP7: 27839.74 | AQ7: 141.57 | AR7: 0.57 | AS7: 115 | AT7: 0.39954338
A8: 1 | C8: FALSE | D8: 0 | E8: 0 | F8: 15 | G8: 10 | H8: 20 | I8: 4260 | J8: 365 | K8: 11.671233 | L8: 30 | M8: 0.3 | N8: 1 | O8: 0.92 | P8: 2 | Q8: 2#2 | R8: 15 | S8: 15 | T8: 10 | U8: 10 | V8: 15 | W8: 15 | X8: 10 | Y8: 10 | Z8: 0 | AA8: 15 | AB8: 10 | AC8: 10 | AD8: 10 | AE8: 20 | AF8: 10 | AG8: 15 | AH8: 10 | AI8: 15 | AJ8: 0 | AK8: 0 | AL8: 0 | AM8: 0 | AN8: 0 | AO8: 0 | AP8: 0 | AQ8: 0 | AR8: 1 | AS8: 0 | AT8: 0.48630137

Sheet comparison_pwm_iec
B1: (Inverter) | D1: Parameters for PELCA (inverter modules) | F1: to copy into 'Faults & Prev. Maint.' sheet of PELCA input Excel file
A2: mission profile | B2: shortest lifetime (year) IGBT or diode | D2: Early failure (sigma, year) | E2: Early failure (beta) | F2: Random failure (sigma, year) | G2: Random failure (beta) | H2: Wear-out failure (sigma, year) | I2: Wear-out failure (beta) | L2: with IEC
A3: profile 1 | B3: 676.4103 | D3: 172.82836 | E3: 0.6 | F3: 32.262881 | G3: 1 | H3: 416.85495 | I3: 3
A4: profile 2 | B4: 63.901397 | D4: 172.82836 | E4: 0.6 | F4: 4.6411179 | G4: 1 | H4: 39.380852 | I4: 3
A5: profile 3 | B5: 67.775827 | D5: 172.82836 | E5: 0.6 | F5: 2.5284222 | G5: 1 | H5: 41.768567 | I5: 3
A6: profile 4 | B6: 13.387374 | D6: 172.82836 | E6: 0.6 | F6: 1.7615197 | G6: 1 | H6: 8.2503075 | I6: 3
A7: profile 5 | B7: 78.056822 | D7: 172.82836 | E7: 0.6 | F7: 3.0396721 | G7: 1 | H7: 48.10449 | I7: 3
A9: to copy into 'Cost - Price' sheet of PELCA input Excel file
A10: RU raw cost/price (€) | B10: RU assembly cost/price (€) | C10: RU disassembly cost/price (€)
A11: 1868.766 | B11: 108.33333 | C11: 86.666667
A14: mission_id | B14: mission profile | C14: life_ratio | D14: Operating_Phase | E14: load_factor | F14: Rel_speed | G14: Rel_torque | H14: Tx | I14: delta_T_cycling | J14: T_max_cycling | K14: Operating_Hours_per_Year | L14: N_cy | M14: theta_cy | N14: RH_ambient | O14: G_RMS | P14: Pi_application | Q14: Pi_type | R14: Tj_D_iec | S14: Tj_Q_iec | T14: deltaT_D_iec | U14: deltaT_Q_iec | V14: Tj_D_pwm | W14: Tj_Q_pwm | X14: deltaT_D_pwm | Y14: deltaT_Q_pwm | Z14: N_fout_cy | AA14: Tc | AB14: delta_Tc_cycling | AC14: delta_Tj_D_cycling | AD14: delta_Tj_Q_cycling | AE14: Tc_max_cycling | AF14: deltaTj_D_phase | AG14: Tj_D_phase | AH14: deltaTj_Q_phase | AI14: Tj_Q_phase | AJ14: PL_on_T_HB | AK14: PL_on_D_HB | AL14: PL_sw_T_HB | AM14: PL_sw_D_HB | AN14: total_loss
A15: 0 | B15: 1 | C15: 0.11 | D15: TRUE | E15: 1 | F15: 1 | G15: 1 | H15: 38 | I15: 8 | J15: 38 | K15: 1000 | L15: 1460 | M15: 0.68493151 | N15: 30 | O15: 0.3 | P15: 1 | Q15: 0.92 | R15: 98.647514 | S15: 102.17572 | T15: 0.85058478 | U15: 2.3684644 | V15: 115.0223 | W15: 117.85547 | X15: 1.4860588 | Y15: 2.7049257 | Z15: 180000000 | AA15: 96.670387 | AB15: 38.8435 | AC15: 38.791343 | AD15: 42.427819 | AE15: 96.670387 | AF15: 38.791343 | AG15: 79.251843 | AH15: 42.427819 | AI15: 80.961812 | AJ15: 61.565955 | AK15: 5.2015545 | AL15: 53.117984 | AM15: 20.81088 | AN15: 1688.3565
A16: 0 | C16: 0.4 | D16: TRUE | E16: 0.25 | F16: 0.5 | G16: 0.25 | H16: 30 | I16: 8 | J16: 30 | K16: 3500 | L16: 1460 | M16: 2.3972603 | N16: 30 | O16: 0.3 | P16: 1 | Q16: 0.92 | R16: 59.856171 | S16: 59.747903 | T16: 1.3917068 | U16: 1.3174553 | V16: 66.963516 | W16: 67.081604 | X16: 1.6240108 | Y16: 1.7049964 | Z16: 315000000 | AA16: 57.826887 | AB16: 7.9288467 | AC16: 7.7135167 | AD16: 8.0546402 | AE16: 57.826887 | AF16: 7.7135167 | AG16: 55.999413 | AH16: 8.0546402 | AI16: 55.720583 | AJ16: 12.797846 | AK16: 8.1177439 | AL16: 27.228643 | AM16: 18.586912 | AN16: 800.77374
A17: 0 | C17: 0.06 | D17: TRUE | E17: 0.025 | F17: 0.05 | G17: 0.25 | H17: 22 | I17: 7 | J17: 22 | K17: 500 | L17: 365 | M17: 1.369863 | N17: 30 | O17: 0.3 | P17: 1 | Q17: 0.92 | R17: 52.142654 | S17: 51.693263 | T17: 4.1162146 | U17: 3.292112 | V17: 58.820244 | W17: 58.933773 | X17: 4.3325911 | Y17: 4.5407837 | Z17: 4500000 | AA17: 49.898041 | AB17: 34.898041 | AC17: 37.142654 | AD17: 36.693263 | AE17: 49.898041 | AF17: 37.142654 | AG17: 33.571327 | AH17: 36.693263 | AI17: 33.346631 | AJ17: 10.496975 | AK17: 11.051139 | AL17: 26.885005 | AM17: 18.468657 | AN17: 802.82131
A18: 0 | C18: 0.43 | D18: FALSE | E18: 0 | F18: 0 | G18: 0 | H18: 15 | I18: 10 | J18: 20 | K18: 3760 | L18: 365 | M18: 10.30137 | N18: 30 | O18: 0.3 | P18: 1 | Q18: 0.92 | R18: 15 | S18: 15 | T18: 10 | U18: 10 | V18: 15 | W18: 15 | X18: 10 | Y18: 10 | Z18: 0 | AA18: 15 | AB18: 10 | AC18: 10 | AD18: 10 | AE18: 20 | AF18: 10 | AG18: 15 | AH18: 10 | AI18: 15 | AJ18: 0 | AK18: 0 | AL18: 0 | AM18: 0 | AN18: 0
A19: 1 | B19: 2 | C19: 0.8 | D19: TRUE | E19: 0.75 | F19: 1 | G19: 0.75 | H19: 60 | I19: 15 | J19: 60 | K19: 7008 | L19: 1460 | M19: 4.8 | N19: 30 | O19: 0.3 | P19: 1 | Q19: 0.92 | R19: 107.34952 | S19: 109.53698 | T19: 0.8037658 | U19: 1.7448354 | V19: 121.33184 | W19: 123.17571 | X19: 1.2848409 | Y19: 2.078098 | Z19: 1261440000 | AA19: 105.48123 | AB19: 75.481225 | AC19: 77.349524 | AD19: 79.536977 | AE19: 105.48123 | AF19: 77.349524 | AG19: 68.674762 | AH19: 79.536977 | AI19: 69.768488 | AJ19: 40.435882 | AK19: 4.1070132 | AL19: 44.05118 | AM19: 20.473611 | AN19: 1308.8122
A20: 1 | C20: 0.2 | D20: FALSE | E20: 0.01 | F20: 0 | G20: 0 | H20: 30 | I20: 25 | J20: 30 | K20: 1752 | L20: 365 | M20: 4.8 | N20: 30 | O20: 0.3 | P20: 1 | Q20: 0.92 | R20: 30 | S20: 30 | T20: 25 | U20: 25 | V20: 30 | W20: 30 | X20: 25 | Y20: 25 | Z20: 0 | AA20: 30 | AB20: 25 | AC20: 25 | AD20: 25 | AE20: 30 | AF20: 25 | AG20: 30 | AH20: 25 | AI20: 30 | AJ20: 0 | AK20: 0 | AL20: 0 | AM20: 0 | AN20: 0
A21: 2 | B21: 3 | C21: 0.8 | D21: TRUE | E21: 0.75 | F21: 1 | G21: 0.75 | H21: 65 | I21: 15 | J21: 65 | K21: 7008 | L21: 1460 | M21: 4.8 | N21: 30 | O21: 0.3 | P21: 1 | Q21: 0.92 | R21: 112.47809 | S21: 114.66559 | T21: 0.80739806 | U21: 1.7484903 | V21: 126.56902 | W21: 128.42118 | X21: 1.289525 | Y21: 2.086347 | Z21: 1261440000 | AA21: 110.60134 | AB21: 65.601343 | AC21: 67.478085 | AD21: 69.66559 | AE21: 110.60134 | AF21: 67.478085 | AG21: 78.739043 | AH21: 69.66559 | AI21: 79.832795 | AJ21: 40.167658 | AK21: 4.0680821 | AL21: 44.496376 | AM21: 20.623623 | AN21: 1312.2689
A22: 2 | C22: 0.2 | D22: FALSE | E22: 0.01 | F22: 0 | G22: 0 | H22: 45 | I22: 25 | J22: 45 | K22: 1752 | L22: 365 | M22: 4.8 | N22: 30 | O22: 0.3 | P22: 1 | Q22: 0.92 | R22: 45 | S22: 45 | T22: 25 | U22: 25 | V22: 45 | W22: 45 | X22: 25 | Y22: 25 | Z22: 0 | AA22: 45 | AB22: 25 | AC22: 25 | AD22: 25 | AE22: 45 | AF22: 25 | AG22: 45 | AH22: 25 | AI22: 45 | AJ22: 0 | AK22: 0 | AL22: 0 | AM22: 0 | AN22: 0
A23: 3 | B23: 4 | C23: 0.8 | D23: TRUE | E23: 0.75 | F23: 1 | G23: 0.75 | H23: 80 | I23: 15 | J23: 80 | K23: 7008 | L23: 1095 | M23: 6.4 | N23: 30 | O23: 0.3 | P23: 1 | Q23: 0.92 | R23: 127.8672 | S23: 130.05529 | T23: 0.81828782 | U23: 1.7596302 | V23: 142.28058 | W23: 144.15759 | X23: 1.3035773 | Y23: 2.1110941 | Z23: 1261440000 | AA23: 125.96515 | AB23: 100.96515 | AC23: 102.8672 | AD23: 105.05529 | AE23: 125.96515 | AF23: 102.8672 | AG23: 76.433602 | AH23: 105.05529 | AI23: 77.527645 | AJ23: 39.371142 | AK23: 3.9509729 | AL23: 45.832299 | AM23: 21.073761 | AN23: 1322.7381
A24: 3 | C24: 0.2 | D24: FALSE | E24: 0.01 | F24: 0 | G24: 0 | H24: 25 | I24: 10 | J24: 30 | K24: 1752 | L24: 1095 | M24: 1.6 | N24: 30 | O24: 0.3 | P24: 1 | Q24: 0.92 | R24: 25 | S24: 25 | T24: 10 | U24: 10 | V24: 25 | W24: 25 | X24: 10 | Y24: 10 | Z24: 0 | AA24: 25 | AB24: 10 | AC24: 10 | AD24: 10 | AE24: 30 | AF24: 10 | AG24: 25 | AH24: 10 | AI24: 25 | AJ24: 0 | AK24: 0 | AL24: 0 | AM24: 0 | AN24: 0
A25: 4 | B25: 5 | C25: 0.8 | D25: TRUE | E25: 0.75 | F25: 1 | G25: 0.75 | H25: 70 | I25: 15 | J25: 70 | K25: 7008 | L25: 365 | M25: 19.2 | N25: 30 | O25: 0.3 | P25: 1 | Q25: 0.92 | R25: 117.60722 | S25: 119.79484 | T25: 0.81102915 | U25: 1.7521742 | V25: 131.80621 | W25: 133.66665 | X25: 1.2942091 | Y25: 2.0945961 | Z25: 1261440000 | AA25: 115.72203 | AB25: 95.722034 | AC25: 97.607216 | AD25: 99.794844 | AE25: 115.72203 | AF25: 97.607216 | AG25: 68.803608 | AH25: 99.794844 | AI25: 69.897422 | AJ25: 39.900787 | AK25: 4.0290981 | AL25: 44.941628 | AM25: 20.773652 | AN25: 1315.742
A26: 4 | C26: 0.2 | D26: FALSE | E26: 0.01 | F26: 0 | G26: 0 | H26: 20 | I26: 10 | J26: 25 | K26: 1752 | L26: 365 | M26: 4.8 | N26: 30 | O26: 0.3 | P26: 1 | Q26: 0.92 | R26: 20 | S26: 20 | T26: 10 | U26: 10 | V26: 20 | W26: 20 | X26: 10 | Y26: 10 | Z26: 0 | AA26: 20 | AB26: 10 | AC26: 10 | AD26: 10 | AE26: 25 | AF26: 10 | AG26: 20 | AH26: 10 | AI26: 20 | AJ26: 0 | AK26: 0 | AL26: 0 | AM26: 0 | AN26: 0
B29: (Inverter) | D29: Parameters for PELCA (inverter modules) | F29: to copy into 'Faults & Prev. Maint.' sheet of PELCA input Excel file
A30: mission profile | B30: shortest lifetime (year) IGBT or diode | D30: Early failure (sigma, year) | E30: Early failure (beta) | F30: Random failure (sigma, year) | G30: Random failure (beta) | H30: Wear-out failure (sigma, year) | I30: Wear-out failure (beta) | L30: with PWM
A31: profile 1 | B31: 147.0371 | D31: 172.82836 | E31: 0.6 | F31: 17.424884 | G31: 1 | H31: 90.61533 | I31: 3
A32: profile 2 | B32: 18.914179 | D32: 172.82836 | E32: 0.6 | F32: 2.3604107 | G32: 1 | H32: 11.656341 | I32: 3
A33: profile 3 | B33: 18.3314 | D33: 172.82836 | E33: 0.6 | F33: 1.5100537 | G33: 1 | H33: 11.297189 | I33: 3
A34: profile 4 | B34: 4.689028 | D34: 172.82836 | E34: 0.6 | F34: 0.88955204 | G34: 1 | H34: 2.8897321 | I34: 3
A35: profile 5 | B35: 25.803745 | D35: 172.82836 | E35: 0.6 | F35: 1.4931346 | G35: 1 | H35: 15.90221 | I35: 3
A37: to copy into 'Cost - Price' sheet of PELCA input Excel file
A38: RU raw cost/price (€) | B38: RU assembly cost/price (€) | C38: RU disassembly cost/price (€)
A39: 1868.766 | B39: 108.33333 | C39: 86.666667
A41: mission_id | B41: mission profile | C41: life_ratio | D41: Operating_Phase | E41: load_factor | F41: Rel_speed | G41: Rel_torque | H41: Tx | I41: delta_T_cycling | J41: T_max_cycling | K41: Operating_Hours_per_Year | L41: N_cy | M41: theta_cy | N41: RH_ambient | O41: G_RMS | P41: Pi_application | Q41: Pi_type | R41: Tj_D_iec | S41: Tj_Q_iec | T41: deltaT_D_iec | U41: deltaT_Q_iec | V41: Tj_D_pwm | W41: Tj_Q_pwm | X41: deltaT_D_pwm | Y41: deltaT_Q_pwm | Z41: N_fout_cy | AA41: Tc | AB41: delta_Tc_cycling | AC41: delta_Tj_D_cycling | AD41: delta_Tj_Q_cycling | AE41: Tc_max_cycling | AF41: deltaTj_D_phase | AG41: Tj_D_phase | AH41: deltaTj_Q_phase | AI41: Tj_Q_phase | AJ41: PL_on_T_HB | AK41: PL_on_D_HB | AL41: PL_sw_T_HB | AM41: PL_sw_D_HB | AN41: total_loss
AA42: 111.56806 | AB42: 46.972552 | AC42: 48.058782 | AD42: 50.773868 | AE42: 111.56806 | AF42: 48.058782 | AG42: 90.992907 | AH42: 50.773868 | AI42: 92.468538 | AJ42: 73.428972 | AK42: 23.084276 | AL42: 57.546836 | AM42: 22.362113 | AN42: 2117.0664
AA43: 64.595504 | AB43: 8.1378662 | AC43: 8.1432724 | AD43: 8.1478301 | AE43: 64.595504 | AF43: 8.1432724 | AG43: 62.89188 | AH43: 8.1478301 | AI43: 63.007688 | AJ43: 22.323418 | AK43: 11.474679 | AL43: 29.477217 | AM43: 19.687525 | AN43: 995.55407
AA44: 56.457638 | AB44: 41.457638 | AC44: 43.820244 | AD44: 43.933773 | AE44: 56.457638 | AF44: 43.820244 | AG44: 36.910122 | AH44: 43.933773 | AI44: 36.966887 | AJ44: 22.432293 | AK44: 11.508153 | AL44: 29.128372 | AM44: 19.563406 | AN44: 991.5867
AA45: 15 | AB45: 10 | AC45: 10 | AD45: 10 | AE45: 20 | AF45: 10 | AG45: 15 | AH45: 10 | AI45: 15 | AJ45: 0 | AK45: 0 | AL45: 0 | AM45: 0 | AN45: 0
AA46: 118.34532 | AB46: 88.345315 | AC46: 91.331841 | AD46: 93.175713 | AE46: 118.34532 | AF46: 91.331841 | AG46: 75.66592 | AH46: 93.175713 | AI46: 76.587856 | AJ46: 53.085713 | AK46: 17.448433 | AL46: 47.53833 | AM46: 21.844347 | AN46: 1679.0019
AA47: 30 | AB47: 25 | AC47: 25 | AD47: 25 | AE47: 30 | AF47: 25 | AG47: 30 | AH47: 25 | AI47: 30 | AJ47: 0 | AK47: 0 | AL47: 0 | AM47: 0 | AN47: 0
...

Sheet results
B1: (inverter_reliability) | D1: Parameters for PELCA (inverter modules) | F1: to copy into 'Faults & Prev. Maint.' sheet of PELCA input Excel file
A2: mission profile | B2: shortest lifetime (year) IGBT or diode | D2: Early failure (sigma, year) | E2: Early failure (beta) | F2: Random failure (sigma, year) | G2: Random failure (beta) | H2: Wear-out failure (sigma, year) | I2: Wear-out failure (beta)
A3: profile 1 | B3: 2146.9435 | D3: 172.82836 | E3: 0.6 | F3: 39.528621 | G3: 1 | H3: 1323.1083 | I3: 3
A4: profile 2 | B4: 1050.3589 | D4: 172.82836 | E4: 0.6 | F4: 35.645332 | G4: 1 | H4: 647.31025 | I4: 3
A6: to copy into 'Cost - Price' sheet of PELCA input Excel file
A7: RU raw cost/price (€) | B7: RU assembly cost/price (€) | C7: RU disassembly cost/price (€)
A8: 1868.766 | B8: 108.33333 | C8: 86.666667
